Workbook

Sheet DUCW-1
A1: Unit Of Measurement | B1: Variable Group | C1: Plant | D1: Tag UID | E1: Business Unit | F1: Line | G1: Equipment Subtype | H1: Cluster | I1: Section | J1: Standard Variable Description | K1: PublishingInterval | L1: Variable Type | M1: Tag Name | N1: Section | O1: Tag UID | P1: ConvertToBinary | Q1: Path | R1: PropertyID | S1: Equipment Group | T1: OPC EndPOint | U1: Plant SAP Code | V1: Flat Line Length | W1: Tag Name | X1: AssetID | Y1: Min | Z1: LCL | AA1: UCL | AB1: Max | AC1: IsDisplay | AD1: Variable Type
A2: TPH | B2: PV | C2: DUCW | D2: W-DUCW2-CM2-F-PV-CM2_532WF1_FR | E2: CEMENT | F2: 2 | G2: Weigh Feeder | H2: W | I2: Cement Mill-2 | J2: Feedrate | M2: CM2_532WF1_FR | N2: Cement Mill-2 | O2: W-DUCW2-CM2-F-PV-CM2_532WF1_FR | Q2: ns=2;s=1:CM2_532WF1_FR?Value | R2: 985a4244-1d9a-4273-9921-0274f35d4607 | S2: CM-Feeding | T2: opc.tcp://10.5.32.43:26080/ | U2: DH01 | V2: 60 | W2: CM2_532WF1_FR | X2: 9101ba08-3823-48c6-b452-957d965cd1cc | AD2: Flow
A3: TPH | B3: PV | C3: DUCW | D3: W-DUCW2-CM2-F-PV-CM2_532WF2_FR | E3: CEMENT | F3: 2 | G3: Weigh Feeder | H3: W | I3: Cement Mill-2 | J3: Feedrate | M3: CM2_532WF2_FR | N3: Cement Mill-2 | O3: W-DUCW2-CM2-F-PV-CM2_532WF2_FR | Q3: ns=2;s=1:CM2_532WF2_FR?Value | R3: 760f25b6-d7b2-475b-8bfb-10c97ca5ddd9 | S3: CM-Feeding | T3: opc.tcp://10.5.32.43:26080/ | U3: DH01 | V3: 60 | W3: CM2_532WF2_FR | X3: 9101ba08-3823-48c6-b452-957d965cd1cc | AD3: Flow
A4: TPH | B4: PV | C4: DUCW | D4: W-DUCW2-CM2-F-PV-CM2_532WF3_FR | E4: CEMENT | F4: 2 | G4: Weigh Feeder | H4: W | I4: Cement Mill-2 | J4: Feedrate | M4: CM2_532WF3_FR | N4: Cement Mill-2 | O4: W-DUCW2-CM2-F-PV-CM2_532WF3_FR | Q4: ns=2;s=1:CM2_532WF3_FR?Value | R4: abf2d953-ff11-4c96-aa86-0a7cbd01bb3a | S4: CM-Feeding | T4: opc.tcp://10.5.32.43:26080/ | U4: DH01 | V4: 60 | W4: CM2_532WF3_FR | X4: 9101ba08-3823-48c6-b452-957d965cd1cc | AD4: Flow
A5: amp | B5: PV | C5: DUCW | D5: W-DUCW2-CM2-I-PV-CM2_532FN1_II | E5: CEMENT | F5: 2 | G5: Bag Filter Fan | H5: W | I5: Cement Mill-2 | J5: Current | M5: CM2_532FN1_II | N5: Cement Mill-2 | O5: W-DUCW2-CM2-I-PV-CM2_532FN1_II | Q5: ns=2;s=1:CM2_532FN1_II?Value | R5: c4cdf49f-5971-403f-8a44-6ee4317a1471 | S5: CM-Dust Collector | T5: opc.tcp://10.5.32.43:26080/ | U5: DH01 | V5: 60 | W5: CM2_532FN1_II | X5: 9101ba08-3823-48c6-b452-957d965cd1cc | AD5: Current
A6: amp | B6: PV | C6: DUCW | D6: W-DUCW2-CM2-I-PV-CM2_532MS1_II | E6: CEMENT | F6: 2 | G6: Magnetic Separator | H6: W | I6: Cement Mill-2 | J6: DC Current | M6: CM2_532MS1_II | N6: Cement Mill-2 | O6: W-DUCW2-CM2-I-PV-CM2_532MS1_II | Q6: ns=2;s=1:CM2_532MS1_II?Value | R6: 7f39c785-4bb6-42e0-85d9-57f679b7734c | S6: CM-Separators | T6: opc.tcp://10.5.32.43:26080/ | U6: DH01 | V6: 60 | W6: CM2_532MS1_II | X6: 9101ba08-3823-48c6-b452-957d965cd1cc | AD6: Current
A7: amp | B7: PV | C7: DUCW | D7: W-DUCW2-CM2-I-PV-CM2_532WF1_II | E7: CEMENT | F7: 2 | G7: Weigh Feeder | H7: W | I7: Cement Mill-2 | J7: Motor Current | M7: CM2_532WF1_II | N7: Cement Mill-2 | O7: W-DUCW2-CM2-I-PV-CM2_532WF1_II | Q7: ns=2;s=1:CM2_532WF1_II?Value | R7: c48ee8ea-437c-4807-a974-70630bb6bfc2 | S7: CM-Feeding | T7: opc.tcp://10.5.32.43:26080/ | U7: DH01 | V7: 60 | W7: CM2_532WF1_II | X7: 9101ba08-3823-48c6-b452-957d965cd1cc | AD7: Current
A8: amp | B8: PV | C8: DUCW | D8: W-DUCW2-CM2-I-PV-CM2_532WF2_II | E8: CEMENT | F8: 2 | G8: Weigh Feeder | H8: W | I8: Cement Mill-2 | J8: Motor Current | M8: CM2_532WF2_II | N8: Cement Mill-2 | O8: W-DUCW2-CM2-I-PV-CM2_532WF2_II | Q8: ns=2;s=1:CM2_532WF2_II?Value | R8: 4c66c409-d103-4b63-9aba-93acbc64d7e8 | S8: CM-Feeding | T8: opc.tcp://10.5.32.43:26080/ | U8: DH01 | V8: 60 | W8: CM2_532WF2_II | X8: 9101ba08-3823-48c6-b452-957d965cd1cc | AD8: Current
A9: amp | B9: PV | C9: DUCW | D9: W-DUCW2-CM2-I-PV-CM2_532WF3_II | E9: CEMENT | F9: 2 | G9: Weigh Feeder | H9: W | I9: Cement Mill-2 | J9: Motor Current | M9: CM2_532WF3_II | N9: Cement Mill-2 | O9: W-DUCW2-CM2-I-PV-CM2_532WF3_II | Q9: ns=2;s=1:CM2_532WF3_II?Value | R9: 94f69d98-abf4-46f5-afe7-6656cea62da1 | S9: CM-Feeding | T9: opc.tcp://10.5.32.43:26080/ | U9: DH01 | V9: 60 | W9: CM2_532WF3_II | X9: 9101ba08-3823-48c6-b452-957d965cd1cc | AD9: Current
A10: mmWC | B10: PV | C10: DUCW | D10: W-DUCW2-CM2-P-PV-CM2_532BF1_DPT | E10: CEMENT | F10: 2 | G10: Bag Filter | H10: W | I10: Cement Mill-2 | J10: Differential pressure | M10: CM2_532BF1_DPT | N10: Cement Mill-2 | O10: W-DUCW2-CM2-P-PV-CM2_532BF1_DPT | Q10: ns=2;s=1:CM2_532BF1_DPT?Value | R10: 1b66b5d4-1a07-4a88-873a-00377ee12e2e | S10: CM-Dust Collector | T10: opc.tcp://10.5.32.43:26080/ | U10: DH01 | V10: 60 | W10: CM2_532BF1_DPT | X10: 9101ba08-3823-48c6-b452-957d965cd1cc | AD10: Pressure
A11: Bar | B11: PV | C11: DUCW | D11: W-DUCW2-CM2-P-PV-CM2_532BF1_PT | E11: CEMENT | F11: 2 | G11: Bag Filter | H11: W | I11: Cement Mill-2 | J11: Compressor Air Pressure | M11: CM2_532BF1_PT | N11: Cement Mill-2 | O11: W-DUCW2-CM2-P-PV-CM2_532BF1_PT | Q11: ns=2;s=1:CM2_532BF1_PT?Value | R11: c340c734-aea6-4bcb-a00b-21c27536bcbe | S11: CM-Dust Collector | T11: opc.tcp://10.5.32.43:26080/ | U11: DH01 | V11: 60 | W11: CM2_532BF1_PT | X11: 9101ba08-3823-48c6-b452-957d965cd1cc | AD11: Pressure
A12: RPM | B12: PV | C12: DUCW | D12: W-DUCW2-CM2-R-PV-CM2_532FN1_SI | E12: CEMENT | F12: 2 | G12: Bag Filter Fan | H12: W | I12: Cement Mill-2 | J12: Speed | M12: CM2_532FN1_SI | N12: Cement Mill-2 | O12: W-DUCW2-CM2-R-PV-CM2_532FN1_SI | Q12: ns=2;s=1:CM2_532FN1_SI?Value | R12: adef58ec-1ab7-4aa3-b0ab-6faf451d8238 | S12: CM-Dust Collector | T12: opc.tcp://10.5.32.43:26080/ | U12: DH01 | V12: 60 | W12: CM2_532FN1_SI | X12: 9101ba08-3823-48c6-b452-957d965cd1cc | AD12: Speed
A13: RPM | B13: PV | C13: DUCW | D13: W-DUCW2-CM2-R-PV-CM2_532WF1_SI | E13: CEMENT | F13: 2 | G13: Weigh Feeder | H13: W | I13: Cement Mill-2 | J13: Motor Speed | M13: CM2_532WF1_SI | N13: Cement Mill-2 | O13: W-DUCW2-CM2-R-PV-CM2_532WF1_SI | Q13: ns=2;s=1:CM2_532WF1_SI?Value | R13: 17d7734e-8cc8-4909-8574-0dadacc13000 | S13: CM-Feeding | T13: opc.tcp://10.5.32.43:26080/ | U13: DH01 | V13: 60 | W13: CM2_532WF1_SI | X13: 9101ba08-3823-48c6-b452-957d965cd1cc | AD13: Speed
... A25: state | B25: Mode | C25: DUCW | D25: W-DUCW2-CM2-ST-SV-CM2_532AB9_PS | E25: CEMENT | F25: 2 | G25: Air Blaster | H25: W | I25: Cement Mill-2 | J25: Pressure Switch | M25: CM2_532AB9_PS | N25: Cement Mill-2 | O25: W-DUCW2-CM2-ST-SV-CM2_532AB9_PS | Q25: ns=2;s=1:CM2_532AB9_PS?Value | R25: 35f2c4db-0ca9-4e0b-b01a-1535551a2721 | S25: Mill | T25: opc.tcp://10.5.32.43:26080/ | U25: DH01 | V25: 60 | W25: CM2_532AB9_PS | X25: 9101ba08-3823-48c6-b452-957d965cd1cc | AD25: Status
A26: state | B26: Mode | C26: DUCW | D26: W-DUCW2-CM2-ST-SV-CM2_532BC1_DE_MG | E26: CEMENT | F26: 2 | G26: Belt Conveyor | H26: W | I26: Cement Mill-2 | J26: Machin Guarding DE | M26: CM2_532BC1_DE_MG | N26: Cement Mill-2 | O26: W-DUCW2-CM2-ST-SV-CM2_532BC1_DE_MG | R26: 1005c013-2423-46a7-a148-1abad0e54ccc | S26: CM-Transport | U26: DH01 | V26: 60 | W26: CM2_532BC1_DE_MG | X26: 9101ba08-3823-48c6-b452-957d965cd1cc | AD26: Status
A27: state | B27: Mode | C27: DUCW | D27: W-DUCW2-CM2-ST-SV-CM2_532BC1_NDE_MG | E27: CEMENT | F27: 2 | G27: Belt Conveyor | H27: W | I27: Cement Mill-2 | J27: Machin Guarding NDE | M27: CM2_532BC1_NDE_MG | N27: Cement Mill-2 | O27: W-DUCW2-CM2-ST-SV-CM2_532BC1_NDE_MG | R27: 8cd1e237-0a42-4ad5-ab28-d628400944c6 | S27: CM-Transport | U27: DH01 | V27: 60 | W27: CM2_532BC1_NDE_MG | X27: 9101ba08-3823-48c6-b452-957d965cd1cc | AD27: Status
A28: state | B28: Mode | C28: DUCW | D28: W-DUCW2-CM2-ST-SV-CM2_532BC2_L_DR_ZS2 | E28: CEMENT | F28: 2 | G28: Belt Conveyor | H28: W | I28: Cement Mill-2 | J28: Non Drive End Door Limit Switch1 | M28: CM2_532BC2_L_DR_ZS2 | N28: Cement Mill-2 | O28: W-DUCW2-CM2-ST-SV-CM2_532BC2_L_DR_ZS2 | Q28: ns=2;s=1:CM2_532BC2_L_DR_ZS2?Value | R28: 7f961c96-0c44-4da3-b076-9b3e84a1a769 | S28: CM-Transport | T28: opc.tcp://10.5.32.43:26080/ | U28: DH01 | V28: 60 | W28: CM2_532BC2_L_DR_ZS2 | X28: 9101ba08-3823-48c6-b452-957d965cd1cc | AD28: Status
A29: state | B29: Mode | C29: DUCW | D29: W-DUCW2-CM2-ST-SV-CM2_532BC2_NDE_MG | E29: CEMENT | F29: 2 | G29: Belt Conveyor | H29: W | I29: Cement Mill-2 | J29: Machin Guarding NDE | M29: CM2_532BC2_NDE_MG | N29: Cement Mill-2 | O29: W-DUCW2-CM2-ST-SV-CM2_532BC2_NDE_MG | R29: b49cd491-3ab5-4241-a90c-c23228e335b1 | S29: CM-Transport | U29: DH01 | V29: 60 | W29: CM2_532BC2_NDE_MG | X29: 9101ba08-3823-48c6-b452-957d965cd1cc | AD29: Status
A30: state | B30: Mode | C30: DUCW | D30: W-DUCW2-CM2-ST-SV-CM2_532BC2_R_DR_ZS2 | E30: CEMENT | F30: 2 | G30: Belt Conveyor | H30: W | I30: Cement Mill-2 | J30: Non Drive End Door Limit Switch12 | M30: CM2_532BC2_R_DR_ZS2 | N30: Cement Mill-2 | O30: W-DUCW2-CM2-ST-SV-CM2_532BC2_R_DR_ZS2 | Q30: ns=2;s=1:CM2_532BC2_R_DR_ZS2?Value | R30: 2f79f08d-3dcd-4b0b-b0c2-33182d1a560f | S30: CM-Transport | T30: opc.tcp://10.5.32.43:26080/ | U30: DH01 | V30: 60 | W30: CM2_532BC2_R_DR_ZS2 | X30: 9101ba08-3823-48c6-b452-957d965cd1cc | AD30: Status
A31: state | B31: Mode | C31: DUCW | D31: W-DUCW2-CM2-ST-SV-CM2_562LD1_M01_PH | E31: CEMENT | F31: 2 | G31: Damper | H31: W | I31: Cement Mill-2 | J31: MOTOR FOR LOURVE DAMPER | M31: CM2 _562LD1_M01_PH | N31: Cement Mill-2 | O31: W-DUCW2-CM2-ST-SV-CM2_562LD1_M01_PH | R31: f060aa7b-67ba-4552-8010-cbb91819b833 | S31: CM-Regulators | U31: DH01 | V31: 60 | W31: CM2 _562LD1_M01_PH | X31: 9101ba08-3823-48c6-b452-957d965cd1cc | AD31: Status
A32: state | B32: Mode | C32: DUCW | D32: W-DUCW2-CM2-ST-SV-CM2_62LD3_M01_PH | E32: CEMENT | F32: 2 | G32: Damper | H32: W | I32: Cement Mill-2 | J32: MOTOR FOR LOURVE DAMPER 5 | M32: CM2 _62LD3_M01_PH | N32: Cement Mill-2 | O32: W-DUCW2-CM2-ST-SV-CM2_62LD3_M01_PH | R32: 5dd80562-d303-4529-aa80-5a491007c6a6 | S32: CM-Regulators | U32: DH01 | V32: 60 | W32: CM2 _62LD3_M01_PH | X32: 9101ba08-3823-48c6-b452-957d965cd1cc | AD32: Status
A33: state | B33: Mode | C33: DUCW | D33: W-DUCW2-CM2-ST-SV-MH2_-512CGE_M01_PH | E33: CEMENT | F33: 2 | G33: Clam Shell Gate | H33: W | I33: Cement Mill-2 | J33: MOTOR FOR CLAM SHELL GATE | M33: MH2_-512CGE_M01_PH | N33: Cement Mill-2 | O33: W-DUCW2-CM2-ST-SV-MH2_-512CGE_M01_PH | Q33: ns=2;s=1:MH2_-512CGE_M01_PH?Value | R33: 19050c98-08ac-4b8d-90a4-a53fa55a1556 | S33: CM-Regulators | T33: opc.tcp://10.5.32.43:26080/ | U33: DH01 | V33: 60 | W33: MH2_-512CGE_M01_PH | X33: 9101ba08-3823-48c6-b452-957d965cd1cc | AD33: Status
A34: state | B34: Mode | C34: DUCW | D34: W-DUCW2-CM2-ST-SV-MH2_492BC1_DE_MG | E34: CEMENT | F34: 2 | G34: Belt Conveyor | H34: W | I34: Cement Mill-2 | J34: Machine Guard Guard DE | M34: MH2_492BC1_DE_MG | N34: Cement Mill-2 | O34: W-DUCW2-CM2-ST-SV-MH2_492BC1_DE_MG | Q34: ns=2;s=1:MH2_492BC1_DE_MG?Value | R34: 9e660021-d218-46c6-bff8-da54385e1abb | S34: CM-Transport | T34: opc.tcp://10.5.32.43:26080/ | U34: DH01 | V34: 60 | W34: MH2_492BC1_DE_MG | X34: 9101ba08-3823-48c6-b452-957d965cd1cc | AD34: Status
A35: state | B35: Mode | C35: DUCW | D35: W-DUCW2-CM2-ST-SV-MH2_492BC1_L_DR_ZS1 | E35: CEMENT | F35: 2 | G35: Belt Conveyor | H35: W | I35: Cement Mill-2 | J35: DE Left Door Proxy Switch | M35: MH2_492BC1_L_DR_ZS1 | N35: Cement Mill-2 | O35: W-DUCW2-CM2-ST-SV-MH2_492BC1_L_DR_ZS1 | Q35: ns=2;s=1:MH2_492BC1_L_DR_ZS1?Value | R35: 644da472-b14a-4b8c-a109-01720412f8bd | S35: CM-Transport | T35: opc.tcp://10.5.32.43:26080/ | U35: DH01 | V35: 60 | W35: MH2_492BC1_L_DR_ZS1 | X35: 9101ba08-3823-48c6-b452-957d965cd1cc | AD35: Status
A36: state | B36: Mode | C36: DUCW | D36: W-DUCW2-CM2-ST-SV-MH2_492BC1_L_DR_ZS2 | E36: CEMENT | F36: 2 | G36: Belt Conveyor | H36: W | I36: Cement Mill-2 | J36: NDE Left Door Proxy Switch | M36: MH2_492BC1_L_DR_ZS2 | N36: Cement Mill-2 | O36: W-DUCW2-CM2-ST-SV-MH2_492BC1_L_DR_ZS2 | Q36: ns=2;s=1:MH2_492BC1_L_DR_ZS2?Value | R36: 6d53d32b-7d30-4235-93ec-4685f60e94a4 | S36: CM-Transport | T36: opc.tcp://10.5.32.43:26080/ | U36: DH01 | V36: 60 | W36: MH2_492BC1_L_DR_ZS2 | X36: 9101ba08-3823-48c6-b452-957d965cd1cc | AD36: Status
A37: state | B37: Mode | C37: DUCW | D37: W-DUCW2-CM2-ST-SV-MH2_492BC1_NDE_MG | E37: CEMENT | F37: 2 | G37: Belt Conveyor | H37: W | I37: Cement Mill-2 | J37: Machine Guard NDE | M37: MH2_492BC1_NDE_MG | N37: Cement Mill-2 | O37: W-DUCW2-CM2-ST-SV-MH2_492BC1_NDE_MG | Q37: ns=2;s=1:MH2_492BC1_NDE_MG?Value | R37: fe2959f2-0a27-4ca5-ae81-ac5a2c2610cf | S37: CM-Transport | T37: opc.tcp://10.5.32.43:26080/ | U37: DH01 | V37: 60 | W37: MH2_492BC1_NDE_MG | X37: 9101ba08-3823-48c6-b452-957d965cd1cc | AD37: Status
A38: state | B38: Mode | C38: DUCW | D38: W-DUCW2-CM2-ST-SV-MH2_492BC1_R_DR_ZS1 | E38: CEMENT | F38: 2 | G38: Belt Conveyor | H38: W | I38: Cement Mill-2 | J38: DE Right Door Proxy Switch | M38: MH2_492BC1_R_DR_ZS1 | N38: Cement Mill-2 | O38: W-DUCW2-CM2-ST-SV-MH2_492BC1_R_DR_ZS1 | Q38: ns=2;s=1:MH2_492BC1_R_DR_ZS1?Value | R38: d94a687d-06ae-46c2-af52-220322f76b46 | S38: CM-Transport | T38: opc.tcp://10.5.32.43:26080/ | U38: DH01 | V38: 60 | W38: MH2_492BC1_R_DR_ZS1 | X38: 9101ba08-3823-48c6-b452-957d965cd1cc | AD38: Status
A39: state | B39: Mode | C39: DUCW | D39: W-DUCW2-CM2-ST-SV-MH2_492BC1_R_DR_ZS2 | E39: CEMENT | F39: 2 | G39: Belt Conveyor | H39: W | I39: Cement Mill-2 | J39: NDE Right Door Proxy Switch | M39: MH2_492BC1_R_DR_ZS2 | N39: Cement Mill-2 | O39: W-DUCW2-CM2-ST-SV-MH2_492BC1_R_DR_ZS2 | Q39: ns=2;s=1:MH2_492BC1_R_DR_ZS2?Value | R39: 144cb536-6a25-4413-9cab-17c49a381fce | S39: CM-Transport | T39: opc.tcp://10.5.32.43:26080/ | U39: DH01 | V39: 60 | W39: MH2_492BC1_R_DR_ZS2 | X39: 9101ba08-3823-48c6-b452-957d965cd1cc | AD39: Status
A40: state | B40: Mode | C40: DUCW | D40: W-DUCW2-CM2-ST-SV-MH2_492FN1_PH | E40: CEMENT | F40: 2 | G40: Bag Filter Fan | H40: W | I40: Cement Mill-2 | J40: Panel Healthy | M40: MH2_492FN1_PH | N40: Cement Mill-2 | O40: W-DUCW2-CM2-ST-SV-MH2_492FN1_PH | Q40: ns=2;s=1:MH2_492FN1_PH?Value | R40: 9c242de6-c0e9-42a6-b2c3-1ffb8236796f | S40: CM-Fans | T40: opc.tcp://10.5.32.43:26080/ | U40: DH01 | V40: 60 | W40: MH2_492FN1_PH | X40: 9101ba08-3823-48c6-b452-957d965cd1cc | AD40: Status
A41: state | B41: Mode | C41: DUCW | D41: W-DUCW2-CM2-ST-SV-MH2_492FN1_RUN | E41: CEMENT | F41: 2 | G41: Bag Filter Fan | H41: W | I41: Cement Mill-2 | J41: Drive Run | M41: MH2_492FN1_RUN | N41: Cement Mill-2 | O41: W-DUCW2-CM2-ST-SV-MH2_492FN1_RUN | Q41: ns=2;s=1:MH2_492FN1?Operating | R41: 3177540f-2a76-42f6-ba8b-eb0eadd0bcf8 | S41: CM-Fans | T41: opc.tcp://10.5.32.43:26080/ | U41: DH01 | V41: 60 | W41: MH2_492FN1_RUN | X41: 9101ba08-3823-48c6-b452-957d965cd1cc | AD41: Status
A42: state | B42: Mode | C42: DUCW | D42: W-DUCW2-CM2-ST-SV-MH2_492FN2_PH | E42: CEMENT | F42: 2 | G42: Bag Filter Fan | H42: W | I42: Cement Mill-2 | J42: Panel Healthy | M42: MH2_492FN2_PH | N42: Cement Mill-2 | O42: W-DUCW2-CM2-ST-SV-MH2_492FN2_PH | Q42: ns=2;s=1:MH2_492FN2_PH?Value | R42: 95d51524-7994-484e-bde4-8c306be78c60 | S42: CM-Fans | T42: opc.tcp://10.5.32.43:26080/ | U42: DH01 | V42: 60 | W42: MH2_492FN2_PH | X42: 9101ba08-3823-48c6-b452-957d965cd1cc | AD42: Status
A43: state | B43: Mode | C43: DUCW | D43: W-DUCW2-CM2-ST-SV-MH2_492FN2_RUN | E43: CEMENT | F43: 2 | G43: Bag Filter Fan | H43: W | I43: Cement Mill-2 | J43: Drive Run | M43: MH2_492FN2_RUN | N43: Cement Mill-2 | O43: W-DUCW2-CM2-ST-SV-MH2_492FN2_RUN | Q43: ns=2;s=1:MH2_492FN2?Operating | R43: 2756f50f-0429-4626-b24b-2d09d6c193b8 | S43: CM-Fans | T43: opc.tcp://10.5.32.43:26080/ | U43: DH01 | V43: 60 | W43: MH2_492FN2_RUN | X43: 9101ba08-3823-48c6-b452-957d965cd1cc | AD43: Status
A44: state | B44: Mode | C44: DUCW | D44: W-DUCW2-CM2-ST-SV-MH2_492FN3_PH | E44: CEMENT | F44: 2 | G44: Bag Filter Fan | H44: W | I44: Cement Mill-2 | J44: Panel Healthy | M44: MH2_492FN3_PH | N44: Cement Mill-2 | O44: W-DUCW2-CM2-ST-SV-MH2_492FN3_PH | Q44: ns=2;s=1:MH2_492FN3_PH?Value | R44: 7a7e9940-0c31-46e2-b365-e9b3bfc3844d | S44: CM-Fans | T44: opc.tcp://10.5.32.43:26080/ | U44: DH01 | V44: 60 | W44: MH2_492FN3_PH | X44: 9101ba08-3823-48c6-b452-957d965cd1cc | AD44: Status
... A78: state | B78: Mode | C78: DUCW | D78: W-DUCW2-CM2-ST-SV-MH2_K22DG1_M01_PH | E78: CEMENT | F78: 2 | G78: Diverting Gate | H78: W | I78: Cement Mill-2 | J78: MOTOR FOR DIVERTING GATE | M78: MH2_K22DG1_M01_PH | N78: Cement Mill-2 | O78: W-DUCW2-CM2-ST-SV-MH2_K22DG1_M01_PH | Q78: ns=2;s=1:MH2_K22DG1_M01_PH?Value | R78: b1825e35-f108-4bd4-b9c7-94ef72201382 | S78: CM-Regulators | T78: opc.tcp://10.5.32.43:26080/ | U78: DH01 | V78: 60 | W78: MH2_K22DG1_M01_PH | X78: 9101ba08-3823-48c6-b452-957d965cd1cc | AD78: Status
A79: state | B79: Mode | C79: DUCW | D79: W-DUCW2-CM2-ST-SV-MH2_K22FN2_PH | E79: CEMENT | F79: 2 | G79: Bag Filter Fan | H79: W | I79: Cement Mill-2 | J79: Panel Healthy | M79: MH2_K22FN2_PH | N79: Cement Mill-2 | O79: W-DUCW2-CM2-ST-SV-MH2_K22FN2_PH | R79: a137d238-cc1a-4aa3-91aa-9b10c37bc5a4 | S79: CM-Fans | U79: DH01 | V79: 60 | W79: MH2_K22FN2_PH | X79: 9101ba08-3823-48c6-b452-957d965cd1cc | AD79: Status
A80: state | B80: Mode | C80: DUCW | D80: W-DUCW2-CM2-ST-SV-MH2_K22FN2_RUN | E80: CEMENT | F80: 2 | G80: Bag Filter Fan | H80: W | I80: Cement Mill-2 | J80: Drive Run | M80: MH2_K22FN2_RUN | N80: Cement Mill-2 | O80: W-DUCW2-CM2-ST-SV-MH2_K22FN2_RUN | Q80: ns=2;s=1:MH2_K22FN2?Operating | R80: 238f707e-3979-4b87-9c9a-9dcd5e374a58 | S80: CM-Fans | T80: opc.tcp://10.5.32.43:26080/ | U80: DH01 | V80: 60 | W80: MH2_K22FN2_RUN | X80: 9101ba08-3823-48c6-b452-957d965cd1cc | AD80: Status
A81: Deg C | B81: PV | C81: DUCW | D81: W-DUCW2-CM2-T-PV-CM2_532MS1_OTE | E81: CEMENT | F81: 2 | G81: Magnetic Separator | H81: W | I81: Cement Mill-2 | J81: Magnet Oil Temperature | M81: CM2_532MS1_OTE | N81: Cement Mill-2 | O81: W-DUCW2-CM2-T-PV-CM2_532MS1_OTE | Q81: ns=2;s=1:CM2_532MS1_OTE?Value | R81: 20ab2b2d-8721-42db-a70a-1900d207ffa6 | S81: CM-Separators | T81: opc.tcp://10.5.32.43:26080/ | U81: DH01 | V81: 60 | W81: CM2_532MS1_OTE | X81: 9101ba08-3823-48c6-b452-957d965cd1cc | AD81: Temperature
A82: Deg C | B82: PV | C82: DUCW | D82: W-DUCW2-CM2-T-PV-CM2_532MS1_TT | E82: CEMENT | F82: 2 | G82: Magnetic Separator | H82: W | I82: Cement Mill-2 | J82: Magnet Temperature | M82: CM2_532MS1_TT | N82: Cement Mill-2 | O82: W-DUCW2-CM2-T-PV-CM2_532MS1_TT | Q82: ns=2;s=1:CM2_532MS1_TT?Value | R82: 2b9b424c-9828-4c0e-84f0-3bc307da05d8 | S82: CM-Separators | T82: opc.tcp://10.5.32.43:26080/ | U82: DH01 | V82: 60 | W82: CM2_532MS1_TT | X82: 9101ba08-3823-48c6-b452-957d965cd1cc | AD82: Temperature
A83: Deg C | B83: PV | C83: DUCW | D83: W-DUCW2-CM2-T-PV-CM2_IO_ROOM_TE | E83: CEMENT | F83: 2 | G83: Others | H83: W | I83: Cement Mill-2 | J83: Temperature | M83: CM2_IO_ROOM_TE | N83: Cement Mill-2 | O83: W-DUCW2-CM2-T-PV-CM2_IO_ROOM_TE | Q83: ns=2;s=1:CM2_IO_ROOM_TE?Value | R83: d31fc0ed-1a54-4ed8-b6ac-09cecc023686 | S83: Mill | T83: opc.tcp://10.5.32.43:26080/ | U83: DH01 | V83: 60 | W83: CM2_IO_ROOM_TE | X83: 9101ba08-3823-48c6-b452-957d965cd1cc | AD83: Temperature
A84: Tons | B84: PV | C84: DUCW | D84: W-DUCW2-CM2-WE-PV-CM2_532WF1_WI | E84: CEMENT | F84: 2 | G84: Weigh Feeder | H84: W | I84: Cement Mill-2 | J84: Bin Weight | M84: CM2_532WF1_WI | N84: Cement Mill-2 | O84: W-DUCW2-CM2-WE-PV-CM2_532WF1_WI | Q84: ns=2;s=1:CM2_532WF1_WI?Value | R84: bfc16dff-3338-4ca0-a7c8-3fcf94616d21 | S84: CM-Feeding | T84: opc.tcp://10.5.32.43:26080/ | U84: DH01 | V84: 60 | W84: CM2_532WF1_WI | X84: 9101ba08-3823-48c6-b452-957d965cd1cc | AD84: Weight
...

Sheet DUCW
M1: Tag Name | N1: Section | O1: Tag UID | P1: Line
M2: CM2_532WF1_FR | N2: Cement Mill-2 | O2: W-DUCW2-CM2-F-PV-CM2_532WF1_FR | P2: 2
M3: CM2_532WF2_FR | N3: Cement Mill-2 | O3: W-DUCW2-CM2-F-PV-CM2_532WF2_FR | P3: 2
M4: CM2_532WF3_FR | N4: Cement Mill-2 | O4: W-DUCW2-CM2-F-PV-CM2_532WF3_FR | P4: 2
M5: CM2_532FN1_II | N5: Cement Mill-2 | O5: W-DUCW2-CM2-I-PV-CM2_532FN1_II | P5: 2
M6: CM2_532MS1_II | N6: Cement Mill-2 | O6: W-DUCW2-CM2-I-PV-CM2_532MS1_II | P6: 2
M7: CM2_532WF1_II | N7: Cement Mill-2 | O7: W-DUCW2-CM2-I-PV-CM2_532WF1_II | P7: 2
M8: CM2_532WF2_II | N8: Cement Mill-2 | O8: W-DUCW2-CM2-I-PV-CM2_532WF2_II | P8: 2
M9: CM2_532WF3_II | N9: Cement Mill-2 | O9: W-DUCW2-CM2-I-PV-CM2_532WF3_II | P9: 2
M10: CM2_532BF1_DPT | N10: Cement Mill-2 | O10: W-DUCW2-CM2-P-PV-CM2_532BF1_DPT | P10: 2
M11: CM2_532BF1_PT | N11: Cement Mill-2 | O11: W-DUCW2-CM2-P-PV-CM2_532BF1_PT | P11: 2
M12: CM2_532FN1_SI | N12: Cement Mill-2 | O12: W-DUCW2-CM2-R-PV-CM2_532FN1_SI | P12: 2
M13: CM2_532WF1_SI | N13: Cement Mill-2 | O13: W-DUCW2-CM2-R-PV-CM2_532WF1_SI | P13: 2
... M86: CM2_532WF3_WI | N86: Cement Mill-2 | O86: W-DUCW2-CM2-WE-PV-CM2_532WF3_WI | P86: 2
M87: CM_561BW1_FR | N87: Cement Mill | O87: N-DUCW1-CM1-F-PV-CM_561BW1_FR | P87: 1
M88: CM_TOTAL_FEED_ACT | N88: Cement Mill | O88: N-DUCW1-CM1-F-PV-CM_TOTAL_FEED_ACT | P88: 1
M89: CM_591BE1_M01II_B | N89: Cement Mill | O89: N-DUCW1-CM1-I-OP-CM_591BE1_M01II_B | P89: 1
M90: CM_561HT1_S01AI01 | N90: Cement Mill | O90: N-DUCW1-CM1-L-PV-CM_561HT1_S01AI01 | P90: 1
M91: CM_611SB1_LT1 | N91: Cement Mill | O91: N-DUCW1-CM1-L-SV-CM_611SB1_LT1 | P91: 1
M92: CM_611SB1_LT2 | N92: Cement Mill | O92: N-DUCW1-CM1-L-SV-CM_611SB1_LT2 | P92: 1
M93: CM_611SB1_LT3 | N93: Cement Mill | O93: N-DUCW1-CM1-L-SV-CM_611SB1_LT3 | P93: 1
M94: CM_561MRV5000GRND_PR | N94: Cement Mill | O94: N-DUCW1-CM1-P-PC-CM_561MRV5000GRND_PR | P94: 1
M95: CM_561FN3_SI | N95: Cement Mill | O95: N-DUCW1-CM1-R-PC-CM_561FN3_SI | P95: 1
M96: CM_561SR1_SI | N96: Cement Mill | O96: N-DUCW1-CM1-R-PC-CM_561SR1_SI | P96: 1
M97: CM_531WF1_FR | N97: Cement Mill | O97: N-DUCW1-CM1-SP-IF-CM_531WF1_FR | P97: 1
M98: CM_531WF2_FR | N98: Cement Mill | O98: N-DUCW1-CM1-SP-IF-CM_531WF2_FR | P98: 1
... M106: CM_561CM1_TT2 | N106: Cement Mill | O106: N-DUCW1-CM1-T-PV-CM_561CM1_TT2 | P106: 1
M107: PP2 _ 622BE1_M02_II | N107: Packing Plant | O107: W-DUCW2-PP2-I-PV-PP2 _ 622BE1_M02_II | P107: 2
M108: PP2 _ 622FN1_II | N108: Packing Plant | O108: W-DUCW2-PP2-I-PV-PP2 _ 622FN1_II | P108: 2
M109: PP2 _ 622VS1_II | N109: Packing Plant | O109: W-DUCW2-PP2-I-PV-PP2 _ 622VS1_II | P109: 2
M110: PP2 _ 642FN6_II | N110: Packing Plant | O110: W-DUCW2-PP2-I-PV-PP2 _ 642FN6_II | P110: 2
M111: PP2 _ 642FN7_II | N111: Packing Plant | O111: W-DUCW2-PP2-I-PV-PP2 _ 642FN7_II | P111: 2
M112: PP2 _ 642FNA_II | N112: Packing Plant | O112: W-DUCW2-PP2-I-PV-PP2 _ 642FNA_II | P112: 2
M113: PP2 _ 642VS1_II | N113: Packing Plant | O113: W-DUCW2-PP2-I-PV-PP2 _ 642VS1_II | P113: 2
M114: PP2 _ 642VS2_II | N114: Packing Plant | O114: W-DUCW2-PP2-I-PV-PP2 _ 642VS2_II | P114: 2
M115: PP2 _ 652BC1_II | N115: Packing Plant | O115: W-DUCW2-PP2-I-PV-PP2 _ 652BC1_II | P115: 2
M116: PP2 _ 652BC5_II | N116: Packing Plant | O116: W-DUCW2-PP2-I-PV-PP2 _ 652BC5_II | P116: 2
M117: PP2 _ 652BC7_II | N117: Packing Plant | O117: W-DUCW2-PP2-I-PV-PP2 _ 652BC7_II | P117: 2
M118: PP2 _ 652BC8_II | N118: Packing Plant | O118: W-DUCW2-PP2-I-PV-PP2 _ 652BC8_II | P118: 2
... M2891: MH2_492RU3_RUN | N2891: Bulk Loading | O2891: W-DUCW2-CM2-ST-SV-MH2_492RU3_RUN | P2891: 2

Sheet BallMill
A1: Tags | B1: Section | C1: Tag UID
A2: CM2_WTR_SYS_LT1 | B2: =VLOOKUP(A:A,'DUCW-1'!M:O,2,) -> Cement Mill-1 | C2: =VLOOKUP(A:A,'DUCW-1'!M:O,3,) -> W-DUCW2-CM2-L-PV-CM2_WTR_SYS_LT1
A3: CM2_WTR_SYS_LT2 | B3: =VLOOKUP(A:A,'DUCW-1'!M:O,2,) -> Cement Mill-1 | C3: =VLOOKUP(A:A,'DUCW-1'!M:O,3,) -> W-DUCW2-CM2-L-PV-CM2_WTR_SYS_LT2
A4: CM2_WTR_SYS_LT3 | B4: =VLOOKUP(A:A,'DUCW-1'!M:O,2,) -> Cement Mill-1 | C4: =VLOOKUP(A:A,'DUCW-1'!M:O,3,) -> W-DUCW2-CM2-L-PV-CM2_WTR_SYS_LT3
A5: CM2_562LQ5_FT1 | B5: =VLOOKUP(A:A,'DUCW-1'!M:O,2,) -> Cement Mill-1 | C5: =VLOOKUP(A:A,'DUCW-1'!M:O,3,) -> W-DUCW2-CM2-F-PV-CM2_562LQ5_FT1
A6: CM2_562LQ5_FT2 | B6: =VLOOKUP(A:A,'DUCW-1'!M:O,2,) -> Cement Mill-1 | C6: =VLOOKUP(A:A,'DUCW-1'!M:O,3,) -> W-DUCW2-CM2-F-PV-CM2_562LQ5_FT2
A7: CM2_562LQ5_FT3 | B7: =VLOOKUP(A:A,'DUCW-1'!M:O,2,) -> Cement Mill-1 | C7: =VLOOKUP(A:A,'DUCW-1'!M:O,3,) -> W-DUCW2-CM2-F-PV-CM2_562LQ5_FT3
A8: CM2_562LQ5_PT2 | B8: =VLOOKUP(A:A,'DUCW-1'!M:O,2,) -> Cement Mill-1 | C8: =VLOOKUP(A:A,'DUCW-1'!M:O,3,) -> W-DUCW2-CM2-P-PV-CM2_562LQ5_PT2
A9: CM2_562LQ5_PT3 | B9: =VLOOKUP(A:A,'DUCW-1'!M:O,2,) -> Cement Mill-1 | C9: =VLOOKUP(A:A,'DUCW-1'!M:O,3,) -> W-DUCW2-CM2-P-PV-CM2_562LQ5_PT3
A10: CM2_562LQ6_FT1 | B10: =VLOOKUP(A:A,'DUCW-1'!M:O,2,) -> Cement Mill-1 | C10: =VLOOKUP(A:A,'DUCW-1'!M:O,3,) -> W-DUCW2-CM2-F-PV-CM2_562LQ6_FT1
A11: CM2_562LQ6_FT2 | B11: =VLOOKUP(A:A,'DUCW-1'!M:O,2,) -> Cement Mill-1 | C11: =VLOOKUP(A:A,'DUCW-1'!M:O,3,) -> W-DUCW2-CM2-F-PV-CM2_562LQ6_FT2
A12: CM2_562LQ6_FT3 | B12: =VLOOKUP(A:A,'DUCW-1'!M:O,2,) -> Cement Mill-1 | C12: =VLOOKUP(A:A,'DUCW-1'!M:O,3,) -> W-DUCW2-CM2-F-PV-CM2_562LQ6_FT3
A13: CM2_562LQ6_FT4 | B13: =VLOOKUP(A:A,'DUCW-1'!M:O,2,) -> Cement Mill-1 | C13: =VLOOKUP(A:A,'DUCW-1'!M:O,3,) -> W-DUCW2-CM2-F-PV-CM2_562LQ6_FT4
... A171: CM2_562LQ9_H02_PH | B171: =VLOOKUP(A:A,'DUCW-1'!M:O,2,) -> #N/A | C171: =VLOOKUP(A:A,'DUCW-1'!M:O,3,) -> #N/A

Sheet BulkLoading
A1: Tags | B1: Section | C1: Tag UID
A2: PP2_622RA1 | B2: =VLOOKUP(A:A,'DUCW-1'!M:O,2,) -> #N/A | C2: =VLOOKUP(A:A,'DUCW-1'!M:O,3,) -> #N/A
A3: PP2_622RA2 | B3: =VLOOKUP(A:A,'DUCW-1'!M:O,2,) -> #N/A | C3: =VLOOKUP(A:A,'DUCW-1'!M:O,3,) -> #N/A
A4: PP2_622BE1_TS | B4: =VLOOKUP(A:A,'DUCW-1'!M:O,2,) -> Packing Plant | C4: =VLOOKUP(A:A,'DUCW-1'!M:O,3,) -> W-DUCW2-PP2-ST-SV-PP2_622BE1_TS
A5: PP2_622BE1_ZS | B5: =VLOOKUP(A:A,'DUCW-1'!M:O,2,) -> Packing Plant | C5: =VLOOKUP(A:A,'DUCW-1'!M:O,3,) -> W-DUCW2-PP2-ST-SV-PP2_622BE1_ZS
A6: PP2_622BE1_BMS1 | B6: =VLOOKUP(A:A,'DUCW-1'!M:O,2,) -> Packing Plant | C6: =VLOOKUP(A:A,'DUCW-1'!M:O,3,) -> W-DUCW2-PP2-ST-SV-PP2_622BE1_BMS1
A7: PP2_622BE1_BMS2 | B7: =VLOOKUP(A:A,'DUCW-1'!M:O,2,) -> Packing Plant | C7: =VLOOKUP(A:A,'DUCW-1'!M:O,3,) -> W-DUCW2-PP2-ST-SV-PP2_622BE1_BMS2
A8: PP2_622BE1_BSS1 | B8: =VLOOKUP(A:A,'DUCW-1'!M:O,2,) -> Packing Plant | C8: =VLOOKUP(A:A,'DUCW-1'!M:O,3,) -> W-DUCW2-PP2-ST-SV-PP2_622BE1_BSS1
A9: PP2_622BE1_BSS1_ALM | B9: =VLOOKUP(A:A,'DUCW-1'!M:O,2,) -> Packing Plant | C9: =VLOOKUP(A:A,'DUCW-1'!M:O,3,) -> W-DUCW2-PP2-ST-SV-PP2_622BE1_BSS1_ALM
A10: PP2_622BE1_BSS2 | B10: =VLOOKUP(A:A,'DUCW-1'!M:O,2,) -> Packing Plant | C10: =VLOOKUP(A:A,'DUCW-1'!M:O,3,) -> W-DUCW2-PP2-ST-SV-PP2_622BE1_BSS2
A11: PP2_622BE1_BSS2_ALM | B11: =VLOOKUP(A:A,'DUCW-1'!M:O,2,) -> Packing Plant | C11: =VLOOKUP(A:A,'DUCW-1'!M:O,3,) -> W-DUCW2-PP2-ST-SV-PP2_622BE1_BSS2_ALM
A12: PP2_622BE1_BSS3 | B12: =VLOOKUP(A:A,'DUCW-1'!M:O,2,) -> Packing Plant | C12: =VLOOKUP(A:A,'DUCW-1'!M:O,3,) -> W-DUCW2-PP2-ST-SV-PP2_622BE1_BSS3
A13: PP2_622BE1_BSS3_ALM | B13: =VLOOKUP(A:A,'DUCW-1'!M:O,2,) -> Packing Plant | C13: =VLOOKUP(A:A,'DUCW-1'!M:O,3,) -> W-DUCW2-PP2-ST-SV-PP2_622BE1_BSS3_ALM
... A116: 622BK1 | B116: =VLOOKUP(A:A,'DUCW-1'!M:O,2,) -> #N/A | C116: =VLOOKUP(A:A,'DUCW-1'!M:O,3,) -> #N/A

Sheet CementMillRollerPress
A1: Tags | B1: Section | C1: Tag UID
A2: CM2_562BM1_EA1 | B2: =VLOOKUP(A:A,'DUCW-1'!M:O,2,) -> Cement Mill-1 | C2: =VLOOKUP(A:A,'DUCW-1'!M:O,3,) -> W-DUCW2-CM2-L-PV-CM2_562BM1_EA1
A3: CM2_562EA_EA1 | B3: =VLOOKUP(A:A,'DUCW-1'!M:O,2,) -> Cement Mill-1 | C3: =VLOOKUP(A:A,'DUCW-1'!M:O,3,) -> W-DUCW2-CM2-L-PV-CM2_562EA_EA1
A4: CM | B4: =VLOOKUP(A:A,'DUCW-1'!M:O,2,) -> #N/A | C4: =VLOOKUP(A:A,'DUCW-1'!M:O,3,) -> #N/A
A5: 531BI1 | B5: =VLOOKUP(A:A,'DUCW-1'!M:O,2,) -> #N/A | C5: =VLOOKUP(A:A,'DUCW-1'!M:O,3,) -> #N/A
A6: CM2_532BI2_LS | B6: =VLOOKUP(A:A,'DUCW-1'!M:O,2,) -> Cement Mill-1 | C6: =VLOOKUP(A:A,'DUCW-1'!M:O,3,) -> W-DUCW2-CM2-ST-SV-CM2_532BI2_LS
A7: 532BI2 | B7: =VLOOKUP(A:A,'DUCW-1'!M:O,2,) -> #N/A | C7: =VLOOKUP(A:A,'DUCW-1'!M:O,3,) -> #N/A
A8: 562BI1 | B8: =VLOOKUP(A:A,'DUCW-1'!M:O,2,) -> #N/A | C8: =VLOOKUP(A:A,'DUCW-1'!M:O,3,) -> #N/A
A9: 562BF4 | B9: =VLOOKUP(A:A,'DUCW-1'!M:O,2,) -> #N/A | C9: =VLOOKUP(A:A,'DUCW-1'!M:O,3,) -> #N/A
A10: CM2_562BF4_PH | B10: =VLOOKUP(A:A,'DUCW-1'!M:O,2,) -> #N/A | C10: =VLOOKUP(A:A,'DUCW-1'!M:O,3,) -> #N/A
A11: CM2_562BF4_RUN | B11: =VLOOKUP(A:A,'DUCW-1'!M:O,2,) -> #N/A | C11: =VLOOKUP(A:A,'DUCW-1'!M:O,3,) -> #N/A
A12: CM2_562BF4_H01 | B12: =VLOOKUP(A:A,'DUCW-1'!M:O,2,) -> #N/A | C12: =VLOOKUP(A:A,'DUCW-1'!M:O,3,) -> #N/A
A13: CM2_562BF4_HP1_LS | B13: =VLOOKUP(A:A,'DUCW-1'!M:O,2,) -> Cement Mill-1 | C13: =VLOOKUP(A:A,'DUCW-1'!M:O,3,) -> W-DUCW2-CM2-ST-SV-CM2_562BF4_HP1_LS
... A151: CM2_562FM2_PT | B151: =VLOOKUP(A:A,'DUCW-1'!M:O,2,) -> Cement Mill-1 | C151: =VLOOKUP(A:A,'DUCW-1'!M:O,3,) -> W-DUCW2-CM2-P-PV-CM2_562FM2_PT
A152: CM2_562FM2_TOT | B152: =VLOOKUP(A:A,'DUCW-1'!M:O,2,) -> #N/A | C152: =VLOOKUP(A:A,'DUCW-1'!P:R,3,) -> #N/A
A153: CM2_562BM1_PT1 | B153: =VLOOKUP(A:A,'DUCW-1'!M:O,2,) -> Cement Mill-1 | C153: =VLOOKUP(A:A,'DUCW-1'!M:O,3,) -> W-DUCW2-CM2-P-PV-CM2_562BM1_PT1
A154: CM2_562BM1_TT | B154: =VLOOKUP(A:A,'DUCW-1'!M:O,2,) -> Cement Mill-1 | C154: =VLOOKUP(A:A,'DUCW-1'!M:O,3,) -> W-DUCW2-CM2-T-PV-CM2_562BM1_TT
A155: CM2_562BM1_BTE1 | B155: =VLOOKUP(A:A,'DUCW-1'!M:O,2,) -> Cement Mill-1 | C155: =VLOOKUP(A:A,'DUCW-1'!M:O,3,) -> W-DUCW2-CM2-T-PV-CM2_562BM1_BTE1
A156: CM2_562BM1_BTE2 | B156: =VLOOKUP(A:A,'DUCW-1'!M:O,2,) -> Cement Mill-1 | C156: =VLOOKUP(A:A,'DUCW-1'!M:O,3,) -> W-DUCW2-CM2-T-PV-CM2_562BM1_BTE2
A157: CM2_562BM1_BTE5 | B157: =VLOOKUP(A:A,'DUCW-1'!M:O,2,) -> Cement Mill-1 | C157: =VLOOKUP(A:A,'DUCW-1'!M:O,3,) -> W-DUCW2-CM2-T-PV-CM2_562BM1_BTE5
A158: CM2_562BM1_BTE6 | B158: =VLOOKUP(A:A,'DUCW-1'!M:O,2,) -> Cement Mill-1 | C158: =VLOOKUP(A:A,'DUCW-1'!M:O,3,) -> W-DUCW2-CM2-T-PV-CM2_562BM1_BTE6
A159: CM2_562BM1 | B159: =VLOOKUP(A:A,'DUCW-1'!M:O,2,) -> #N/A | C159: =VLOOKUP(A:A,'DUCW-1'!M:O,3,) -> #N/A
A160: CM2_562BM1_BTE8 | B160: =VLOOKUP(A:A,'DUCW-1'!M:O,2,) -> Cement Mill-1 | C160: =VLOOKUP(A:A,'DUCW-1'!M:O,3,) -> W-DUCW2-CM2-T-PV-CM2_562BM1_BTE8
A161: CM2_562BC1II | B161: =VLOOKUP(A:A,'DUCW-1'!M:O,2,) -> #N/A | C161: =VLOOKUP(A:A,'DUCW-1'!P:R,3,) -> #N/A
A162: CM2_562VS1_PT3 | B162: =VLOOKUP(A:A,'DUCW-1'!M:O,2,) -> Cement Mill-1 | C162: =VLOOKUP(A:A,'DUCW-1'!M:O,3,) -> W-DUCW2-CM2-P-PV-CM2_562VS1_PT3
A163: Analog Input Fault | B163: =VLOOKUP(A:A,'DUCW-1'!M:O,2,) -> #N/A | C163: =VLOOKUP(A:A,'DUCW-1'!P:R,3,) -> #N/A
A164: CM2_562RA4_SI | B164: =VLOOKUP(A:A,'DUCW-1'!M:O,2,) -> Cement Mill-1 | C164: =VLOOKUP(A:A,'DUCW-1'!M:O,3,) -> W-DUCW2-CM2-R-PV-CM2_562RA4_SI
A165: CM2_562RA4_SPSPM | B165: =VLOOKUP(A:A,'DUCW-1'!M:O,2,) -> #N/A | C165: =VLOOKUP(A:A,'DUCW-1'!P:R,3,) -> #N/A
A166: CM2_562RA4_II | B166: =VLOOKUP(A:A,'DUCW-1'!M:O,2,) -> Cement Mill-1 | C166: =VLOOKUP(A:A,'DUCW-1'!M:O,3,) -> W-DUCW2-CM2-I-PV-CM2_562RA4_II
A167: CM2_562FM1_FR | B167: =VLOOKUP(A:A,'DUCW-1'!M:O,2,) -> Cement Mill-1 | C167: =VLOOKUP(A:A,'DUCW-1'!M:O,3,) -> W-DUCW2-CM2-F-PV-CM2_562FM1_FR
A168: CM2_562FM1_PT | B168: =VLOOKUP(A:A,'DUCW-1'!M:O,2,) -> Cement Mill-1 | C168: =VLOOKUP(A:A,'DUCW-1'!M:O,3,) -> W-DUCW2-CM2-P-PV-CM2_562FM1_PT
A169: CM2_562FM1_TOT | B169: =VLOOKUP(A:A,'DUCW-1'!M:O,2,) -> #N/A | C169: =VLOOKUP(A:A,'DUCW-1'!M:O,3,) -> #N/A
A170: CM2_562BM1_PT2 | B170: =VLOOKUP(A:A,'DUCW-1'!M:O,2,) -> Cement Mill-1 | C170: =VLOOKUP(A:A,'DUCW-1'!M:O,3,) -> W-DUCW2-CM2-P-PV-CM2_562BM1_PT2
A171: CM2_562BM1_TT2 | B171: =VLOOKUP(A:A,'DUCW-1'!M:O,2,) -> Cement Mill-1 | C171: =VLOOKUP(A:A,'DUCW-1'!M:O,3,) -> W-DUCW2-CM2-T-PV-CM2_562BM1_TT2
A172: CM2_562BM1_BTE3 | B172: =VLOOKUP(A:A,'DUCW-1'!M:O,2,) -> Cement Mill-1 | C172: =VLOOKUP(A:A,'DUCW-1'!M:O,3,) -> W-DUCW2-CM2-T-PV-CM2_562BM1_BTE3
A173: CM2_562BM1_BTE4 | B173: =VLOOKUP(A:A,'DUCW-1'!M:O,2,) -> Cement Mill-1 | C173: =VLOOKUP(A:A,'DUCW-1'!M:O,3,) -> W-DUCW2-CM2-T-PV-CM2_562BM1_BTE4
A174: CM2_562FN6_PT1 | B174: =VLOOKUP(A:A,'DUCW-1'!M:O,2,) -> Cement Mill-1 | C174: =VLOOKUP(A:A,'DUCW-1'!M:O,3,) -> W-DUCW2-CM2-P-PV-CM2_562FN6_PT1
A175: CM2_562FN6_TT1 | B175: =VLOOKUP(A:A,'DUCW-1'!M:O,2,) -> Cement Mill-1 | C175: =VLOOKUP(A:A,'DUCW-1'!M:O,3,) -> W-DUCW2-CM2-T-PV-CM2_562FN6_TT1
A176: CM2_562CN1_PT | B176: =VLOOKUP(A:A,'DUCW-1'!M:O,2,) -> Cement Mill-1 | C176: =VLOOKUP(A:A,'DUCW-1'!M:O,3,) -> W-DUCW2-CM2-P-PV-CM2_562CN1_PT
A177: CM2_562CN2_PT | B177: =VLOOKUP(A:A,'DUCW-1'!M:O,2,) -> Cement Mill-1 | C177: =VLOOKUP(A:A,'DUCW-1'!M:O,3,) -> W-DUCW2-CM2-P-PV-CM2_562CN2_PT
...

Sheet CementSilo
A1: Tags | B1: Section | C1: Tag UID
A2: CG4 | B2: =VLOOKUP(A:A,'DUCW-1'!M:O,2,) -> #N/A | C2: =VLOOKUP(A:A,'DUCW-1'!M:O,3,) -> #N/A
A3: CG5 | B3: =VLOOKUP(A:A,'DUCW-1'!M:O,2,) -> #N/A | C3: =VLOOKUP(A:A,'DUCW-1'!M:O,3,) -> #N/A
A4: CG6 | B4: =VLOOKUP(A:A,'DUCW-1'!M:O,2,) -> #N/A | C4: =VLOOKUP(A:A,'DUCW-1'!M:O,3,) -> #N/A
A5: Force Down | B5: =VLOOKUP(A:A,'DUCW-1'!M:O,2,) -> #N/A | C5: =VLOOKUP(A:A,'DUCW-1'!M:O,3,) -> #N/A
A6: Force UP | B6: =VLOOKUP(A:A,'DUCW-1'!M:O,2,) -> #N/A | C6: =VLOOKUP(A:A,'DUCW-1'!M:O,3,) -> #N/A
A7: NA | B7: =VLOOKUP(A:A,'DUCW-1'!M:O,2,) -> #N/A | C7: =VLOOKUP(A:A,'DUCW-1'!M:O,3,) -> #N/A
A8: Out | B8: =VLOOKUP(A:A,'DUCW-1'!M:O,2,) -> #N/A | C8: =VLOOKUP(A:A,'DUCW-1'!M:O,3,) -> #N/A
A9: PP2_611BI1_WI | B9: =VLOOKUP(A:A,'DUCW-1'!M:O,2,) -> #N/A | C9: =VLOOKUP(A:A,'DUCW-1'!M:O,3,) -> #N/A
A10: PP2_611BI2_WI | B10: =VLOOKUP(A:A,'DUCW-1'!M:O,2,) -> #N/A | C10: =VLOOKUP(A:A,'DUCW-1'!M:O,3,) -> #N/A
A11: PP2_611BI3_WI | B11: =VLOOKUP(A:A,'DUCW-1'!M:O,2,) -> #N/A | C11: =VLOOKUP(A:A,'DUCW-1'!M:O,3,) -> #N/A
A12: PP2_612AE1_SEQ01 | B12: =VLOOKUP(A:A,'DUCW-1'!M:O,2,) -> #N/A | C12: =VLOOKUP(A:A,'DUCW-1'!M:O,3,) -> #N/A
A13: PP2_612AE1_SEQ01_SP | B13: =VLOOKUP(A:A,'DUCW-1'!M:O,2,) -> #N/A | C13: =VLOOKUP(A:A,'DUCW-1'!M:O,3,) -> #N/A
... A88: PP2_612SGK | B88: =VLOOKUP(A:A,'DUCW-1'!M:O,2,) -> #N/A | C88: =VLOOKUP(A:A,'DUCW-1'!M:O,3,) -> #N/A

Sheet ClinkerSiloFeeding
A1: Tags | B1: Section | C1: Tag UID
A2: 492BC1 | B2: =VLOOKUP(A:A,'DUCW-1'!M:O,2,) -> #N/A | C2: =VLOOKUP(A:A,'DUCW-1'!M:O,3,) -> #N/A
A3: 492BC4 | B3: =VLOOKUP(A:A,'DUCW-1'!M:O,2,) -> #N/A | C3: =VLOOKUP(A:A,'DUCW-1'!M:O,3,) -> #N/A
A4: 492CG1 | B4: =VLOOKUP(A:A,'DUCW-1'!M:O,2,) -> #N/A | C4: =VLOOKUP(A:A,'DUCW-1'!M:O,3,) -> #N/A
A5: 492SG1 | B5: =VLOOKUP(A:A,'DUCW-1'!M:O,2,) -> #N/A | C5: =VLOOKUP(A:A,'DUCW-1'!M:O,3,) -> #N/A
A6: 511BC3 | B6: =VLOOKUP(A:A,'DUCW-1'!M:O,2,) -> #N/A | C6: =VLOOKUP(A:A,'DUCW-1'!M:O,3,) -> #N/A
A7: 512BC1 | B7: =VLOOKUP(A:A,'DUCW-1'!M:O,2,) -> #N/A | C7: =VLOOKUP(A:A,'DUCW-1'!M:O,3,) -> #N/A
A8: 512BC2 | B8: =VLOOKUP(A:A,'DUCW-1'!M:O,2,) -> #N/A | C8: =VLOOKUP(A:A,'DUCW-1'!M:O,3,) -> #N/A
A9: 512BC3 | B9: =VLOOKUP(A:A,'DUCW-1'!M:O,2,) -> #N/A | C9: =VLOOKUP(A:A,'DUCW-1'!M:O,3,) -> #N/A
A10: 512BC4 | B10: =VLOOKUP(A:A,'DUCW-1'!M:O,2,) -> #N/A | C10: =VLOOKUP(A:A,'DUCW-1'!M:O,3,) -> #N/A
A11: 512BC5 | B11: =VLOOKUP(A:A,'DUCW-1'!M:O,2,) -> #N/A | C11: =VLOOKUP(A:A,'DUCW-1'!M:O,3,) -> #N/A
A12: 512BE1 | B12: =VLOOKUP(A:A,'DUCW-1'!M:O,2,) -> #N/A | C12: =VLOOKUP(A:A,'DUCW-1'!M:O,3,) -> #N/A
A13: 512BF2 | B13: =VLOOKUP(A:A,'DUCW-1'!M:O,2,) -> #N/A | C13: =VLOOKUP(A:A,'DUCW-1'!M:O,3,) -> #N/A
... A109: To 511BE1 | B109: =VLOOKUP(A:A,'DUCW-1'!M:O,2,) -> #N/A | C109: =VLOOKUP(A:A,'DUCW-1'!M:O,3,) -> #N/A
B110: =VLOOKUP(A:A,'DUCW-1'!M:O,2,) -> #N/A | C110: =VLOOKUP(A:A,'DUCW-1'!M:O,3,) -> #N/A

Sheet FlyashSilo
A1: Tags | B1: Section | C1: Tag UID
A2: BVA | B2: =VLOOKUP(A:A,DUCW!M:O,2,FALSE) -> #N/A | C2: =VLOOKUP(A:A,'DUCW-1'!P:R,3,) -> #N/A
A3: BVB | B3: =VLOOKUP(A:A,DUCW!M:O,2,FALSE) -> #N/A | C3: =VLOOKUP(A:A,'DUCW-1'!P:R,3,) -> #N/A
A4: BV1 | B4: =VLOOKUP(A:A,DUCW!M:O,2,FALSE) -> #N/A | C4: =VLOOKUP(A:A,'DUCW-1'!P:R,3,) -> #N/A
A5: BV5 | B5: =VLOOKUP(A:A,DUCW!M:O,2,FALSE) -> #N/A | C5: =VLOOKUP(A:A,'DUCW-1'!P:R,3,) -> #N/A
A6: BV6 | B6: =VLOOKUP(A:A,DUCW!M:O,2,FALSE) -> #N/A | C6: =VLOOKUP(A:A,'DUCW-1'!P:R,3,) -> #N/A
A7: BV7 | B7: =VLOOKUP(A:A,DUCW!M:O,2,FALSE) -> #N/A | C7: =VLOOKUP(A:A,'DUCW-1'!P:R,3,) -> #N/A
A8: BV9 | B8: =VLOOKUP(A:A,DUCW!M:O,2,FALSE) -> #N/A | C8: =VLOOKUP(A:A,'DUCW-1'!P:R,3,) -> #N/A
A9: BVC | B9: =VLOOKUP(A:A,DUCW!M:O,2,FALSE) -> #N/A | C9: =VLOOKUP(A:A,'DUCW-1'!P:R,3,) -> #N/A
A10: CM_K31CG2_CLS | B10: =VLOOKUP(A:A,DUCW!M:O,2,FALSE) -> #N/A | C10: =VLOOKUP(A:A,'DUCW-1'!P:R,3,) -> #N/A
A11: CM_K31CG2_OLS | B11: =VLOOKUP(A:A,DUCW!M:O,2,FALSE) -> #N/A | C11: =VLOOKUP(A:A,'DUCW-1'!P:R,3,) -> #N/A
A12: CM_K31FN3_PH | B12: =VLOOKUP(A:A,DUCW!M:O,2,FALSE) -> #N/A | C12: =VLOOKUP(A:A,'DUCW-1'!P:R,3,) -> #N/A
A13: CM_K31FN3_RUN | B13: =VLOOKUP(A:A,DUCW!M:O,2,FALSE) -> #N/A | C13: =VLOOKUP(A:A,'DUCW-1'!P:R,3,) -> #N/A
... A184: SP | B184: =VLOOKUP(A:A,DUCW!M:O,2,FALSE) -> #N/A | C184: =VLOOKUP(A:A,'DUCW-1'!P:R,3,) -> #N/A

Sheet FreshFeed
A1: Tags | B1: Section | C1: Tag UID
A2: 532BC1 | B2: =VLOOKUP(A:A,DUCW!M:O,2,FALSE) -> #N/A | C2: =VLOOKUP(A:A,DUCW!M:O,3,) -> #N/A
A3: 532BC2 | B3: =VLOOKUP(A:A,DUCW!M:O,2,FALSE) -> #N/A | C3: =VLOOKUP(A:A,DUCW!M:O,3,) -> #N/A
A4: 532BF1 | B4: =VLOOKUP(A:A,DUCW!M:O,2,FALSE) -> #N/A | C4: =VLOOKUP(A:A,DUCW!M:O,3,) -> #N/A
A5: 532BF2 | B5: =VLOOKUP(A:A,DUCW!M:O,2,FALSE) -> #N/A | C5: =VLOOKUP(A:A,DUCW!M:O,3,) -> #N/A
A6: 532FN1 | B6: =VLOOKUP(A:A,DUCW!M:O,2,FALSE) -> #N/A | C6: =VLOOKUP(A:A,DUCW!M:O,3,) -> #N/A
A7: 532FN2 | B7: =VLOOKUP(A:A,DUCW!M:O,2,FALSE) -> #N/A | C7: =VLOOKUP(A:A,DUCW!M:O,3,) -> #N/A
A8: 532HP1 | B8: =VLOOKUP(A:A,DUCW!M:O,2,FALSE) -> #N/A | C8: =VLOOKUP(A:A,DUCW!M:O,3,) -> #N/A
A9: 532HP2 | B9: =VLOOKUP(A:A,DUCW!M:O,2,FALSE) -> #N/A | C9: =VLOOKUP(A:A,DUCW!M:O,3,) -> #N/A
A10: 532HP3 | B10: =VLOOKUP(A:A,DUCW!M:O,2,FALSE) -> #N/A | C10: =VLOOKUP(A:A,DUCW!M:O,3,) -> #N/A
A11: 532RA1 | B11: =VLOOKUP(A:A,DUCW!M:O,2,FALSE) -> #N/A | C11: =VLOOKUP(A:A,DUCW!M:O,3,) -> #N/A
A12: 532RA2 | B12: =VLOOKUP(A:A,DUCW!M:O,2,FALSE) -> #N/A | C12: =VLOOKUP(A:A,DUCW!M:O,3,) -> #N/A
A13: 532WF1 | B13: =VLOOKUP(A:A,DUCW!M:O,2,FALSE) -> #N/A | C13: =VLOOKUP(A:A,DUCW!M:O,3,) -> #N/A
... A106: Total Feed Control | B106: =VLOOKUP(A:A,DUCW!M:O,2,FALSE) -> #N/A | C106: =VLOOKUP(A:A,DUCW!M:O,3,) -> #N/A

Sheet Packer1and2
A1: Tags | B1: Section | C1: Tag UID
A2: 612ASB | B2: =VLOOKUP(A:A,DUCW!M:O,2,) -> #N/A | C2: =VLOOKUP(A:A,'DUCW-1'!M:O,3,) -> #N/A
A3: 612ASD | B3: =VLOOKUP(A:A,DUCW!M:O,2,) -> #N/A | C3: =VLOOKUP(A:A,'DUCW-1'!M:O,3,) -> #N/A
A4: 642AS1 | B4: =VLOOKUP(A:A,DUCW!M:O,2,) -> #N/A | C4: =VLOOKUP(A:A,'DUCW-1'!M:O,3,) -> #N/A
A5: 642AS2 | B5: =VLOOKUP(A:A,DUCW!M:O,2,) -> #N/A | C5: =VLOOKUP(A:A,'DUCW-1'!M:O,3,) -> #N/A
A6: 642BCD1 | B6: =VLOOKUP(A:A,DUCW!M:O,2,) -> #N/A | C6: =VLOOKUP(A:A,'DUCW-1'!M:O,3,) -> #N/A
A7: 642BCD2 | B7: =VLOOKUP(A:A,DUCW!M:O,2,) -> #N/A | C7: =VLOOKUP(A:A,'DUCW-1'!M:O,3,) -> #N/A
A8: 642BF1 | B8: =VLOOKUP(A:A,DUCW!M:O,2,) -> #N/A | C8: =VLOOKUP(A:A,'DUCW-1'!M:O,3,) -> #N/A
A9: 642BF2 | B9: =VLOOKUP(A:A,DUCW!M:O,2,) -> #N/A | C9: =VLOOKUP(A:A,'DUCW-1'!M:O,3,) -> #N/A
A10: 642BF3 | B10: =VLOOKUP(A:A,DUCW!M:O,2,) -> #N/A | C10: =VLOOKUP(A:A,'DUCW-1'!M:O,3,) -> #N/A
A11: 642BF4 | B11: =VLOOKUP(A:A,DUCW!M:O,2,) -> #N/A | C11: =VLOOKUP(A:A,'DUCW-1'!M:O,3,) -> #N/A
A12: 642BL1 | B12: =VLOOKUP(A:A,DUCW!M:O,2,) -> #N/A | C12: =VLOOKUP(A:A,'DUCW-1'!M:O,3,) -> #N/A
A13: 642BL2 | B13: =VLOOKUP(A:A,DUCW!M:O,2,) -> #N/A | C13: =VLOOKUP(A:A,'DUCW-1'!M:O,3,) -> #N/A
... A141: SP | B141: =VLOOKUP(A:A,DUCW!M:O,2,) -> #N/A | C141: =VLOOKUP(A:A,'DUCW-1'!M:O,3,) -> #N/A
