Workbook

Sheet NCJW
A1: Business Unit | B1: Cluster | C1: Plant | D1: Line | E1: Plant SAP Code | F1: Section | G1: Equipment Group | H1: Equipment Subtype | I1: Variable Group | J1: Variable Type | K1: Standard Variable Description | L1: Unit Of Measurement | M1: Tag Name | N1: Section | O1: Tag Name | P1: Tag UID | Q1: Min | R1: Max | S1: LCL | T1: UCL | U1: Flat Line Length | V1: OPC EndPOint | W1: Path | X1: PropertyID | Y1: AssetID | Z1: IsDisplay | AA1: ConvertToBinary | AB1: PublishingInterval | AC1: IsHighFrequencyTag
A2: CEMENT | B2: W | C2: NCJW | D2: 1 | E2: JF01 | F2: Crusher | G2: Crusher | H2: Other | I2: PV | J2: Count | K2: B15 IDLE TIME | L2: sec | M2: B15_IDLE_TIME | N2: Crusher | O2: B15_IDLE_TIME | P2: W-NCJW1-CR1-C-PV-B15_IDLE_TIME | Q2: 0 | R2: 500 | S2: TBD | T2: TBD | U2: 60 | V2: opc.tcp://10.5.16.43:26080 | W2: ns=2;s=1:B15_IDLE_TIME?Value | X2: 140065a5-45cd-476a-a00b-dd7421f5d6bd | Y2: a34c754d-7b25-479b-80bc-31fe79bff586 | Z2: TRUE | AB2: 60000
A3: CEMENT | B3: W | C3: NCJW | D3: 1 | E3: JF01 | F3: Crusher | G3: Crusher | H3: Other | I3: PV | J3: Count | K3: B3_OPR_COUNT | L3: Count | M3: B3_OPR_COUNT | N3: Crusher | O3: B3_OPR_COUNT | P3: W-NCJW1-CR1-C-PV-B3_OPR_COUNT | Q3: 0 | R3: 500 | S3: TBD | T3: TBD | U3: 60 | V3: opc.tcp://10.5.16.43:26080 | W3: ns=2;s=1:B3_OPR_COUNT?Value | X3: 030e08eb-d5bd-4160-a022-4cc8cf339d2a | Y3: a34c754d-7b25-479b-80bc-31fe79bff586 | Z3: TRUE | AB3: 60000
A4: CEMENT | B4: W | C4: NCJW | D4: 1 | E4: JF01 | F4: Crusher | G4: Crusher | H4: Other | I4: PV | J4: Count | K4: B3 SCALPING FOR RUNHR | L4: hr | M4: B3_RUNHR | N4: Crusher | O4: B3_RUNHR | P4: W-NCJW1-CR1-C-PV-B3_RUNHR | Q4: 0 | R4: 25 | S4: TBD | T4: TBD | U4: 60 | V4: opc.tcp://10.5.16.43:26080 | W4: ns=2;s=1:B3_RUNHR?Value | X4: a7b6d5d1-1735-44c6-8bbf-b07c5aba5447 | Y4: a34c754d-7b25-479b-80bc-31fe79bff586 | Z4: TRUE | AB4: 60000
A5: CEMENT | B5: W | C5: NCJW | D5: 1 | E5: JF01 | F5: Crusher | G5: Crusher | H5: Other | I5: PV | J5: Count | K5: B7 CRUSHER MOTOR RUNHR | L5: hr | M5: B7_RUNHR | N5: Crusher | O5: B7_RUNHR | P5: W-NCJW1-CR1-C-PV-B7_RUNHR | Q5: 0 | R5: 25 | S5: TBD | T5: TBD | U5: 60 | V5: opc.tcp://10.5.16.43:26080 | W5: ns=2;s=1:B7_RUNHR?Value | X5: 961a4684-c5a6-4ca4-9644-c18636748ec3 | Y5: a34c754d-7b25-479b-80bc-31fe79bff586 | Z5: TRUE | AB5: 60000
A6: CEMENT | B6: W | C6: NCJW | D6: 1 | E6: JF01 | F6: Crusher | G6: Crusher | H6: Belt Weigher | I6: PV | J6: Flow | K6: C1 BELT WEIGHER | L6: TPH | M6: B_FT230 | N6: Crusher | O6: B_FT230 | P6: W-NCJW1-CR1-F-PV-B_FT230 | Q6: 0 | R6: 1050 | S6: TBD | T6: TBD | U6: 60 | V6: opc.tcp://10.5.16.43:26080 | W6: ns=2;s=1:B_FT230?Value | X6: 003ef6e1-a493-45e9-a02f-64dbf8fd1380 | Y6: a34c754d-7b25-479b-80bc-31fe79bff586 | Z6: TRUE | AB6: 60000
A7: CEMENT | B7: W | C7: NCJW | D7: 1 | E7: JF01 | F7: Crusher | G7: Crusher | H7: Water Spray | I7: PV | J7: Flow | K7: FS WATER FLOW | L7: LPM | M7: B_FT240 | N7: Crusher | O7: B_FT240 | P7: W-NCJW1-CR1-F-PV-B_FT240 | Q7: 0 | R7: 200 | S7: TBD | T7: TBD | U7: 60 | V7: opc.tcp://10.5.16.43:26080 | W7: ns=2;s=1:B_FT240?Value | X7: 7dbd82c8-e7fa-4e9d-9669-6c957ba1c76f | Y7: a34c754d-7b25-479b-80bc-31fe79bff586 | AB7: 60000
A8: CEMENT | B8: W | C8: NCJW | D8: 1 | E8: JF01 | F8: Crusher | G8: CR-Transport | H8: Belt Weigher | I8: PV | J8: Flow | K8: C19 BELT WEIGHER | L8: TPH | M8: C19_BW | N8: Crusher | O8: C19_BW | P8: W-NCJW1-CR1-F-PV-C19_BW | Q8: 0 | R8: 900 | S8: TBD | T8: TBD | U8: 60 | V8: opc.tcp://10.5.16.43:26080 | W8: ns=2;s=1:C19_BW?Value | X8: 1f7e6409-4f3f-4dcf-bda1-bf21bb12960d | Y8: a34c754d-7b25-479b-80bc-31fe79bff586 | AB8: 60000
A9: CEMENT | B9: W | C9: NCJW | D9: 1 | E9: JF01 | F9: Crusher | G9: CR-Quality | H9: Other | I9: PV | J9: Flow | K9: STACKER_BELT_TPH | L9: TPH | M9: CBA_BELT_WEIGHER | N9: Crusher | O9: CBA_BELT_WEIGHER | P9: W-NCJW1-CR1-F-PV-CBA_BELT_WEIGHER | Q9: 0 | R9: 1000 | S9: TBD | T9: TBD | U9: 60 | V9: opc.tcp://10.5.16.43:26080 | W9: ns=2;s=1:CBA_BELT_WEIGHER?Value | X9: 4f5cd82a-fe4f-4127-8da6-8d26011a4cc3 | Y9: a34c754d-7b25-479b-80bc-31fe79bff586 | Z9: TRUE | AB9: 60000
A10: CEMENT | B10: W | C10: NCJW | D10: 1 | E10: JF01 | F10: Crusher | G10: CR-Controller | H10: PID | I10: PV | J10: Flow | K10: CRUSHER REJECT, Set Point | L10: % | M10: NJ_FC8030_SPM | N10: Crusher | O10: NJ_FC8030_SPM | P10: W-NCJW1-CR1-F-PV-NJ_FC8030_SPM | Q10: 0 | R10: 100 | S10: TBD | T10: TBD | U10: 60 | V10: opc.tcp://10.5.16.43:26080 | W10: ns=2;s=1:NJ_FC8030_SPM?Value | X10: e21d130e-ea21-48d0-ac07-e8a9c6873025 | Y10: a34c754d-7b25-479b-80bc-31fe79bff586 | AB10: 60000
A11: CEMENT | B11: W | C11: NCJW | D11: 1 | E11: JF01 | F11: Crusher | G11: Crusher | H11: VFD | I11: PV | J11: Current | K11: B12_VFD_RPM_FB | L11: amp | M11: B12_VFD_CURRENT_FB | N11: Crusher | O11: B12_VFD_CURRENT_FB | P11: W-NCJW1-CR1-I-PV-B12_VFD_CURRENT_FB | Q11: 0 | R11: 168 | S11: TBD | T11: TBD | U11: 60 | V11: opc.tcp://10.5.16.43:26080 | W11: ns=2;s=1:B12_VFD_CURRENT_FB?Value | X11: 3ea4aea1-cc40-4a9c-8c2b-3fd1c1389139 | Y11: a34c754d-7b25-479b-80bc-31fe79bff586 | Z11: TRUE | AB11: 60000
A12: CEMENT | B12: W | C12: NCJW | D12: 1 | E12: JF01 | F12: Crusher | G12: CR-Transport | H12: Bucket Elevator | I12: PV | J12: Current | K12: B22 BUCKET ELEVATOR CURRENT | L12: amp | M12: B22_BE_CURRENT | N12: Crusher | O12: B22_BE_CURRENT | P12: W-NCJW1-CR1-I-PV-B22_BE_CURRENT | Q12: 0 | R12: 5 | S12: TBD | T12: TBD | U12: 60 | V12: opc.tcp://10.5.16.43:26080 | W12: ns=2;s=1:B22_BE_CURRENT?Value | X12: 28830329-76f7-4547-a607-16a3c5361294 | Y12: a34c754d-7b25-479b-80bc-31fe79bff586 | AB12: 60000
A13: CEMENT | B13: W | C13: NCJW | D13: 1 | E13: JF01 | F13: Crusher | G13: Crusher | H13: Other | I13: PV | J13: Current | K13: B3 CURRENT E3+ | L13: amp | M13: B3_CURRENT | N13: Crusher | O13: B3_CURRENT | P13: W-NCJW1-CR1-I-PV-B3_CURRENT | Q13: 0 | R13: 150 | S13: TBD | T13: TBD | U13: 60 | V13: opc.tcp://10.5.16.43:26080 | W13: ns=2;s=1:B3_CURRENT?Value | X13: f4e7507d-a55d-4859-959e-a67c1f302b62 | Y13: a34c754d-7b25-479b-80bc-31fe79bff586 | AB13: 60000
A14: CEMENT | B14: W | C14: NCJW | D14: 1 | E14: JF01 | F14: Crusher | G14: CR-Controller | H14: PID | I14: PV | J14: Current | K14: B3 SCALPING FEEDER VFD PID AUTO SET PT | L14: amp | M14: B3_SCALPING_VFD_SPA | N14: Crusher | O14: B3_SCALPING_VFD_SPA | P14: W-NCJW1-CR1-I-PV-B3_SCALPING_VFD_SPA | Q14: 0 | R14: 75 | S14: TBD | T14: TBD | U14: 60 | V14: opc.tcp://10.5.16.43:26080 | W14: ns=2;s=1:B3_SCALPING_VFD_SPA?Value | X14: a270fbf0-b08f-478c-a2ff-ea9f02c39246 | Y14: a34c754d-7b25-479b-80bc-31fe79bff586 | Z14: TRUE | AB14: 60000
A15: CEMENT | B15: W | C15: NCJW | D15: 1 | E15: JF01 | F15: Crusher | G15: Crusher | H15: VFD | I15: PV | J15: Current | K15: B3_VFD_current | L15: amp | M15: B3_VFD_current | N15: Crusher | O15: B3_VFD_current | P15: W-NCJW1-CR1-I-PV-B3_VFD_current | Q15: 0 | R15: 88 | S15: TBD | T15: TBD | U15: 60 | V15: opc.tcp://10.5.16.43:26080 | W15: ns=2;s=1:B3_VFD_current?Value | X15: 9f8a3cec-8a59-434a-9193-2d2b7b6d1a9f | Y15: a34c754d-7b25-479b-80bc-31fe79bff586 | Z15: TRUE | AB15: 60000
A16: CEMENT | B16: W | C16: NCJW | D16: 1 | E16: JF01 | F16: Crusher | G16: Crusher | H16: Other | I16: PV | J16: Current | K16: LS CRSHR MOTORCURRENT | L16: amp | M16: B_IT100 | N16: Crusher | O16: B_IT100 | P16: W-NCJW1-CR1-I-PV-B_IT100 | Q16: 0 | R16: 100 | S16: TBD | T16: TBD | U16: 60 | V16: opc.tcp://10.5.16.43:26080 | W16: ns=2;s=1:B_IT100?Value | X16: bc6e1b87-cf97-4853-a70f-0257ffb2dcde | Y16: a34c754d-7b25-479b-80bc-31fe79bff586 | Z16: TRUE | AB16: 60000
A17: CEMENT | B17: W | C17: NCJW | D17: 1 | E17: JF01 | F17: Crusher | G17: Crusher | H17: Other | I17: PV | J17: Current | K17: B15 RBC MOTORCURRENT | L17: amp | M17: B_IT110 | N17: Crusher | O17: B_IT110 | P17: W-NCJW1-CR1-I-PV-B_IT110 | Q17: 0 | R17: 100 | S17: TBD | T17: TBD | U17: 60 | V17: opc.tcp://10.5.16.43:26080 | W17: ns=2;s=1:B_IT110?Value | X17: 9ada599e-268c-4a8f-aaf0-378215036a52 | Y17: a34c754d-7b25-479b-80bc-31fe79bff586 | Z17: TRUE | AB17: 60000
A18: CEMENT | B18: W | C18: NCJW | D18: 1 | E18: JF01 | F18: Crusher | G18: CR-Transport | H18: Belt Conveyor | I18: PV | J18: Current | K18: C1 RBC CURRENT | L18: amp | M18: C1_CURRENT | N18: Crusher | O18: C1_CURRENT | P18: W-NCJW1-CR1-I-PV-C1_CURRENT | Q18: 0 | R18: 500 | S18: TBD | T18: TBD | U18: 60 | V18: opc.tcp://10.5.16.43:26080 | W18: ns=2;s=1:C1_CURRENT?Value | X18: 3e168712-8c19-4bc6-878a-f08c933a6169 | Y18: a34c754d-7b25-479b-80bc-31fe79bff586 | AB18: 60000
A19: CEMENT | B19: W | C19: NCJW | D19: 1 | E19: JF01 | F19: Crusher | G19: CR-Transport | H19: Belt Conveyor | I19: PV | J19: Current | K19: C1 CURRENT E3+ | L19: amp | M19: C1_CURRENT_DB | N19: Crusher | O19: C1_CURRENT_DB | P19: W-NCJW1-CR1-I-PV-C1_CURRENT_DB | Q19: 0 | R19: 150 | S19: TBD | T19: TBD | U19: 60 | V19: opc.tcp://10.5.16.43:26080 | W19: ns=2;s=1:C1_CURRENT_DB?Value | X19: 8259d327-61f3-42ec-80b3-0a6eff8f7243 | Y19: a34c754d-7b25-479b-80bc-31fe79bff586 | Z19: TRUE | AB19: 60000
A20: CEMENT | B20: W | C20: NCJW | D20: 1 | E20: JF01 | F20: Crusher | G20: CR-Drives | H20: Other | I20: PV | J20: Current | K20: B7 MOTOR CURRENT | L20: amp | M20: D_IT1560 | N20: Crusher | O20: D_IT1560 | P20: W-NCJW1-CR1-I-PV-D_IT1560 | Q20: 0 | R20: 100 | S20: TBD | T20: TBD | U20: 60 | V20: opc.tcp://10.5.16.43:26080 | W20: ns=2;s=1:D_IT1560?Value | X20: 1da7045e-6d76-4925-a029-8921f0827fe3 | Y20: a34c754d-7b25-479b-80bc-31fe79bff586 | AB20: 60000
A21: CEMENT | B21: W | C21: NCJW | D21: 1 | E21: JF01 | F21: Crusher | G21: Crusher | H21: Motor | I21: PV | J21: Power | K21: CRUSHER_MAIN_MOTOR_KW | L21: kW | M21: CRS_MCC_KW | N21: Crusher | O21: CRS_MCC_KW | P21: W-NCJW1-CR1-J-PV-CRS_MCC_KW | Q21: 0 | R21: 3000 | S21: TBD | T21: TBD | U21: 60 | V21: opc.tcp://10.5.16.43:26080 | W21: ns=2;s=1:CRS_MCC_KW?Value | X21: 7333e351-fdac-4f87-b1c8-e8e2f6890150 | Y21: a34c754d-7b25-479b-80bc-31fe79bff586 | AB21: 60000
A22: CEMENT | B22: W | C22: NCJW | D22: 1 | E22: JF01 | F22: Crusher | G22: Crusher | H22: Other | I22: PV | J22: Level | K22: C1 BELT WEIGHER DAY TOTAL | L22: tons | M22: B_FT230_DAY_TOT | N22: Crusher | O22: B_FT230_DAY_TOT | P22: W-NCJW1-CR1-L-PV-B_FT230_DAY_TOT | Q22: 0 | R22: 100 | S22: TBD | T22: TBD | U22: 60 | V22: opc.tcp://10.5.16.43:26080 | W22: ns=2;s=1:B_FT230_DAY_TOT?Value | X22: 1dc036b4-1a92-44f6-babe-e3f08f03f976 | Y22: a34c754d-7b25-479b-80bc-31fe79bff586 | Z22: TRUE | AB22: 60000
A23: CEMENT | B23: W | C23: NCJW | D23: 1 | E23: JF01 | F23: Crusher | G23: CR-Storage | H23: Bin | I23: PV | J23: Level | K23: D3 FEEDBIN CONT.LEVEL | L23: % | M23: D_LT1331 | N23: Crusher | O23: D_LT1331 | P23: W-NCJW1-CR1-L-PV-D_LT1331 | Q23: 0 | R23: 100 | S23: TBD | T23: TBD | U23: 60 | V23: opc.tcp://10.5.16.43:26080 | W23: ns=2;s=1:D_LT1331?Value | X23: 13a1e52c-4d14-4906-80b4-1089418071db | Y23: a34c754d-7b25-479b-80bc-31fe79bff586 | AB23: 60000
A24: CEMENT | B24: W | C24: NCJW | D24: 1 | E24: JF01 | F24: Crusher | G24: Crusher | H24: Other | I24: KPI | J24: Others | K24: Crusher Power | L24: kWh/T | M24: CR_SP_PWR | N24: Crusher | O24: CR_SP_PWR | P24: W-NCJW1-CR1-O-KPI-CR_SP_PWR | Q24: 0 | R24: 2 | S24: TBD | T24: TBD | U24: 60 | V24: opc.tcp://10.5.16.43:26080 | W24: ns=2;s=1:CR_SP_PWR?Value | X24: 892c3f29-0788-4bd4-9858-a620ccacf54b | Y24: a34c754d-7b25-479b-80bc-31fe79bff586 | Z24: TRUE | AB24: 60000
A25: CEMENT | B25: W | C25: NCJW | D25: 1 | E25: JF01 | F25: Crusher | G25: Crusher | H25: Other | I25: PV | J25: Others | K25: TIME BETWEEN TWO START 20 MINS | L25: min | M25: B7_TIMER2 | N25: Crusher | O25: B7_TIMER2 | P25: W-NCJW1-CR1-O-PV-B7_TIMER2 | Q25: 0 | R25: 100 | S25: TBD | T25: TBD | U25: 60 | V25: opc.tcp://10.5.16.43:26080 | W25: ns=2;s=1:B7_TIMER2?Value | X25: 8f277f2f-6cf1-480b-a29a-b2327594c12e | Y25: a34c754d-7b25-479b-80bc-31fe79bff586 | Z25: TRUE | AB25: 60000
A26: CEMENT | B26: W | C26: NCJW | D26: 1 | E26: JF01 | F26: Crusher | G26: Crusher | H26: Other | I26: PV | J26: Pressure | K26: FS WATER PRESSURE | L26: bar | M26: B_PT250 | N26: Crusher | O26: B_PT250 | P26: W-NCJW1-CR1-P-PV-B_PT250 | Q26: 0 | R26: 10 | S26: TBD | T26: TBD | U26: 60 | V26: opc.tcp://10.5.16.43:26080 | W26: ns=2;s=1:B_PT250?Value | X26: 9c4d1be2-4661-43ee-92b2-14cd8966e391 | Y26: a34c754d-7b25-479b-80bc-31fe79bff586 | AB26: 60000
A27: CEMENT | B27: W | C27: NCJW | D27: 1 | E27: JF01 | F27: Crusher | G27: Crusher | H27: Other | I27: PV | J27: Pressure | K27: FS AIR PRESSURE | L27: bar | M27: B_PT260 | N27: Crusher | O27: B_PT260 | P27: W-NCJW1-CR1-P-PV-B_PT260 | Q27: 0 | R27: 10 | S27: TBD | T27: TBD | U27: 60 | V27: opc.tcp://10.5.16.43:26080 | W27: ns=2;s=1:B_PT260?Value | X27: 51213956-ae4c-4dbb-9de1-dc0c974a325b | Y27: a34c754d-7b25-479b-80bc-31fe79bff586 | AB27: 60000
A28: CEMENT | B28: W | C28: NCJW | D28: 1 | E28: JF01 | F28: Crusher | G28: Crusher | H28: Bag Filter | I28: PV | J28: Pressure | K28: B12 BAGFILTER DP | L28: mmWC | M28: C_PT1010 | N28: Crusher | O28: C_PT1010 | P28: W-NCJW1-CR1-P-PV-C_PT1010 | Q28: 0 | R28: 300 | S28: TBD | T28: TBD | U28: 60 | V28: opc.tcp://10.5.16.43:26080 | W28: ns=2;s=1:C_PT1010?Value | X28: 6df85e35-2baa-4a49-a49f-af976a927661 | Y28: a34c754d-7b25-479b-80bc-31fe79bff586 | Z28: TRUE | AB28: 60000
A29: CEMENT | B29: W | C29: NCJW | D29: 1 | E29: JF01 | F29: Crusher | G29: Crusher | H29: VFD | I29: PV | J29: Speed | K29: B12_VFD_RPM_SPM | L29: RPM | M29: B12_VFD_RPM_FB | N29: Crusher | O29: B12_VFD_RPM_FB | P29: W-NCJW1-CR1-R-PV-B12_VFD_RPM_FB | Q29: 0 | R29: 1500 | S29: TBD | T29: TBD | U29: 60 | V29: opc.tcp://10.5.16.43:26080 | W29: ns=2;s=1:B12_VFD_RPM_FB?Value | X29: 820c0023-e360-4b83-8e6d-bb985bced7ed | Y29: a34c754d-7b25-479b-80bc-31fe79bff586 | Z29: TRUE | AB29: 60000
A30: CEMENT | B30: W | C30: NCJW | D30: 1 | E30: JF01 | F30: Crusher | G30: CR-Controller | H30: PID | I30: PV | J30: Speed | K30: B12 VFD RPM PID SPM | L30: RPM | M30: B12_VFD_RPM_SPM | N30: Crusher | O30: B12_VFD_RPM_SPM | P30: W-NCJW1-CR1-R-PV-B12_VFD_RPM_SPM | Q30: 0 | R30: 1500 | S30: TBD | T30: TBD | U30: 60 | V30: opc.tcp://10.5.16.43:26080 | W30: ns=2;s=1:B12_VFD_RPM_SPM?Value | X30: faada458-3fcb-452f-8b3b-db3b0acada30 | Y30: a34c754d-7b25-479b-80bc-31fe79bff586 | AB30: 60000
A31: CEMENT | B31: W | C31: NCJW | D31: 1 | E31: JF01 | F31: Crusher | G31: CR-Controller | H31: PID | I31: PV | J31: Speed | K31: B3 VFD PID MANUAL SET POINT | L31: RPM | M31: B3_SCALPING_VFD_SPM | N31: Crusher | O31: B3_SCALPING_VFD_SPM | P31: W-NCJW1-CR1-R-PV-B3_SCALPING_VFD_SPM | Q31: 0 | R31: 1000 | S31: TBD | T31: TBD | U31: 60 | V31: opc.tcp://10.5.16.43:26080 | W31: ns=2;s=1:B3_SCALPING_VFD_SPM?Value | X31: 42837563-ec38-4af4-a2e3-5c4ab81959c0 | Y31: a34c754d-7b25-479b-80bc-31fe79bff586 | AB31: 60000
A32: CEMENT | B32: W | C32: NCJW | D32: 1 | E32: JF01 | F32: Crusher | G32: Crusher | H32: VFD | I32: PV | J32: Speed | K32: B3_VFD_RPM_FB | L32: RPM | M32: B3_VFD_RPM_FB | N32: Crusher | O32: B3_VFD_RPM_FB | P32: W-NCJW1-CR1-R-PV-B3_VFD_RPM_FB | Q32: 0 | R32: 1000 | S32: TBD | T32: TBD | U32: 60 | V32: opc.tcp://10.5.16.43:26080 | W32: ns=2;s=1:B3_VFD_RPM_FB?Value | X32: 8d00ac28-0f4f-47f6-aae5-8ce831545910 | Y32: a34c754d-7b25-479b-80bc-31fe79bff586 | Z32: TRUE | AB32: 60000
A33: CEMENT | B33: W | C33: NCJW | D33: 1 | E33: JF01 | F33: Crusher | G33: Crusher | H33: Other | I33: PV | J33: Speed | K33: B15 RBC MOTION ANALOG | L33: RPM | M33: B_ST120 | N33: Crusher | O33: B_ST120 | P33: W-NCJW1-CR1-R-PV-B_ST120 | Q33: 0 | R33: 100 | S33: TBD | T33: TBD | U33: 60 | V33: opc.tcp://10.5.16.43:26080 | W33: ns=2;s=1:B_ST120?Value | X33: e4658491-6ce2-4473-9ebd-e9714433cabd | Y33: a34c754d-7b25-479b-80bc-31fe79bff586 | Z33: TRUE | AB33: 60000
A34: CEMENT | B34: W | C34: NCJW | D34: 1 | E34: JF01 | F34: Crusher | G34: Crusher | H34: Other | I34: PV | J34: Speed | K34: C1 MOTION ANALOG | L34: RPM | M34: B_ST130 | N34: Crusher | O34: B_ST130 | P34: W-NCJW1-CR1-R-PV-B_ST130 | Q34: 0 | R34: 100 | S34: TBD | T34: TBD | U34: 60 | V34: opc.tcp://10.5.16.43:26080 | W34: ns=2;s=1:B_ST130?Value | X34: bb87b5af-687e-467d-a0cf-f5083a9c31f2 | Y34: a34c754d-7b25-479b-80bc-31fe79bff586 | Z34: TRUE | AB34: 60000
A35: CEMENT | B35: W | C35: NCJW | D35: 1 | E35: JF01 | F35: Crusher | G35: Crusher | H35: Other | I35: PV | J35: Speed | K35: C6 MOTION ANALOG | L35: RPM | M35: B_ST140 | N35: Crusher | O35: B_ST140 | P35: W-NCJW1-CR1-R-PV-B_ST140 | Q35: 0 | R35: 100 | S35: TBD | T35: TBD | U35: 60 | V35: opc.tcp://10.5.16.43:26080 | W35: ns=2;s=1:B_ST140?Value | X35: b16655c7-9cf4-4af1-a8d3-98d4288901c1 | Y35: a34c754d-7b25-479b-80bc-31fe79bff586 | AB35: 60000
A36: CEMENT | B36: W | C36: NCJW | D36: 1 | E36: JF01 | F36: Crusher | G36: Crusher | H36: Other | I36: PV | J36: Speed | K36: C19 MOTION ANALOG | L36: RPM | M36: B_ST150 | N36: Crusher | O36: B_ST150 | P36: W-NCJW1-CR1-R-PV-B_ST150 | Q36: 0 | R36: 100 | S36: TBD | T36: TBD | U36: 60 | V36: opc.tcp://10.5.16.43:26080 | W36: ns=2;s=1:B_ST150?Value | X36: 2af32249-ada8-43e3-afac-53baf3d74dd7 | Y36: a34c754d-7b25-479b-80bc-31fe79bff586 | AB36: 60000
A37: CEMENT | B37: W | C37: NCJW | D37: 1 | E37: JF01 | F37: Crusher | G37: Crusher | H37: Other | I37: PV | J37: Speed | K37: C22_1 MOTION ANALOG | L37: RPM | M37: B_ST160 | N37: Crusher | O37: B_ST160 | P37: W-NCJW1-CR1-R-PV-B_ST160 | Q37: 0 | R37: 100 | S37: TBD | T37: TBD | U37: 60 | V37: opc.tcp://10.5.16.43:26080 | W37: ns=2;s=1:B_ST160?Value | X37: 5510f6d0-077d-4bbe-b9bb-cc23dbcc8aea | Y37: a34c754d-7b25-479b-80bc-31fe79bff586 | AB37: 60000
A38: CEMENT | B38: W | C38: NCJW | D38: 1 | E38: JF01 | F38: Crusher | G38: Crusher | H38: Other | I38: PV | J38: Temperature | K38: CRUSHER PLC ROOM TEMP | L38: deg C | M38: B_PLC_ROOM_TEMP | N38: Crusher | O38: B_PLC_ROOM_TEMP | P38: W-NCJW1-CR1-T-PV-B_PLC_ROOM_TEMP | Q38: 0 | R38: 150 | S38: TBD | T38: TBD | U38: 60 | V38: opc.tcp://10.5.16.43:26080 | W38: ns=2;s=1:B_PLC_ROOM_TEMP?Value | X38: 77614c13-6cb8-49e8-b590-7b87b337042a | Y38: a34c754d-7b25-479b-80bc-31fe79bff586 | Z38: TRUE | AB38: 60000
A39: CEMENT | B39: W | C39: NCJW | D39: 1 | E39: JF01 | F39: Crusher | G39: Crusher | H39: Component | I39: PV | J39: Temperature | K39: LS CRSHRBEARING TEMP-DE | L39: deg C | M39: B_RTD120 | N39: Crusher | O39: B_RTD120 | P39: W-NCJW1-CR1-T-PV-B_RTD120 | Q39: 0 | R39: 150 | S39: TBD | T39: TBD | U39: 60 | V39: opc.tcp://10.5.16.43:26080 | W39: ns=2;s=1:B_RTD120?Value | X39: 393c3895-90f8-40bb-b2e8-ea44dbc33505 | Y39: a34c754d-7b25-479b-80bc-31fe79bff586 | Z39: TRUE | AB39: 60000
A40: CEMENT | B40: W | C40: NCJW | D40: 1 | E40: JF01 | F40: Crusher | G40: Crusher | H40: Component | I40: PV | J40: Temperature | K40: LS CRSHRBEARING TEMP-NDE | L40: deg C | M40: B_RTD130 | N40: Crusher | O40: B_RTD130 | P40: W-NCJW1-CR1-T-PV-B_RTD130 | Q40: 0 | R40: 150 | S40: TBD | T40: TBD | U40: 60 | V40: opc.tcp://10.5.16.43:26080 | W40: ns=2;s=1:B_RTD130?Value | X40: e86d05ec-4db9-4b42-8864-28dc4f141b56 | Y40: a34c754d-7b25-479b-80bc-31fe79bff586 | Z40: TRUE | AB40: 60000
...

Sheet NCJW-AlternateFuelSystem
A1: Tag Name | B1: Section | C1: Tag UID
A2: 261WF150 | B2: =VLOOKUP(A2,NCJW!M:N,2,FALSE) -> #N/A | C2: =VLOOKUP(A2,NCJW!O:P,2,FALSE) -> #N/A
A3: 261BC610 | B3: =VLOOKUP(A3,NCJW!M:N,2,FALSE) -> #N/A | C3: =VLOOKUP(A3,NCJW!O:P,2,FALSE) -> #N/A
A4: 261DPC700 | B4: =VLOOKUP(A4,NCJW!M:N,2,FALSE) -> #N/A | C4: =VLOOKUP(A4,NCJW!O:P,2,FALSE) -> #N/A
A5: HOPPER 261FY110 | B5: =VLOOKUP(A5,NCJW!M:N,2,FALSE) -> #N/A | C5: =VLOOKUP(A5,NCJW!O:P,2,FALSE) -> #N/A
A6: Calciner 6th Floor | B6: =VLOOKUP(A6,NCJW!M:N,2,FALSE) -> #N/A | C6: =VLOOKUP(A6,NCJW!O:P,2,FALSE) -> #N/A
A7: 261TI100 | B7: =VLOOKUP(A7,NCJW!M:N,2,FALSE) -> #N/A | C7: =VLOOKUP(A7,NCJW!O:P,2,FALSE) -> #N/A
A8: _261BC700_DISH_CHUTE_BLK | B8: =VLOOKUP(A8,NCJW!M:N,2,FALSE) -> #N/A | C8: =VLOOKUP(A8,NCJW!O:P,2,FALSE) -> #N/A
A9: DRIVE-3 (2,3,4) | B9: =VLOOKUP(A9,NCJW!M:N,2,FALSE) -> #N/A | C9: =VLOOKUP(A9,NCJW!O:P,2,FALSE) -> #N/A
A10: 261FY110D3_U01I01 | B10: =VLOOKUP(A10,NCJW!M:N,2,FALSE) -> PreHeater | C10: =VLOOKUP(A10,NCJW!O:P,2,FALSE) -> W-NCJW1-PH1-I-PV-261FY110D3_U01I01
A11: 261FY110D3_U01S01 | B11: =VLOOKUP(A11,NCJW!M:N,2,FALSE) -> PreHeater | C11: =VLOOKUP(A11,NCJW!O:P,2,FALSE) -> W-NCJW1-PH1-R-PV-261FY110D3_U01S01
A12: 261FY110D3_U01S11_SPM | B12: =VLOOKUP(A12,NCJW!M:N,2,FALSE) -> PreHeater | C12: =VLOOKUP(A12,NCJW!O:P,2,FALSE) -> W-NCJW1-PH1-O-PV-261FY110D3_U01S11_SPM
A13: DRIVE-2 (1,5) | B13: =VLOOKUP(A13,NCJW!M:N,2,FALSE) -> #N/A | C13: =VLOOKUP(A13,NCJW!O:P,2,FALSE) -> #N/A
... A83: _261RF711_CURRENT | B83: =VLOOKUP(A83,NCJW!M:N,2,FALSE) -> #N/A | C83: =VLOOKUP(A83,NCJW!O:P,2,FALSE) -> #N/A

Sheet NCJW-Bag House
A1: Tag Name | B1: Section | C1: Tag UID
A2: RABH Stack SOX Counter | B2: =VLOOKUP(A2,NCJW!M:N,2,FALSE) -> #N/A | C2: =VLOOKUP(A2,NCJW!O:P,2,FALSE) -> #N/A
A3: RABH_STACK_SOX_COUNTER | B3: =VLOOKUP(A3,NCJW!M:N,2,FALSE) -> #N/A | C3: =VLOOKUP(A3,NCJW!O:P,2,FALSE) -> #N/A
A4: RABH Stack Opacity Counter | B4: =VLOOKUP(A4,NCJW!M:N,2,FALSE) -> #N/A | C4: =VLOOKUP(A4,NCJW!O:P,2,FALSE) -> #N/A
A5: RABH_STACK_COUNTER | B5: =VLOOKUP(A5,NCJW!M:N,2,FALSE) -> #N/A | C5: =VLOOKUP(A5,NCJW!O:P,2,FALSE) -> #N/A
A6: RABH Stack NOX Counter | B6: =VLOOKUP(A6,NCJW!M:N,2,FALSE) -> #N/A | C6: =VLOOKUP(A6,NCJW!O:P,2,FALSE) -> #N/A
A7: RABH_STACK_NOX_COUNTER | B7: =VLOOKUP(A7,NCJW!M:N,2,FALSE) -> #N/A | C7: =VLOOKUP(A7,NCJW!O:P,2,FALSE) -> #N/A
A8: ESP_Stack_Counter | B8: =VLOOKUP(A8,NCJW!M:N,2,FALSE) -> #N/A | C8: =VLOOKUP(A8,NCJW!O:P,2,FALSE) -> #N/A
A9: FCR_YT302E_ESP_STACK_COUNTER | B9: =VLOOKUP(A9,NCJW!M:N,2,FALSE) -> #N/A | C9: =VLOOKUP(A9,NCJW!O:P,2,FALSE) -> #N/A
A10: COAL_Stack_Counter | B10: =VLOOKUP(A10,NCJW!M:N,2,FALSE) -> #N/A | C10: =VLOOKUP(A10,NCJW!O:P,2,FALSE) -> #N/A
A11: _462AM420_A01A01_COAL_STACK_COUNTER | B11: =VLOOKUP(A11,NCJW!M:N,2,FALSE) -> #N/A | C11: =VLOOKUP(A11,NCJW!O:P,2,FALSE) -> #N/A
A12: RM FAN O/L DRAFT_NEW | B12: =VLOOKUP(A12,NCJW!M:N,2,FALSE) -> #N/A | C12: =VLOOKUP(A12,NCJW!O:P,2,FALSE) -> #N/A
A13: F_TC2111_SPA | B13: =VLOOKUP(A13,NCJW!M:N,2,FALSE) -> Raw Mill | C13: =VLOOKUP(A13,NCJW!O:P,2,FALSE) -> W-NCJW1-RM1-T-CSP-F_TC2111_SPA
... A97: Dust Transport | B97: =VLOOKUP(A97,NCJW!M:N,2,FALSE) -> #N/A | C97: =VLOOKUP(A97,NCJW!O:P,2,FALSE) -> #N/A

Sheet NCJW-Cementmill
A1: Tag Name | B1: Section | C1: Tag UID
A2: NJ8008_T2_TMP | B2: =VLOOKUP(A2,NCJW!M:N,2,FALSE) -> #N/A | C2: =VLOOKUP(A2,NCJW!O:P,2,FALSE) -> #N/A
A3: NJ8010_TI | B3: =VLOOKUP(A3,NCJW!M:N,2,FALSE) -> Cooler | C3: =VLOOKUP(A3,NCJW!O:P,2,FALSE) -> W-NCJW1-CL1-T-PV-NJ8010_TI
A4: NJ_FI8054 | B4: =VLOOKUP(A4,NCJW!M:N,2,FALSE) -> Cement Mill | C4: =VLOOKUP(A4,NCJW!O:P,2,FALSE) -> W-NCJW1-CM1-F-PV-NJ_FI8054
A5: NJ_FC8054_SPA | B5: =VLOOKUP(A5,NCJW!M:N,2,FALSE) -> Cement Mill | C5: =VLOOKUP(A5,NCJW!O:P,2,FALSE) -> W-NCJW1-CM1-F-CSP-NJ_FC8054_SPA
A6: CLINKER | B6: =VLOOKUP(A6,NCJW!M:N,2,FALSE) -> #N/A | C6: =VLOOKUP(A6,NCJW!O:P,2,FALSE) -> #N/A
A7: NCM_CRUSH_BIN_LEVEL | B7: =VLOOKUP(A7,NCJW!M:N,2,FALSE) -> Cement Mill | C7: =VLOOKUP(A7,NCJW!O:P,2,FALSE) -> W-NCJW1-CM1-L-PV-NCM_CRUSH_BIN_LEVEL
A8: NCJW_CRUSH_BIN_TEMP | B8: =VLOOKUP(A8,NCJW!M:N,2,FALSE) -> Cement Mill | C8: =VLOOKUP(A8,NCJW!O:P,2,FALSE) -> W-NCJW1-CM1-T-PV-NCJW_CRUSH_BIN_TEMP
A9: NJ_FI8060 | B9: =VLOOKUP(A9,NCJW!M:N,2,FALSE) -> Cement Mill | C9: =VLOOKUP(A9,NCJW!O:P,2,FALSE) -> W-NCJW1-CM1-F-PV-NJ_FI8060
A10: NJ_FC8060_SPA | B10: =VLOOKUP(A10,NCJW!M:N,2,FALSE) -> Cement Mill | C10: =VLOOKUP(A10,NCJW!O:P,2,FALSE) -> W-NCJW1-CM1-F-CSP-NJ_FC8060_SPA
A11: J8060_LEVEL_TX | B11: =VLOOKUP(A11,NCJW!M:N,2,FALSE) -> #N/A | C11: =VLOOKUP(A11,NCJW!O:P,2,FALSE) -> #N/A
A12: GYPSUM | B12: =VLOOKUP(A12,NCJW!M:N,2,FALSE) -> #N/A | C12: =VLOOKUP(A12,NCJW!O:P,2,FALSE) -> #N/A
A13: NJ_FI8042 | B13: =VLOOKUP(A13,NCJW!M:N,2,FALSE) -> Cement Mill | C13: =VLOOKUP(A13,NCJW!O:P,2,FALSE) -> W-NCJW1-CM1-F-PV-NJ_FI8042
... A121: J8155 | B121: =VLOOKUP(A121,NCJW!M:N,2,FALSE) -> #N/A | C121: =VLOOKUP(A121,NCJW!O:P,2,FALSE) -> #N/A

Sheet NCJW-ClinketTransport
A1: Tag Name | B1: Section | C1: Tag UID
A2: F55.1 | B2: =VLOOKUP('NCJW-ClinketTransport'!A2,NCJW!M:N,2,FALSE) -> #N/A | C2: =VLOOKUP(A2,NCJW!O:P,2,FALSE) -> #N/A
A3: F62 | B3: =VLOOKUP('NCJW-ClinketTransport'!A3,NCJW!M:N,2,FALSE) -> #N/A | C3: =VLOOKUP(A3,NCJW!O:P,2,FALSE) -> #N/A
A4: F706_NEW | B4: =VLOOKUP('NCJW-ClinketTransport'!A4,NCJW!M:N,2,FALSE) -> #N/A | C4: =VLOOKUP(A4,NCJW!O:P,2,FALSE) -> #N/A
A5: F75 | B5: =VLOOKUP('NCJW-ClinketTransport'!A5,NCJW!M:N,2,FALSE) -> #N/A | C5: =VLOOKUP(A5,NCJW!O:P,2,FALSE) -> #N/A
A6: F76 | B6: =VLOOKUP('NCJW-ClinketTransport'!A6,NCJW!M:N,2,FALSE) -> #N/A | C6: =VLOOKUP(A6,NCJW!O:P,2,FALSE) -> #N/A
A7: F77 | B7: =VLOOKUP('NCJW-ClinketTransport'!A7,NCJW!M:N,2,FALSE) -> #N/A | C7: =VLOOKUP(A7,NCJW!O:P,2,FALSE) -> #N/A
A8: F78 | B8: =VLOOKUP('NCJW-ClinketTransport'!A8,NCJW!M:N,2,FALSE) -> #N/A | C8: =VLOOKUP(A8,NCJW!O:P,2,FALSE) -> #N/A
A9: Gate 3 | B9: =VLOOKUP('NCJW-ClinketTransport'!A9,NCJW!M:N,2,FALSE) -> #N/A | C9: =VLOOKUP(A9,NCJW!O:P,2,FALSE) -> #N/A
A10: Gate 2 | B10: =VLOOKUP('NCJW-ClinketTransport'!A10,NCJW!M:N,2,FALSE) -> #N/A | C10: =VLOOKUP(A10,NCJW!O:P,2,FALSE) -> #N/A
A11: Gate 4 | B11: =VLOOKUP('NCJW-ClinketTransport'!A11,NCJW!M:N,2,FALSE) -> #N/A | C11: =VLOOKUP(A11,NCJW!O:P,2,FALSE) -> #N/A
A12: F-92 Gate | B12: =VLOOKUP('NCJW-ClinketTransport'!A12,NCJW!M:N,2,FALSE) -> #N/A | C12: =VLOOKUP(A12,NCJW!O:P,2,FALSE) -> #N/A
A13: 1) DESLECT JETTY GATE F86.1, 2, 5, & 6 | B13: =VLOOKUP('NCJW-ClinketTransport'!A13,NCJW!M:N,2,FALSE) -> #N/A | C13: =VLOOKUP(A13,NCJW!O:P,2,FALSE) -> #N/A
... A27: F-202 | B27: =VLOOKUP('NCJW-ClinketTransport'!A27,NCJW!M:N,2,FALSE) -> #N/A | C27: =VLOOKUP(A27,NCJW!O:P,2,FALSE) -> #N/A
A28: N_F202_IT | B28: =VLOOKUP('NCJW-ClinketTransport'!A28,NCJW!M:N,2,FALSE) -> General | C28: =VLOOKUP(A28,NCJW!O:P,2,FALSE) -> W-NCJW1-JT1-I-PV-N_F202_IT | I28: 261WF150_A01F11_SPA
A29: F705 MOTION | B29: =VLOOKUP('NCJW-ClinketTransport'!A29,NCJW!M:N,2,FALSE) -> #N/A | C29: =VLOOKUP(A29,NCJW!O:P,2,FALSE) -> #N/A
A30: F705_CURRENT | B30: =VLOOKUP('NCJW-ClinketTransport'!A30,NCJW!M:N,2,FALSE) -> #N/A | C30: =VLOOKUP(A30,NCJW!O:P,2,FALSE) -> #N/A
A31: F705 RPM | B31: =VLOOKUP('NCJW-ClinketTransport'!A31,NCJW!M:N,2,FALSE) -> #N/A | C31: =VLOOKUP(A31,NCJW!O:P,2,FALSE) -> #N/A
A32: F705_DPC_SPEED | B32: =VLOOKUP('NCJW-ClinketTransport'!A32,NCJW!M:N,2,FALSE) -> Cooler | C32: =VLOOKUP(A32,NCJW!O:P,2,FALSE) -> W-NCJW1-CL1-R-PV-F705_DPC_SPEED
A33: F75_1_RH | B33: =VLOOKUP('NCJW-ClinketTransport'!A33,NCJW!M:N,2,FALSE) -> #N/A | C33: =VLOOKUP(A33,NCJW!O:P,2,FALSE) -> #N/A
A34: F83_1_AMPS | B34: =VLOOKUP('NCJW-ClinketTransport'!A34,NCJW!M:N,2,FALSE) -> #N/A | C34: =VLOOKUP(A34,NCJW!O:P,2,FALSE) -> #N/A
A35: F83_1_SPEED | B35: =VLOOKUP('NCJW-ClinketTransport'!A35,NCJW!M:N,2,FALSE) -> #N/A | C35: =VLOOKUP(A35,NCJW!O:P,2,FALSE) -> #N/A
A36: 471AC100N01T01 | B36: =VLOOKUP('NCJW-ClinketTransport'!A36,NCJW!M:N,2,FALSE) -> Cooler | C36: =VLOOKUP(A36,NCJW!O:P,2,FALSE) -> W-NCJW1-CL1-T-PV-471AC100N01T01
A37: F55_CURRENT | B37: =VLOOKUP('NCJW-ClinketTransport'!A37,NCJW!M:N,2,FALSE) -> Cooler | C37: =VLOOKUP(A37,NCJW!O:P,2,FALSE) -> W-NCJW1-CL1-I-PV-F55_CURRENT
A38: F55_PYRO_DISCHARGE | B38: =VLOOKUP('NCJW-ClinketTransport'!A38,NCJW!M:N,2,FALSE) -> Cooler | C38: =VLOOKUP(A38,NCJW!O:P,2,FALSE) -> W-NCJW1-CL1-T-PV-F55_PYRO_DISCHARGE
A39: Cooler | B39: =VLOOKUP('NCJW-ClinketTransport'!A39,NCJW!M:N,2,FALSE) -> #N/A | C39: =VLOOKUP(A39,NCJW!O:P,2,FALSE) -> #N/A
A40: GROUND | B40: =VLOOKUP('NCJW-ClinketTransport'!A40,NCJW!M:N,2,FALSE) -> #N/A | C40: =VLOOKUP(A40,NCJW!O:P,2,FALSE) -> #N/A
A41: Clinker | B41: =VLOOKUP('NCJW-ClinketTransport'!A41,NCJW!M:N,2,FALSE) -> #N/A | C41: =VLOOKUP(A41,NCJW!O:P,2,FALSE) -> #N/A

Sheet NCJW-Coalmill
A1: Tag Name | B1: Section | C1: Tag UID
A2: BI050_RTD1 | B2: =VLOOKUP(A2,NCJW!M:N,2,FALSE) -> #N/A | C2: =VLOOKUP(A2,NCJW!O:P,2,FALSE) -> #N/A
A3: 462LC035_A01W01 | B3: =VLOOKUP(A3,NCJW!M:N,2,FALSE) -> Coal Mill | C3: =VLOOKUP(A3,NCJW!O:P,2,FALSE) -> W-NCJW1-KM1-L-PV-462LC035_A01W01
A4: PETCOKE BI050 | B4: =VLOOKUP(A4,NCJW!M:N,2,FALSE) -> #N/A | C4: =VLOOKUP(A4,NCJW!O:P,2,FALSE) -> #N/A
A5: BI050_RTD2 | B5: =VLOOKUP(A5,NCJW!M:N,2,FALSE) -> #N/A | C5: =VLOOKUP(A5,NCJW!O:P,2,FALSE) -> #N/A
A6: BI030_RTD1 | B6: =VLOOKUP(A6,NCJW!M:N,2,FALSE) -> #N/A | C6: =VLOOKUP(A6,NCJW!O:P,2,FALSE) -> #N/A
A7: 462LC055_A01W01 | B7: =VLOOKUP(A7,NCJW!M:N,2,FALSE) -> Coal Mill | C7: =VLOOKUP(A7,NCJW!O:P,2,FALSE) -> W-NCJW1-KM1-L-PV-462LC055_A01W01
A8: MOZ BI030 | B8: =VLOOKUP(A8,NCJW!M:N,2,FALSE) -> #N/A | C8: =VLOOKUP(A8,NCJW!O:P,2,FALSE) -> #N/A
A9: BI030_RTD2 | B9: =VLOOKUP(A9,NCJW!M:N,2,FALSE) -> #N/A | C9: =VLOOKUP(A9,NCJW!O:P,2,FALSE) -> #N/A
A10: WF065 PID | B10: =VLOOKUP(A10,NCJW!M:N,2,FALSE) -> #N/A | C10: =VLOOKUP(A10,NCJW!O:P,2,FALSE) -> #N/A
A11: 462WF065_A01S01 | B11: =VLOOKUP(A11,NCJW!M:N,2,FALSE) -> Coal Mill | C11: =VLOOKUP(A11,NCJW!O:P,2,FALSE) -> W-NCJW1-KM1-R-PV-462WF065_A01S01
A12: 462WF065_N01I01 | B12: =VLOOKUP(A12,NCJW!M:N,2,FALSE) -> Coal Mill | C12: =VLOOKUP(A12,NCJW!O:P,2,FALSE) -> W-NCJW1-KM1-I-PV-462WF065_N01I01
A13: WF065_MSP | B13: =VLOOKUP(A13,NCJW!M:N,2,FALSE) -> #N/A | C13: =VLOOKUP(A13,NCJW!O:P,2,FALSE) -> #N/A
... A165: BI750_GAS_ANA_CO | B165: =VLOOKUP(A165,NCJW!M:N,2,FALSE) -> #N/A | C165: =VLOOKUP(A165,NCJW!O:P,2,FALSE) -> #N/A

Sheet NCJW-CoalMillFeeding
A1: Tag Name | B1: Section | C1: Tag UID
A2: PETCOKE HOPPER | B2: =VLOOKUP(A2,NCJW!M:N,2,FALSE) -> #N/A | C2: =VLOOKUP(A2,NCJW!O:P,2,FALSE) -> #N/A
A3: COAL HOPPER | B3: =VLOOKUP(A3,NCJW!M:N,2,FALSE) -> #N/A | C3: =VLOOKUP(A3,NCJW!O:P,2,FALSE) -> #N/A
A4: F169 | B4: =VLOOKUP(A4,NCJW!M:N,2,FALSE) -> #N/A | C4: =VLOOKUP(A4,NCJW!O:P,2,FALSE) -> #N/A
A5: F171 | B5: =VLOOKUP(A5,NCJW!M:N,2,FALSE) -> #N/A | C5: =VLOOKUP(A5,NCJW!O:P,2,FALSE) -> #N/A
A6: _F171_M01I01 | B6: =VLOOKUP(A6,NCJW!M:N,2,FALSE) -> Coal Mill | C6: =VLOOKUP(A6,NCJW!O:P,2,FALSE) -> W-NCJW1-KM1-I-PV-_F171_M01I01
A7: _F171_MACHINE_GUARD_SW | B7: =VLOOKUP(A7,NCJW!M:N,2,FALSE) -> #N/A | C7: =VLOOKUP(A7,NCJW!O:P,2,FALSE) -> #N/A
A8: F173 NEW | B8: =VLOOKUP(A8,NCJW!M:N,2,FALSE) -> #N/A | C8: =VLOOKUP(A8,NCJW!O:P,2,FALSE) -> #N/A
A9: _F173_M01I01 | B9: =VLOOKUP(A9,NCJW!M:N,2,FALSE) -> Coal Mill | C9: =VLOOKUP(A9,NCJW!O:P,2,FALSE) -> W-NCJW1-KM1-I-PV-_F173_M01I01
A10: _F173_MACHINE_GUARD_SW | B10: =VLOOKUP(A10,NCJW!M:N,2,FALSE) -> #N/A | C10: =VLOOKUP(A10,NCJW!O:P,2,FALSE) -> #N/A
A11: BC010 | B11: =VLOOKUP(A11,NCJW!M:N,2,FALSE) -> #N/A | C11: =VLOOKUP(A11,NCJW!O:P,2,FALSE) -> #N/A
A12: _BC10_MACHINE_GUARD_SW | B12: =VLOOKUP(A12,NCJW!M:N,2,FALSE) -> #N/A | C12: =VLOOKUP(A12,NCJW!O:P,2,FALSE) -> #N/A
A13: 462BC015_M01I01 | B13: =VLOOKUP(A13,NCJW!M:N,2,FALSE) -> Coal Mill | C13: =VLOOKUP(A13,NCJW!O:P,2,FALSE) -> W-NCJW1-KM1-I-PV-462BC015_M01I01
... A61: 462FN022_M01I01 | B61: =VLOOKUP(A61,NCJW!M:N,2,FALSE) -> Coal Mill | C61: =VLOOKUP(A61,NCJW!O:P,2,FALSE) -> W-NCJW1-KM1-I-PV-462FN022_M01I01

Sheet NCJW-cooler
A1: Tag Name | B1: Section | C1: Tag UID
A2: 441CC100N11T01 | B2: =VLOOKUP('NCJW-cooler'!A2,NCJW!M:N,2,FALSE) -> Cooler | C2: =VLOOKUP(A2,NCJW!O:P,2,FALSE) -> W-NCJW1-CL1-T-PV-441CC100N11T01
A3: 441CC100N21T01 | B3: =VLOOKUP('NCJW-cooler'!A3,NCJW!M:N,2,FALSE) -> Cooler | C3: =VLOOKUP(A3,NCJW!O:P,2,FALSE) -> W-NCJW1-CL1-T-PV-441CC100N21T01
A4: 441CC100N31T01 | B4: =VLOOKUP('NCJW-cooler'!A4,NCJW!M:N,2,FALSE) -> Cooler | C4: =VLOOKUP(A4,NCJW!O:P,2,FALSE) -> W-NCJW1-CL1-T-PV-441CC100N31T01
A5: 441CC100N12T01 | B5: =VLOOKUP('NCJW-cooler'!A5,NCJW!M:N,2,FALSE) -> Cooler | C5: =VLOOKUP(A5,NCJW!O:P,2,FALSE) -> W-NCJW1-CL1-T-PV-441CC100N12T01
A6: 441CC100N22T01 | B6: =VLOOKUP('NCJW-cooler'!A6,NCJW!M:N,2,FALSE) -> Cooler | C6: =VLOOKUP(A6,NCJW!O:P,2,FALSE) -> W-NCJW1-CL1-T-PV-441CC100N22T01
A7: 441CC100N32T01 | B7: =VLOOKUP('NCJW-cooler'!A7,NCJW!M:N,2,FALSE) -> Cooler | C7: =VLOOKUP(A7,NCJW!O:P,2,FALSE) -> W-NCJW1-CL1-T-PV-441CC100N32T01
A8: MD140A01S11_SP | B8: =VLOOKUP('NCJW-cooler'!A8,NCJW!M:N,2,FALSE) -> Cooler | C8: =VLOOKUP(A8,NCJW!O:P,2,FALSE) -> W-NCJW1-CL1-R-PV-MD140A01S11_SP
A9: 441FN305N02P01_PID_SPM | B9: =VLOOKUP('NCJW-cooler'!A9,NCJW!M:N,2,FALSE) -> Cooler | C9: =VLOOKUP(A9,NCJW!O:P,2,FALSE) -> W-NCJW1-CL1-O-COP-441FN305N02P01_PID_SPM
A10: MD140A01S13_SP | B10: =VLOOKUP('NCJW-cooler'!A10,NCJW!M:N,2,FALSE) -> Cooler | C10: =VLOOKUP(A10,NCJW!O:P,2,FALSE) -> W-NCJW1-CL1-R-PV-MD140A01S13_SP
A11: MD140A01S01 | B11: =VLOOKUP('NCJW-cooler'!A11,NCJW!M:N,2,FALSE) -> Cooler | C11: =VLOOKUP(A11,NCJW!O:P,2,FALSE) -> W-NCJW1-CL1-R-PV-MD140A01S01
A12: MD140A01S02 | B12: =VLOOKUP('NCJW-cooler'!A12,NCJW!M:N,2,FALSE) -> Cooler | C12: =VLOOKUP(A12,NCJW!O:P,2,FALSE) -> W-NCJW1-CL1-R-PV-MD140A01S02
A13: MD140A01S03 | B13: =VLOOKUP('NCJW-cooler'!A13,NCJW!M:N,2,FALSE) -> Cooler | C13: =VLOOKUP(A13,NCJW!O:P,2,FALSE) -> W-NCJW1-CL1-R-PV-MD140A01S03
... A205: F44_ANALG_SPEED | B205: =VLOOKUP('NCJW-cooler'!A205,NCJW!M:N,2,FALSE) -> #N/A | C205: =VLOOKUP(A205,NCJW!O:P,2,FALSE) -> #N/A

Sheet NCJW-Crusher
A1: Tag Name | B1: Section | C1: Tag UID
A2: B7 MOTOR TEMPERATURE | B2: =VLOOKUP(A2,NCJW!M:N,2,FALSE) -> #N/A | C2: =VLOOKUP(A2,NCJW!O:P,2,FALSE) -> #N/A
A3: B_RTD140 | B3: =VLOOKUP(A3,NCJW!M:N,2,FALSE) -> Crusher | C3: =VLOOKUP(A3,NCJW!O:P,2,FALSE) -> W-NCJW1-CR1-T-PV-B_RTD140
A4: B_RTD170 | B4: =VLOOKUP(A4,NCJW!M:N,2,FALSE) -> Crusher | C4: =VLOOKUP(A4,NCJW!O:P,2,FALSE) -> W-NCJW1-CR1-T-PV-B_RTD170
A5: B_RTD150 | B5: =VLOOKUP(A5,NCJW!M:N,2,FALSE) -> Crusher | C5: =VLOOKUP(A5,NCJW!O:P,2,FALSE) -> W-NCJW1-CR1-T-PV-B_RTD150
A6: B_RTD180 | B6: =VLOOKUP(A6,NCJW!M:N,2,FALSE) -> Crusher | C6: =VLOOKUP(A6,NCJW!O:P,2,FALSE) -> W-NCJW1-CR1-T-PV-B_RTD180
A7: B_RTD160 | B7: =VLOOKUP(A7,NCJW!M:N,2,FALSE) -> Crusher | C7: =VLOOKUP(A7,NCJW!O:P,2,FALSE) -> W-NCJW1-CR1-T-PV-B_RTD160
A8: B_RTD190 | B8: =VLOOKUP(A8,NCJW!M:N,2,FALSE) -> Crusher | C8: =VLOOKUP(A8,NCJW!O:P,2,FALSE) -> W-NCJW1-CR1-T-PV-B_RTD190
A9: B_RTD200 | B9: =VLOOKUP(A9,NCJW!M:N,2,FALSE) -> Crusher | C9: =VLOOKUP(A9,NCJW!O:P,2,FALSE) -> W-NCJW1-CR1-T-PV-B_RTD200
A10: B_RTD210 | B10: =VLOOKUP(A10,NCJW!M:N,2,FALSE) -> Crusher | C10: =VLOOKUP(A10,NCJW!O:P,2,FALSE) -> W-NCJW1-CR1-T-PV-B_RTD210
A11: EQUIPMENTS RUN HOUR | B11: =VLOOKUP(A11,NCJW!M:N,2,FALSE) -> #N/A | C11: =VLOOKUP(A11,NCJW!O:P,2,FALSE) -> #N/A
A12: B3 RUN HOURS | B12: =VLOOKUP(A12,NCJW!M:N,2,FALSE) -> #N/A | C12: =VLOOKUP(A12,NCJW!O:P,2,FALSE) -> #N/A
A13: B3_RUNHR | B13: =VLOOKUP(A13,NCJW!M:N,2,FALSE) -> Crusher | C13: =VLOOKUP(A13,NCJW!O:P,2,FALSE) -> W-NCJW1-CR1-C-PV-B3_RUNHR
... A108: B_FT230 | B108: =VLOOKUP(A108,NCJW!M:N,2,FALSE) -> Crusher | C108: =VLOOKUP(A108,NCJW!O:P,2,FALSE) -> W-NCJW1-CR1-F-PV-B_FT230

Sheet NCJW-Jetty
A1: Tag Name | B1: Section | C1: Tag UID
A2: RIPIK KILN COAL SELECTION | B2: =VLOOKUP(A2,NCJW!M:N,2,FALSE) -> #N/A | C2: =VLOOKUP(A2,NCJW!O:P,2,FALSE) -> #N/A
A3: FLAME FEEDBACK | B3: =VLOOKUP(A3,NCJW!M:N,2,FALSE) -> #N/A | C3: =VLOOKUP(A3,NCJW!O:P,2,FALSE) -> #N/A
A4: RIPIK_KILN_FLAME_FEEDBACK | B4: =VLOOKUP(A4,NCJW!M:N,2,FALSE) -> #N/A | C4: =VLOOKUP(A4,NCJW!O:P,2,FALSE) -> #N/A
A5: COAL CORRECTION | B5: =VLOOKUP(A5,NCJW!M:N,2,FALSE) -> #N/A | C5: =VLOOKUP(A5,NCJW!O:P,2,FALSE) -> #N/A
A6: RIPIK_KILN_COAL_CORR_VAL | B6: =VLOOKUP(A6,NCJW!M:N,2,FALSE) -> #N/A | C6: =VLOOKUP(A6,NCJW!O:P,2,FALSE) -> #N/A
A7: COAL DAY TOTALISER | B7: =VLOOKUP(A7,NCJW!M:N,2,FALSE) -> #N/A | C7: =VLOOKUP(A7,NCJW!O:P,2,FALSE) -> #N/A
A8: RIPIK_COAL _CORR_TOT | B8: =VLOOKUP(A8,NCJW!M:N,2,FALSE) -> #N/A | C8: =VLOOKUP(A8,NCJW!O:P,2,FALSE) -> #N/A
A9: COAL CORR COUNTS | B9: =VLOOKUP(A9,NCJW!M:N,2,FALSE) -> #N/A | C9: =VLOOKUP(A9,NCJW!O:P,2,FALSE) -> #N/A
A10: RIPIK_ACT_COUNT | B10: =VLOOKUP(A10,NCJW!M:N,2,FALSE) -> #N/A | C10: =VLOOKUP(A10,NCJW!O:P,2,FALSE) -> #N/A
A11: CEMS_ROOM_TEMP | B11: =VLOOKUP(A11,NCJW!M:N,2,FALSE) -> PreHeater | C11: =VLOOKUP(A11,NCJW!O:P,2,FALSE) -> W-NCJW1-PH1-T-PV-CEMS_ROOM_TEMP
A12: FIRE HYD LINE PRESS | B12: =VLOOKUP(A12,NCJW!M:N,2,FALSE) -> #N/A | C12: =VLOOKUP(A12,NCJW!O:P,2,FALSE) -> #N/A
A13: A_PT375 | B13: =VLOOKUP(A13,NCJW!M:N,2,FALSE) -> #N/A | C13: =VLOOKUP(A13,NCJW!O:P,2,FALSE) -> #N/A
... A134: A101 | B134: =VLOOKUP(A134,NCJW!M:N,2,FALSE) -> #N/A | C134: =VLOOKUP(A134,NCJW!O:P,2,FALSE) -> #N/A

Sheet NCJW-KilnMainPage
A1: Tag Name | B1: Section | C1: Tag UID
A2: KILN | B2: =VLOOKUP(A2,NCJW!M:N,2,FALSE) -> #N/A | C2: =VLOOKUP(A2,NCJW!O:P,2,FALSE) -> #N/A
A3: KILN_FILLING_PERC | B3: =VLOOKUP(A3,NCJW!M:N,2,FALSE) -> #N/A | C3: =VLOOKUP(A3,NCJW!O:P,2,FALSE) -> #N/A
A4: TEMPMaxTempKiln | B4: =VLOOKUP(A4,NCJW!M:N,2,FALSE) -> #N/A | C4: =VLOOKUP(A4,NCJW!O:P,2,FALSE) -> #N/A
A5: FEED_TO_RPM_RATIO | B5: =VLOOKUP(A5,NCJW!M:N,2,FALSE) -> #N/A | C5: =VLOOKUP(A5,NCJW!O:P,2,FALSE) -> #N/A
A6: KILN HOOD | B6: =VLOOKUP(A6,NCJW!M:N,2,FALSE) -> #N/A | C6: =VLOOKUP(A6,NCJW!O:P,2,FALSE) -> #N/A
A7: 441FN300N02P01 | B7: =VLOOKUP(A7,NCJW!M:N,2,FALSE) -> Cooler | C7: =VLOOKUP(A7,NCJW!O:P,2,FALSE) -> W-NCJW1-CL1-P-PV-441FN300N02P01
A8: 441FN305N02P01 | B8: =VLOOKUP(A8,NCJW!M:N,2,FALSE) -> Cooler | C8: =VLOOKUP(A8,NCJW!O:P,2,FALSE) -> W-NCJW1-CL1-P-PV-441FN305N02P01
A9: 441FN310N02P01 | B9: =VLOOKUP(A9,NCJW!M:N,2,FALSE) -> Cooler | C9: =VLOOKUP(A9,NCJW!O:P,2,FALSE) -> W-NCJW1-CL1-P-PV-441FN310N02P01
A10: 441FN315N02P01 | B10: =VLOOKUP(A10,NCJW!M:N,2,FALSE) -> Cooler | C10: =VLOOKUP(A10,NCJW!O:P,2,FALSE) -> W-NCJW1-CL1-P-PV-441FN315N02P01
A11: 441FN320N02P01 | B11: =VLOOKUP(A11,NCJW!M:N,2,FALSE) -> Cooler | C11: =VLOOKUP(A11,NCJW!O:P,2,FALSE) -> W-NCJW1-CL1-P-PV-441FN320N02P01
A12: 441FN325N02P01 | B12: =VLOOKUP(A12,NCJW!M:N,2,FALSE) -> Cooler | C12: =VLOOKUP(A12,NCJW!O:P,2,FALSE) -> W-NCJW1-CL1-P-PV-441FN325N02P01
A13: 441FN330N02P01 | B13: =VLOOKUP(A13,NCJW!M:N,2,FALSE) -> Cooler | C13: =VLOOKUP(A13,NCJW!O:P,2,FALSE) -> W-NCJW1-CL1-P-PV-441FN330N02P01
... A15: 1B | B15: =VLOOKUP(A15,NCJW!M:N,2,FALSE) -> #N/A | C15: =VLOOKUP(A15,NCJW!O:P,2,FALSE) -> #N/A
A16: 2 | B16: =VLOOKUP(A16,NCJW!M:N,2,FALSE) -> #N/A | C16: =VLOOKUP(A16,NCJW!O:P,2,FALSE) -> #N/A
A17: 3 | B17: =VLOOKUP(A17,NCJW!M:N,2,FALSE) -> #N/A | C17: =VLOOKUP(A17,NCJW!O:P,2,FALSE) -> #N/A
A18: 4 | B18: =VLOOKUP(A18,NCJW!M:N,2,FALSE) -> #N/A | C18: =VLOOKUP(A18,NCJW!O:P,2,FALSE) -> #N/A
A19: CAL | B19: =VLOOKUP(A19,NCJW!M:N,2,FALSE) -> #N/A | C19: =VLOOKUP(A19,NCJW!O:P,2,FALSE) -> #N/A
A20: O2 | B20: =VLOOKUP(A20,NCJW!M:N,2,FALSE) -> #N/A | C20: =VLOOKUP(A20,NCJW!O:P,2,FALSE) -> #N/A
A21: FKL_AT348A_OLD | B21: =VLOOKUP(A21,NCJW!M:N,2,FALSE) -> #N/A | C21: =VLOOKUP(A21,NCJW!O:P,2,FALSE) -> #N/A
A22: CO | B22: =VLOOKUP(A22,NCJW!M:N,2,FALSE) -> #N/A | C22: =VLOOKUP(A22,NCJW!O:P,2,FALSE) -> #N/A
A23: FKL_AT348B | B23: =VLOOKUP(A23,NCJW!M:N,2,FALSE) -> PreHeater | C23: =VLOOKUP(A23,NCJW!O:P,2,FALSE) -> W-NCJW1-PH1-Q-PV-FKL_AT348B
A24: PH_O/L_CO_SP | B24: =VLOOKUP(A24,NCJW!M:N,2,FALSE) -> PreHeater | C24: =VLOOKUP(A24,NCJW!O:P,2,FALSE) -> W-NCJW1-PH1-Q-PV-PH_O/L_CO_SP
A25: Stage 1A | B25: =VLOOKUP(A25,NCJW!M:N,2,FALSE) -> #N/A | C25: =VLOOKUP(A25,NCJW!O:P,2,FALSE) -> #N/A
A26: FKL_PT306A | B26: =VLOOKUP(A26,NCJW!M:N,2,FALSE) -> PreHeater | C26: =VLOOKUP(A26,NCJW!O:P,2,FALSE) -> W-NCJW1-PH1-DR-PV-FKL_PT306A
A27: FKL_TT317 | B27: =VLOOKUP(A27,NCJW!M:N,2,FALSE) -> PreHeater | C27: =VLOOKUP(A27,NCJW!O:P,2,FALSE) -> W-NCJW1-PH1-T-PV-FKL_TT317
A28: FKL_TT312 | B28: =VLOOKUP(A28,NCJW!M:N,2,FALSE) -> PreHeater | C28: =VLOOKUP(A28,NCJW!O:P,2,FALSE) -> W-NCJW1-PH1-T-PV-FKL_TT312
A29: FKL_PT306C | B29: =VLOOKUP(A29,NCJW!M:N,2,FALSE) -> PreHeater | C29: =VLOOKUP(A29,NCJW!O:P,2,FALSE) -> W-NCJW1-PH1-DR-PV-FKL_PT306C
A30: Stage 2 | B30: =VLOOKUP(A30,NCJW!M:N,2,FALSE) -> #N/A | C30: =VLOOKUP(A30,NCJW!O:P,2,FALSE) -> #N/A
... A101: E295B | B101: =VLOOKUP(A101,NCJW!M:N,2,FALSE) -> #N/A | C101: =VLOOKUP(A101,NCJW!O:P,2,FALSE) -> #N/A
A102: 1004 | B102: =VLOOKUP(A102,NCJW!M:N,2,FALSE) -> #N/A | C102: =VLOOKUP(A102,NCJW!O:P,2,FALSE) -> #N/A
A103: ST3_FEED_PIPE | B103: =VLOOKUP(A103,NCJW!M:N,2,FALSE) -> #N/A | C103: =VLOOKUP(A103,NCJW!O:P,2,FALSE) -> #N/A
A104: FKL_PT332 | B104: =VLOOKUP(A104,NCJW!M:N,2,FALSE) -> Kiln | C104: =VLOOKUP(A104,NCJW!O:P,2,FALSE) -> W-NCJW1-KL1-P-PV-FKL_PT332
A105: FKL_TT322 | B105: =VLOOKUP(A105,NCJW!M:N,2,FALSE) -> Kiln | C105: =VLOOKUP(A105,NCJW!O:P,2,FALSE) -> W-NCJW1-KL1-T-PV-FKL_TT322
A106: Diesel Firing | B106: =VLOOKUP(A106,NCJW!M:N,2,FALSE) -> #N/A | C106: =VLOOKUP(A106,NCJW!O:P,2,FALSE) -> #N/A
A107: BU500_A01Z11_PID_SPM | B107: =VLOOKUP(A107,NCJW!M:N,2,FALSE) -> Kiln | C107: =VLOOKUP(A107,NCJW!O:P,2,FALSE) -> W-NCJW1-KL1-F-PV-BU500_A01Z11_PID_SPM
A108: BU500_A01F01 | B108: =VLOOKUP(A108,NCJW!M:N,2,FALSE) -> Kiln | C108: =VLOOKUP(A108,NCJW!O:P,2,FALSE) -> W-NCJW1-KL1-F-PV-BU500_A01F01
A109: WIND SPEED | B109: =VLOOKUP(A109,NCJW!M:N,2,FALSE) -> #N/A | C109: =VLOOKUP(A109,NCJW!O:P,2,FALSE) -> #N/A
A110: RM_WIND_VELOCITY | B110: =VLOOKUP(A110,NCJW!M:N,2,FALSE) -> #N/A | C110: =VLOOKUP(A110,NCJW!O:P,2,FALSE) -> #N/A
A111: FKL_ST349 | B111: =VLOOKUP(A111,NCJW!M:N,2,FALSE) -> Kiln | C111: =VLOOKUP(A111,NCJW!O:P,2,FALSE) -> W-NCJW1-KL1-R-PV-FKL_ST349
...

Sheet NCJW-RawMill
A1: Tag Name | B1: Section | C1: Tag UID
A2: D_ST1032 | B2: =VLOOKUP(A2,NCJW!M:N,2,FALSE) -> Raw Mill | C2: =VLOOKUP(A2,NCJW!O:P,2,FALSE) -> W-NCJW1-RM1-R-PV-D_ST1032
A3: D19A_LVL_TX | B3: =VLOOKUP(A3,NCJW!M:N,2,FALSE) -> Raw Mill | C3: =VLOOKUP(A3,NCJW!O:P,2,FALSE) -> W-NCJW1-RM1-L-PV-D19A_LVL_TX
A4: LATERITE/ | B4: =VLOOKUP(A4,NCJW!M:N,2,FALSE) -> #N/A | C4: =VLOOKUP(A4,NCJW!O:P,2,FALSE) -> #N/A
A5: COPPER SLAG | B5: =VLOOKUP(A5,NCJW!M:N,2,FALSE) -> #N/A | C5: =VLOOKUP(A5,NCJW!O:P,2,FALSE) -> #N/A
A6: D19A | B6: =VLOOKUP(A6,NCJW!M:N,2,FALSE) -> #N/A | C6: =VLOOKUP(A6,NCJW!O:P,2,FALSE) -> #N/A
A7: DRMFC1300_SPM | B7: =VLOOKUP(A7,NCJW!M:N,2,FALSE) -> Raw Mill | C7: =VLOOKUP(A7,NCJW!O:P,2,FALSE) -> W-NCJW1-RM1-F-COP-DRMFC1300_SPM
A8: DRMFC1300_SPA | B8: =VLOOKUP(A8,NCJW!M:N,2,FALSE) -> Raw Mill | C8: =VLOOKUP(A8,NCJW!O:P,2,FALSE) -> W-NCJW1-RM1-F-CSP-DRMFC1300_SPA
A9: D_FT1300 | B9: =VLOOKUP(A9,NCJW!M:N,2,FALSE) -> Raw Mill | C9: =VLOOKUP(A9,NCJW!O:P,2,FALSE) -> W-NCJW1-RM1-F-PV-D_FT1300
A10: D19 CONT OP PERCENTAGE | B10: =VLOOKUP(A10,NCJW!M:N,2,FALSE) -> #N/A | C10: =VLOOKUP(A10,NCJW!O:P,2,FALSE) -> #N/A
A11: D19_LVL_TX | B11: =VLOOKUP(A11,NCJW!M:N,2,FALSE) -> Raw Mill | C11: =VLOOKUP(A11,NCJW!O:P,2,FALSE) -> W-NCJW1-RM1-L-PV-D19_LVL_TX
A12: LOW GRADE/ | B12: =VLOOKUP(A12,NCJW!M:N,2,FALSE) -> #N/A | C12: =VLOOKUP(A12,NCJW!O:P,2,FALSE) -> #N/A
A13: BESALT | B13: =VLOOKUP(A13,NCJW!M:N,2,FALSE) -> #N/A | C13: =VLOOKUP(A13,NCJW!O:P,2,FALSE) -> #N/A
... A175: TO BH | B175: =VLOOKUP(A175,NCJW!M:N,2,FALSE) -> #N/A | C175: =VLOOKUP(A175,NCJW!O:P,2,FALSE) -> #N/A

Sheet NCJW-Reclaimer
A1: Tag Name | B1: Section | C1: Tag UID
A2: C4_RUNHR | B2: =VLOOKUP(A2,NCJW!M:N,2,FALSE) -> #N/A | C2: =VLOOKUP(A2,NCJW!O:P,2,FALSE) -> #N/A
A3: RECMR_AMPS | B3: =VLOOKUP(A3,NCJW!M:N,2,FALSE) -> Raw Mill | C3: =VLOOKUP(A3,NCJW!O:P,2,FALSE) -> W-NCJW1-RM1-I-PV-RECMR_AMPS
A4: C6_CURRENT | B4: =VLOOKUP(A4,NCJW!M:N,2,FALSE) -> Raw Mill | C4: =VLOOKUP(A4,NCJW!O:P,2,FALSE) -> W-NCJW1-RM1-I-PV-C6_CURRENT
A5: BUCKET WHEEL | B5: =VLOOKUP(A5,NCJW!M:N,2,FALSE) -> #N/A | C5: =VLOOKUP(A5,NCJW!O:P,2,FALSE) -> #N/A
A6: REC_BW_AMPS | B6: =VLOOKUP(A6,NCJW!M:N,2,FALSE) -> Crusher | C6: =VLOOKUP(A6,NCJW!O:P,2,FALSE) -> W-NCJW1-MH1-I-PV-REC_BW_AMPS
A7: C4 RBC | B7: =VLOOKUP(A7,NCJW!M:N,2,FALSE) -> #N/A | C7: =VLOOKUP(A7,NCJW!O:P,2,FALSE) -> #N/A
A8: REC_C4_AMPS | B8: =VLOOKUP(A8,NCJW!M:N,2,FALSE) -> Raw Mill | C8: =VLOOKUP(A8,NCJW!O:P,2,FALSE) -> W-NCJW1-RM1-I-PV-REC_C4_AMPS
A9: CROSS TRAVEL | B9: =VLOOKUP(A9,NCJW!M:N,2,FALSE) -> #N/A | C9: =VLOOKUP(A9,NCJW!O:P,2,FALSE) -> #N/A
A10: REC_CT_VFD_SP | B10: =VLOOKUP(A10,NCJW!M:N,2,FALSE) -> Crusher | C10: =VLOOKUP(A10,NCJW!O:P,2,FALSE) -> W-NCJW1-MH1-R-PV-REC_CT_VFD_SP
A11: REC_CT_VFD_SPD | B11: =VLOOKUP(A11,NCJW!M:N,2,FALSE) -> Crusher | C11: =VLOOKUP(A11,NCJW!O:P,2,FALSE) -> W-NCJW1-MH1-R-PV-REC_CT_VFD_SPD
A12: REC_CT_VFD_CURRENT | B12: =VLOOKUP(A12,NCJW!M:N,2,FALSE) -> Crusher | C12: =VLOOKUP(A12,NCJW!O:P,2,FALSE) -> W-NCJW1-MH1-I-PV-REC_CT_VFD_CURRENT
A13: RECLAIMER | B13: =VLOOKUP(A13,NCJW!M:N,2,FALSE) -> #N/A | C13: =VLOOKUP(A13,NCJW!O:P,2,FALSE) -> #N/A
... A70: C19_CURRENT | B70: =VLOOKUP(A70,NCJW!M:N,2,FALSE) -> Raw Mill | C70: =VLOOKUP(A70,NCJW!O:P,2,FALSE) -> W-NCJW1-RM1-I-PV-C19_CURRENT
B71: =VLOOKUP(A71,NCJW!M:N,2,FALSE) -> #N/A | C71: =VLOOKUP(A71,NCJW!O:P,2,FALSE) -> #N/A
A72: C22.2 | B72: =VLOOKUP(A72,NCJW!M:N,2,FALSE) -> #N/A | C72: =VLOOKUP(A72,NCJW!O:P,2,FALSE) -> #N/A
A73: C22_2_CURRENT | B73: =VLOOKUP(A73,NCJW!M:N,2,FALSE) -> #N/A | C73: =VLOOKUP(A73,NCJW!O:P,2,FALSE) -> #N/A

Sheet NCJW-Utility
A1: Tag Name | B1: Section | C1: Tag UID
A2: RIPIK KILN COAL SELECTION | B2: =VLOOKUP(A2,NCJW!M:N,2,FALSE) -> #N/A | C2: =VLOOKUP(A2,NCJW!O:P,2,FALSE) -> #N/A
A3: FLAME FEEDBACK | B3: =VLOOKUP(A3,NCJW!M:N,2,FALSE) -> #N/A | C3: =VLOOKUP(A3,NCJW!O:P,2,FALSE) -> #N/A
A4: RIPIK_KILN_FLAME_FEEDBACK | B4: =VLOOKUP(A4,NCJW!M:N,2,FALSE) -> #N/A | C4: =VLOOKUP(A4,NCJW!O:P,2,FALSE) -> #N/A
A5: COAL CORRECTION | B5: =VLOOKUP(A5,NCJW!M:N,2,FALSE) -> #N/A | C5: =VLOOKUP(A5,NCJW!O:P,2,FALSE) -> #N/A
A6: RIPIK_KILN_COAL_CORR_VAL | B6: =VLOOKUP(A6,NCJW!M:N,2,FALSE) -> #N/A | C6: =VLOOKUP(A6,NCJW!O:P,2,FALSE) -> #N/A
A7: COAL DAY TOTALISER | B7: =VLOOKUP(A7,NCJW!M:N,2,FALSE) -> #N/A | C7: =VLOOKUP(A7,NCJW!O:P,2,FALSE) -> #N/A
A8: RIPIK_COAL _CORR_TOT | B8: =VLOOKUP(A8,NCJW!M:N,2,FALSE) -> #N/A | C8: =VLOOKUP(A8,NCJW!O:P,2,FALSE) -> #N/A
A9: COAL CORR COUNTS | B9: =VLOOKUP(A9,NCJW!M:N,2,FALSE) -> #N/A | C9: =VLOOKUP(A9,NCJW!O:P,2,FALSE) -> #N/A
A10: RIPIK_ACT_COUNT | B10: =VLOOKUP(A10,NCJW!M:N,2,FALSE) -> #N/A | C10: =VLOOKUP(A10,NCJW!O:P,2,FALSE) -> #N/A
A11: CEMS_ROOM_TEMP | B11: =VLOOKUP(A11,NCJW!M:N,2,FALSE) -> PreHeater | C11: =VLOOKUP(A11,NCJW!O:P,2,FALSE) -> W-NCJW1-PH1-T-PV-CEMS_ROOM_TEMP
A12: FIRE HYD LINE PRESS | B12: =VLOOKUP(A12,NCJW!M:N,2,FALSE) -> #N/A | C12: =VLOOKUP(A12,NCJW!O:P,2,FALSE) -> #N/A
A13: A_PT375 | B13: =VLOOKUP(A13,NCJW!M:N,2,FALSE) -> #N/A | C13: =VLOOKUP(A13,NCJW!O:P,2,FALSE) -> #N/A
... A134: A101 | B134: =VLOOKUP(A134,NCJW!M:N,2,FALSE) -> #N/A | C134: =VLOOKUP(A134,NCJW!O:P,2,FALSE) -> #N/A
