Workbook

Sheet PLCW
A1: Business Unit | B1: Cluster | C1: Plant | D1: Line | E1: Plant SAP Code | F1: Section | G1: Equipment Group | H1: Equipment Subtype | I1: Variable Group | J1: Variable Type | K1: Standard Variable Description | L1: Unit Of Measurement | M1: Tag Name | N1: Section | O1: Tag Name | P1: Tag UID | Q1: Min | R1: Max | S1: LCL | T1: UCL | U1: Flat Line Length | V1: OPC EndPOint | W1: Path | X1: PropertyID | Y1: AssetID | Z1: IsDisplay | AA1: ConvertToBinary | AB1: PublishingInterval | AC1: IsHighFrequencyTag
A2: CEMENT | B2: N | C2: PLCW | D2: 1 | E2: PC01 | F2: Crusher | G2: dummy | H2: dummy | I2: Mode | J2: Status | K2: Crusher Main Drive | L2: state | M2: CR_211MD1 | N2: Crusher | O2: CR_211MD1 | P2: N-PLCW1-CR1-ST-SV-CR_211MD1 | U2: 60 | V2: opc.tcp://10.5.9.43:26080 | W2: ns=2;s=1:CR_211MD1?Operating | X2: a22834c4-cf2c-4e8e-a81d-e823769fe1a2 | Y2: 994b5cbf-facc-477c-b8a6-dbb0783fb3cf | AB2: 60000
A3: CEMENT | B3: N | C3: PLCW | D3: 1 | E3: PC01 | F3: Coal Mill | G3: dummy | H3: dummy | I3: Mode | J3: Status | K3: Coal Mill Main Drive | L3: state | M3: CO_L41MD1 | N3: Coal Mill | O3: CO_L41MD1 | P3: N-PLCW1-KM1-ST-SV-CO_L41MD1 | U3: 60 | V3: opc.tcp://10.5.9.43:26080 | W3: ns=2;s=1:CO_L41MD1?Operating | X3: 8f686f38-a666-4627-8853-a703057b69e0 | Y3: 994b5cbf-facc-477c-b8a6-dbb0783fb3cf | AB3: 60000
A4: CEMENT | B4: N | C4: PLCW | D4: 1 | E4: PC01 | F4: Raw Mill | G4: Mill | H4: Main Equipment | I4: SP | J4: Flow | K4: QCX Set Point Weighfeeder-1 | L4: % | M4: CO_L41KM1_TT1 | N4: Coal Mill | O4: CO_L41KM1_TT1 | P4: N-PLCW1-KM1-T-PV-CO_L41KM1_TT1 | Q4: 0 | R4: 100 | S4: TBD | T4: TBD | U4: 60 | V4: opc.tcp://10.5.9.43:26080 | W4: ns=2;s=1:RM1_331WF1_FBAI01?Value | X4: d61139d5-f8d5-4a5d-b6f1-f366ba064a02 | Y4: 994b5cbf-facc-477c-b8a6-dbb0783fb3cf | Z4: TRUE | AB4: 60000
A5: CEMENT | B5: N | C5: PLCW | D5: 1 | E5: PC01 | F5: Raw Mill | G5: Mill | H5: Main Equipment | I5: SP | J5: Flow | K5: QCX Set Point Weighfeeder-2 | L5: % | M5: CMH_511BC2_TA | N5: Clinker Transport | O5: CMH_511BC2_TA | P5: N-PLCW1-CT1-T-PV-CMH_511BC2_TA | Q5: 0 | R5: 100 | S5: TBD | T5: TBD | U5: 60 | V5: opc.tcp://10.5.9.43:26080 | W5: ns=2;s=1:RM1_331WF2_FBAI02?Value | X5: 57551374-29e5-4a36-a9e5-d1e8e7209139 | Y5: 994b5cbf-facc-477c-b8a6-dbb0783fb3cf | Z5: TRUE | AB5: 60000
A6: CEMENT | B6: N | C6: PLCW | D6: 1 | E6: PC01 | F6: Raw Mill | G6: Mill | H6: Main Equipment | I6: SP | J6: Flow | K6: QCX Set Point Weighfeeder-3 | L6: % | M6: RM1_331WF1_FBAI01 | N6: Raw Mill | O6: RM1_331WF1_FBAI01 | P6: N-PLCW1-RM1-F-FSP-RM1_331WF1_FBAI01 | Q6: 0 | R6: 100 | S6: TBD | T6: TBD | U6: 60 | V6: opc.tcp://10.5.9.43:26080 | W6: ns=2;s=1:RM1_331WF3_FBAI03?Value | X6: 445ee3ab-6aa6-4c2f-b7a2-e680cc71111e | Y6: 994b5cbf-facc-477c-b8a6-dbb0783fb3cf | Z6: TRUE | AB6: 60000
A7: CEMENT | B7: N | C7: PLCW | D7: 1 | E7: PC01 | F7: Raw Mill | G7: Mill | H7: Main Equipment | I7: SP | J7: Flow | K7: QCX Set Point Weighfeeder-4 | L7: % | M7: RM1_331WF2_FBAI02 | N7: Raw Mill | O7: RM1_331WF2_FBAI02 | P7: N-PLCW1-RM1-F-FSP-RM1_331WF2_FBAI02 | Q7: 0 | R7: 100 | S7: TBD | T7: TBD | U7: 60 | V7: opc.tcp://10.5.9.43:26080 | W7: ns=2;s=1:RM1_331WF4_FBAI04?Value | X7: b4dfc7c3-a4fa-4244-8b12-3bdfe925cb93 | Y7: 994b5cbf-facc-477c-b8a6-dbb0783fb3cf | Z7: TRUE | AB7: 60000
A8: CEMENT | B8: N | C8: PLCW | D8: 1 | E8: PC01 | F8: Raw Mill | G8: Mill | H8: Main Equipment | I8: SP | J8: Flow | K8: QCX Set Point Weighfeeder-5 | L8: % | M8: RM1_331WF3_FBAI03 | N8: Raw Mill | O8: RM1_331WF3_FBAI03 | P8: N-PLCW1-RM1-F-FSP-RM1_331WF3_FBAI03 | Q8: 0 | R8: 100 | S8: TBD | T8: TBD | U8: 60 | V8: opc.tcp://10.5.9.43:26080 | W8: ns=2;s=1:RM1_331WF5_FBAI05?Value | X8: f255fcc0-3d46-444e-b3cd-984e475ad4f9 | Y8: 994b5cbf-facc-477c-b8a6-dbb0783fb3cf | Z8: TRUE | AB8: 60000
A9: CEMENT | B9: N | C9: PLCW | D9: 1 | E9: PC01 | F9: Raw Mill | G9: Mill | H9: Main Equipment | I9: PV | J9: Flow | K9: Lime Stone Weighfeeder -1 Feed Rate | L9: TPH | M9: RM1_331WF4_FBAI04 | N9: Raw Mill | O9: RM1_331WF4_FBAI04 | P9: N-PLCW1-RM1-F-FSP-RM1_331WF4_FBAI04 | Q9: 0 | R9: 850 | S9: TBD | T9: TBD | U9: 60 | V9: opc.tcp://10.5.9.43:26080 | W9: ns=2;s=1:RM1_331WF1_FR?Value | X9: fa6b8603-8aa6-48ce-ad04-c58d5a7eb3a0 | Y9: 994b5cbf-facc-477c-b8a6-dbb0783fb3cf | Z9: TRUE | AB9: 60000
A10: CEMENT | B10: N | C10: PLCW | D10: 1 | E10: PC01 | F10: Raw Mill | G10: Mill | H10: Main Equipment | I10: PV | J10: Flow | K10: Lime Stone Weighfeeder -2 Feed Rate | L10: TPH | M10: RM1_331WF5_FBAI05 | N10: Raw Mill | O10: RM1_331WF5_FBAI05 | P10: N-PLCW1-RM1-F-FSP-RM1_331WF5_FBAI05 | Q10: 0 | R10: 850 | S10: TBD | T10: TBD | U10: 60 | V10: opc.tcp://10.5.9.43:26080 | W10: ns=2;s=1:RM1_331WF2_FR?Value | X10: a4d05724-19b1-46eb-9622-2fc465110847 | Y10: 994b5cbf-facc-477c-b8a6-dbb0783fb3cf | Z10: TRUE | AB10: 60000
A11: CEMENT | B11: N | C11: PLCW | D11: 1 | E11: PC01 | F11: Raw Mill | G11: Mill | H11: Main Equipment | I11: PV | J11: Flow | K11: High Grade Lime Stone Weighfeeder -2 Feed Rate | L11: TPH | M11: RM1_331WF1_FR | N11: Raw Mill | O11: RM1_331WF1_FR | P11: N-PLCW1-RM1-F-PV-RM1_331WF1_FR | Q11: 0 | R11: 80 | S11: TBD | T11: TBD | U11: 60 | V11: opc.tcp://10.5.9.43:26080 | W11: ns=2;s=1:RM1_331WF3_FR?Value | X11: 9208bcfe-4b16-42f3-80a7-b3bfb473d812 | Y11: 994b5cbf-facc-477c-b8a6-dbb0783fb3cf | Z11: TRUE | AB11: 60000
A12: CEMENT | B12: N | C12: PLCW | D12: 1 | E12: PC01 | F12: Raw Mill | G12: Mill | H12: Main Equipment | I12: PV | J12: Flow | K12: Additive-1 Weighfeeder Feed rate | L12: TPH | M12: RM1_331WF2_FR | N12: Raw Mill | O12: RM1_331WF2_FR | P12: N-PLCW1-RM1-F-PV-RM1_331WF2_FR | Q12: 0 | R12: 35 | S12: TBD | T12: TBD | U12: 60 | V12: opc.tcp://10.5.9.43:26080 | W12: ns=2;s=1:RM1_331WF4_FR?Value | X12: 1516612b-6631-439f-85ae-f583feb52a46 | Y12: 994b5cbf-facc-477c-b8a6-dbb0783fb3cf | Z12: TRUE | AB12: 60000
A13: CEMENT | B13: N | C13: PLCW | D13: 1 | E13: PC01 | F13: Raw Mill | G13: Mill | H13: Main Equipment | I13: PV | J13: Flow | K13: Additive-2 Weighfeeder Feed rate | L13: TPH | M13: RM1_331WF3_FR | N13: Raw Mill | O13: RM1_331WF3_FR | P13: N-PLCW1-RM1-F-PV-RM1_331WF3_FR | Q13: 0 | R13: 35 | S13: TBD | T13: TBD | U13: 60 | V13: opc.tcp://10.5.9.43:26080 | W13: ns=2;s=1:RM1_331WF5_FR?Value | X13: 85fc7ada-9172-4616-9e88-53ef22f9f576 | Y13: 994b5cbf-facc-477c-b8a6-dbb0783fb3cf | Z13: TRUE | AB13: 60000
A14: CEMENT | B14: N | C14: PLCW | D14: 1 | E14: PC01 | F14: Raw Mill | G14: dummy | H14: dummy | I14: PV | J14: Flow | K14: Addetive WF-2 Feed (t/h) | L14: TPH | M14: RM1_331WF4_FR | N14: Raw Mill | O14: RM1_331WF4_FR | P14: N-PLCW1-RM1-F-PV-RM1_331WF4_FR | U14: 60 | V14: opc.tcp://10.5.9.43:26080 | W14: ns=2;s=1:RM1_331WF5_FR_B?Value | X14: 302d9adc-d4af-45e8-a761-838a5c17367a | Y14: 994b5cbf-facc-477c-b8a6-dbb0783fb3cf | AB14: 60000
A15: CEMENT | B15: N | C15: PLCW | D15: 1 | E15: PC01 | F15: Raw Mill | G15: Mill | H15: Main Equipment | I15: PV | J15: Flow | K15: Raw Mill Feed rate | L15: TPH | M15: RM1_331WF5_FR | N15: Raw Mill | O15: RM1_331WF5_FR | P15: N-PLCW1-RM1-F-PV-RM1_331WF5_FR | Q15: 0 | R15: 850 | S15: TBD | T15: TBD | U15: 60 | V15: opc.tcp://10.5.9.43:26080 | W15: ns=2;s=1:RM1_331WF_TPH_TOT?Value | X15: 8e63f4e6-21f9-4e74-bf52-76dd3019f96f | Y15: 994b5cbf-facc-477c-b8a6-dbb0783fb3cf | Z15: TRUE | AB15: 60000
A16: CEMENT | B16: N | C16: PLCW | D16: 1 | E16: PC01 | F16: Raw Mill | G16: Mill | H16: Main Equipment | I16: PV | J16: Flow | K16: Mill reject feed Rate | L16: TPH | M16: RM1_331WF5_FR_B | N16: Raw Mill | O16: RM1_331WF5_FR_B | P16: N-PLCW1-RM1-F-PV-RM1_331WF5_FR_B | Q16: 0 | R16: 350 | S16: TBD | T16: TBD | U16: 60 | V16: opc.tcp://10.5.9.43:26080 | W16: ns=2;s=1:RM1_361BW1_FR?Value | X16: 43b9caf4-3e54-4a2f-93fb-8034716f222c | Y16: 994b5cbf-facc-477c-b8a6-dbb0783fb3cf | Z16: TRUE | AB16: 60000
A17: CEMENT | B17: N | C17: PLCW | D17: 1 | E17: PC01 | F17: Raw Mill | G17: Mill | H17: Main Equipment | I17: PV | J17: Flow | K17: Water Spray Flow measurement | L17: m2/hr | M17: RM1_331WF_TPH_TOT | N17: Raw Mill | O17: RM1_331WF_TPH_TOT | P17: N-PLCW1-RM1-F-PV-RM1_331WF_TPH_TOT | Q17: 0 | R17: 20 | S17: TBD | T17: TBD | U17: 60 | V17: opc.tcp://10.5.9.43:26080 | W17: ns=2;s=1:RM1_361WI1_FT1?Value | X17: 7a0e3aef-fee5-4d0d-a2e2-b4d9c3690ce8 | Y17: 994b5cbf-facc-477c-b8a6-dbb0783fb3cf | Z17: TRUE | AB17: 60000
A18: CEMENT | B18: N | C18: PLCW | D18: 1 | E18: PC01 | F18: Raw Mill | G18: Mill | H18: Main Equipment | I18: PV | J18: Current | K18: RM BH Fan VFD Current | L18: amp | M18: RM1_361BW1_FR | N18: Raw Mill | O18: RM1_361BW1_FR | P18: N-PLCW1-RM1-F-PV-RM1_361BW1_FR | Q18: 0 | R18: 242 | S18: TBD | T18: TBD | U18: 60 | V18: opc.tcp://10.5.9.43:26080 | W18: ns=2;s=1:PH_421FN1_II?Value | X18: 665863c1-8435-42da-845f-9e1886bf64f9 | Y18: 994b5cbf-facc-477c-b8a6-dbb0783fb3cf | Z18: TRUE | AB18: 60000
A19: CEMENT | B19: N | C19: PLCW | D19: 1 | E19: PC01 | F19: Raw Mill | G19: Mill | H19: Main Equipment | I19: PV | J19: Current | K19: Mill reject Bucket Elevator Current | L19: amp | M19: RM1_361WI1_FT1 | N19: Raw Mill | O19: RM1_361WI1_FT1 | P19: N-PLCW1-RM1-F-PV-RM1_361WI1_FT1 | Q19: 0 | R19: 126 | S19: TBD | T19: TBD | U19: 60 | V19: opc.tcp://10.5.9.43:26080 | W19: ns=2;s=1:RM1_361BE1_M01II_B?Value | X19: 925f0b1f-a410-438f-a500-4eafb0f86472 | Y19: 994b5cbf-facc-477c-b8a6-dbb0783fb3cf | Z19: TRUE | AB19: 60000
A20: CEMENT | B20: N | C20: PLCW | D20: 1 | E20: PC01 | F20: Raw Mill | G20: Mill | H20: Main Equipment | I20: PV | J20: Current | K20: Bucket Elevator Current | L20: amp | M20: PH_421FN1_II | N20: Raw Mill | O20: PH_421FN1_II | P20: N-PLCW1-RM1-I-PV-PH_421FN1_II | Q20: 0 | R20: 228 | S20: TBD | T20: TBD | U20: 60 | V20: opc.tcp://10.5.9.43:26080 | W20: ns=2;s=1:RM1_391BE1_M01II_B?Value | X20: 13ee99e1-35f3-4035-a955-88f1329efbc9 | Y20: 994b5cbf-facc-477c-b8a6-dbb0783fb3cf | Z20: TRUE | AB20: 60000
A21: CEMENT | B21: N | C21: PLCW | D21: 1 | E21: PC01 | F21: Raw Mill | G21: Mill | H21: Main Equipment | I21: PV | J21: Current | K21: Bucket Elevator Current | L21: amp | M21: RM1_361BE1_M01II_B | N21: Raw Mill | O21: RM1_361BE1_M01II_B | P21: N-PLCW1-RM1-I-PV-RM1_361BE1_M01II_B | Q21: 0 | R21: 228 | S21: TBD | T21: TBD | U21: 60 | V21: opc.tcp://10.5.9.43:26080 | W21: ns=2;s=1:RM1_391BE1_M02II_B?Value | X21: de34e727-0819-4798-8d47-efb0c3be6eb4 | Y21: 994b5cbf-facc-477c-b8a6-dbb0783fb3cf | Z21: TRUE | AB21: 60000
A22: CEMENT | B22: N | C22: PLCW | D22: 1 | E22: PC01 | F22: Raw Mill | G22: Mill | H22: Main Equipment | I22: PV | J22: Power | K22: Mill Main Motor Power | L22: kW | M22: RM1_391BE1_M01II_B | N22: Raw Mill | O22: RM1_391BE1_M01II_B | P22: N-PLCW1-RM1-I-PV-RM1_391BE1_M01II_B | Q22: 0 | R22: 8400 | S22: TBD | T22: TBD | U22: 60 | V22: opc.tcp://10.5.9.43:26080 | W22: ns=2;s=1:RABH_HT_MFM4_TOT_ACT_PWR?Value | X22: 6ee2e13b-dede-4742-a72f-dc58d5781a2b | Y22: 994b5cbf-facc-477c-b8a6-dbb0783fb3cf | Z22: TRUE | AB22: 60000
A23: CEMENT | B23: N | C23: PLCW | D23: 1 | E23: PC01 | F23: Raw Mill | G23: dummy | H23: dummy | I23: PV | J23: Power | K23: RM_Fan_KW | L23: kW | M23: RM1_391BE1_M02II_B | N23: Raw Mill | O23: RM1_391BE1_M02II_B | P23: N-PLCW1-RM1-I-PV-RM1_391BE1_M02II_B | U23: 60 | V23: opc.tcp://10.5.9.43:26080 | W23: ns=2;s=1:RM1_361FN1_JI?Value | X23: a1594e5e-cbec-4443-b14c-7374cce8a801 | Y23: 994b5cbf-facc-477c-b8a6-dbb0783fb3cf | AB23: 60000
A24: CEMENT | B24: N | C24: PLCW | D24: 1 | E24: PC01 | F24: Raw Mill | G24: dummy | H24: dummy | I24: PV | J24: Power | K24: RM_MD_KW | L24: kW | M24: RABH_HT_MFM4_TOT_ACT_PWR | N24: Raw Mill | O24: RABH_HT_MFM4_TOT_ACT_PWR | P24: N-PLCW1-RM1-J-PV-RABH_HT_MFM4_TOT_ACT_PWR | U24: 60 | V24: opc.tcp://10.5.9.43:26080 | W24: ns=2;s=1:RM1_361RM1_JI?Value | X24: 1889e860-98da-453c-98df-d2739bf052c5 | Y24: 994b5cbf-facc-477c-b8a6-dbb0783fb3cf | AB24: 60000
A25: CEMENT | B25: N | C25: PLCW | D25: 1 | E25: PC01 | F25: Raw Mill | G25: Mill | H25: Main Equipment | I25: PV | J25: Power | K25: Bucket Elevator Power | L25: kW | M25: RM1_361FN1_JI | N25: Raw Mill | O25: RM1_361FN1_JI | P25: N-PLCW1-RM1-J-PV-RM1_361FN1_JI | Q25: 0 | R25: 500 | S25: TBD | T25: TBD | U25: 60 | V25: opc.tcp://10.5.9.43:26080 | W25: ns=2;s=1:RM1_391BE1_M01JI_B?Value | X25: 222d3ef8-78a6-46fb-ac7d-1cd2d1e4ed58 | Y25: 994b5cbf-facc-477c-b8a6-dbb0783fb3cf | Z25: TRUE | AB25: 60000
A26: CEMENT | B26: N | C26: PLCW | D26: 1 | E26: PC01 | F26: Raw Mill | G26: Mill | H26: Main Equipment | I26: PV | J26: Power | K26: Bucket Elevator Power | L26: kW | M26: RM1_361RM1_JI | N26: Raw Mill | O26: RM1_361RM1_JI | P26: N-PLCW1-RM1-J-PV-RM1_361RM1_JI | Q26: 0 | R26: 500 | S26: TBD | T26: TBD | U26: 60 | V26: opc.tcp://10.5.9.43:26080 | W26: ns=2;s=1:RM1_391BE1_M02JI_B?Value | X26: a60e565c-2129-443e-80d8-9dd6fdf67567 | Y26: 994b5cbf-facc-477c-b8a6-dbb0783fb3cf | Z26: TRUE | AB26: 60000
A27: CEMENT | B27: N | C27: PLCW | D27: 1 | E27: PC01 | F27: Raw Mill | G27: Mill | H27: Main Equipment | I27: PV | J27: Level | K27: Bed Height | L27: mm | M27: RM1_391BE1_M01JI_B | N27: Raw Mill | O27: RM1_391BE1_M01JI_B | P27: N-PLCW1-RM1-J-PV-RM1_391BE1_M01JI_B | Q27: 0 | R27: 100 | S27: TBD | T27: TBD | U27: 60 | V27: opc.tcp://10.5.9.43:26080 | W27: ns=2;s=1:RM1_361HT1_S01AI01?Value | X27: 40f797ff-aa56-4c8f-b7da-f26923d930f4 | Y27: 994b5cbf-facc-477c-b8a6-dbb0783fb3cf | Z27: TRUE | AB27: 60000
A28: CEMENT | B28: N | C28: PLCW | D28: 1 | E28: PC01 | F28: Raw Mill | G28: Mill | H28: Main Equipment | I28: PV | J28: Level | K28: Blending Silo Level | L28: meter | M28: RM1_391BE1_M02JI_B | N28: Raw Mill | O28: RM1_391BE1_M02JI_B | P28: N-PLCW1-RM1-J-PV-RM1_391BE1_M02JI_B | Q28: 0 | R28: 37 | S28: TBD | T28: TBD | U28: 60 | V28: opc.tcp://10.5.9.43:26080 | W28: ns=2;s=1:RM1_391SB1_LT?Value | X28: 71c274bc-1fb0-4e83-acbe-3879cc7e6467 | Y28: 994b5cbf-facc-477c-b8a6-dbb0783fb3cf | Z28: TRUE | AB28: 60000
A29: CEMENT | B29: N | C29: PLCW | D29: 1 | E29: PC01 | F29: Raw Mill | G29: Mill | H29: Main Equipment | I29: PV | J29: Level | K29: Blending Silo Level MT | L29: tons | M29: RM1_361HT1_S01AI01 | N29: Raw Mill | O29: RM1_361HT1_S01AI01 | P29: N-PLCW1-RM1-L-PV-RM1_361HT1_S01AI01 | Q29: 0 | R29: 15000 | S29: TBD | T29: TBD | U29: 60 | V29: opc.tcp://10.5.9.43:26080 | W29: ns=2;s=1:RM1_CF_SILO_LVL_MT?Value | X29: 676e3dba-d98c-4aea-9421-c2c8de026203 | Y29: 994b5cbf-facc-477c-b8a6-dbb0783fb3cf | Z29: TRUE | AB29: 60000
A30: CEMENT | B30: N | C30: PLCW | D30: 1 | E30: PC01 | F30: Raw Mill | G30: Mill | H30: Main Equipment | I30: SP | J30: Pressure | K30: RM BH Fan VFD Set Point | L30: mmWC | M30: RM1_391SB1_LT | N30: Raw Mill | O30: RM1_391SB1_LT | P30: N-PLCW1-RM1-L-PV-RM1_391SB1_LT | Q30: -100 | R30: 100 | S30: TBD | T30: TBD | U30: 60 | V30: opc.tcp://10.5.9.43:26080 | W30: ns=2;s=1:PH_421FN1_SPSPA?Value | X30: 8193319a-2d48-4b7c-a451-e32cada3b0d2 | Y30: 994b5cbf-facc-477c-b8a6-dbb0783fb3cf | Z30: TRUE | AB30: 60000
A31: CEMENT | B31: N | C31: PLCW | D31: 1 | E31: PC01 | F31: Raw Mill | G31: Mill | H31: Main Equipment | I31: PV | J31: Pressure | K31: Bag House Differnetial Pressure | L31: mmWC | M31: RM1_CF_SILO_LVL_MT | N31: Raw Mill | O31: RM1_CF_SILO_LVL_MT | P31: N-PLCW1-RM1-L-PV-RM1_CF_SILO_LVL_MT | Q31: 0 | R31: 250 | S31: TBD | T31: TBD | U31: 60 | V31: opc.tcp://10.5.9.43:26080 | W31: ns=2;s=1:PH_421BF1_DPT?Value | X31: a9d0771f-198a-4549-bc85-f37844b26a4b | Y31: 994b5cbf-facc-477c-b8a6-dbb0783fb3cf | Z31: TRUE | AB31: 60000
A32: CEMENT | B32: N | C32: PLCW | D32: 1 | E32: PC01 | F32: Raw Mill | G32: Mill | H32: Main Equipment | I32: PV | J32: Pressure | K32: Preheater Fan Outlet Pressure | L32: mmWC | M32: PH_421FN1_SPSPA | N32: Raw Mill | O32: PH_421FN1_SPSPA | P32: N-PLCW1-RM1-P-FSP-PH_421FN1_SPSPA | Q32: -100 | R32: 100 | S32: TBD | T32: TBD | U32: 60 | V32: opc.tcp://10.5.9.43:26080 | W32: ns=2;s=1:PH_441FN1_PT02?Value | X32: cbdff085-6f4b-4710-86e9-57de4e40fd33 | Y32: 994b5cbf-facc-477c-b8a6-dbb0783fb3cf | Z32: TRUE | AB32: 60000
A33: CEMENT | B33: N | C33: PLCW | D33: 1 | E33: PC01 | F33: Raw Mill | G33: Mill | H33: Main Equipment | I33: PV | J33: Pressure | K33: Hyd Tension Pressure Roller 1/3 | L33: bar | M33: PH_421BF1_DPT | N33: Raw Mill | O33: PH_421BF1_DPT | P33: N-PLCW1-RM1-P-PV-PH_421BF1_DPT | Q33: 0 | R33: 600 | S33: TBD | T33: TBD | U33: 60 | V33: opc.tcp://10.5.9.43:26080 | W33: ns=2;s=1:RM1_361HT1_PT13?Value | X33: 56d9408c-e1d3-4d2c-af3c-449346e202af | Y33: 994b5cbf-facc-477c-b8a6-dbb0783fb3cf | Z33: TRUE | AB33: 60000
A34: CEMENT | B34: N | C34: PLCW | D34: 1 | E34: PC01 | F34: Raw Mill | G34: Mill | H34: Main Equipment | I34: PV | J34: Pressure | K34: Hyd Tension Pressure Roller 2/4 | L34: bar | M34: PH_441FN1_PT02 | N34: Raw Mill | O34: PH_441FN1_PT02 | P34: N-PLCW1-RM1-P-PV-PH_441FN1_PT02 | Q34: 0 | R34: 600 | S34: TBD | T34: TBD | U34: 60 | V34: opc.tcp://10.5.9.43:26080 | W34: ns=2;s=1:RM1_361HT1_PT24?Value | X34: b10fd39b-7a18-405c-b837-83fc12023457 | Y34: 994b5cbf-facc-477c-b8a6-dbb0783fb3cf | Z34: TRUE | AB34: 60000
A35: CEMENT | B35: N | C35: PLCW | D35: 1 | E35: PC01 | F35: Raw Mill | G35: Mill | H35: Main Equipment | I35: PV | J35: Pressure | K35: Raw Mill I/L Pressure | L35: mbar | M35: RM1_361HT1_PT13 | N35: Raw Mill | O35: RM1_361HT1_PT13 | P35: N-PLCW1-RM1-P-PV-RM1_361HT1_PT13 | Q35: -40 | R35: 5 | S35: TBD | T35: TBD | U35: 60 | V35: opc.tcp://10.5.9.43:26080 | W35: ns=2;s=1:RM1_361RM1_PT1?Value | X35: 0fc516a1-f869-4f72-b352-42be9878876f | Y35: 994b5cbf-facc-477c-b8a6-dbb0783fb3cf | Z35: TRUE | AB35: 60000
A36: CEMENT | B36: N | C36: PLCW | D36: 1 | E36: PC01 | F36: Raw Mill | G36: Mill | H36: Main Equipment | I36: PV | J36: Pressure | K36: Calculated Mill DP | L36: mbar | M36: RM1_361HT1_PT24 | N36: Raw Mill | O36: RM1_361HT1_PT24 | P36: N-PLCW1-RM1-P-PV-RM1_361HT1_PT24 | Q36: 0 | R36: 100 | S36: TBD | T36: TBD | U36: 60 | V36: opc.tcp://10.5.9.43:26080 | W36: ns=2;s=1:RM1_361RM1_PT1_PT2?Value | X36: 8674e68a-5714-4830-aaf5-8c39038b28e9 | Y36: 994b5cbf-facc-477c-b8a6-dbb0783fb3cf | Z36: TRUE | AB36: 60000
... A43: CEMENT | B43: N | C43: PLCW | D43: 1 | E43: PC01 | F43: Raw Mill | G43: Mill | H43: Main Equipment | I43: PV | J43: Speed | K43: Raw Mill Classifier Speed | L43: RPM | M43: PH_421FN1_SI | N43: Raw Mill | O43: PH_421FN1_SI | P43: N-PLCW1-RM1-R-PV-PH_421FN1_SI | Q43: 0 | R43: 1485 | S43: TBD | T43: TBD | U43: 60 | V43: opc.tcp://10.5.9.43:26080 | W43: ns=2;s=1:RM1_361SR1_SI?Value | X43: ce56f8e1-0c2b-4f37-b415-b68c86e62f27 | Y43: 994b5cbf-facc-477c-b8a6-dbb0783fb3cf | Z43: TRUE | AB43: 60000
A44: CEMENT | B44: N | C44: PLCW | D44: 1 | E44: PC01 | F44: Raw Mill | G44: Others | H44: Other | I44: PV | J44: Position | K44: Bed Height (mm) | L44: mm | M44: PH_421FN1_SPSPM | N44: Raw Mill | O44: PH_421FN1_SPSPM | P44: N-PLCW1-RM1-R-PV-PH_421FN1_SPSPM | U44: 60 | V44: opc.tcp://10.5.9.43:26080 | W44: ns=2;s=1:RM1_361HT1_S01AI01?Value | X44: 5c130b0b-60f8-4d45-8e9e-c5c8907f2df3 | Y44: 959c1179-a3c0-4745-b667-5a62419dcb40 | AB44: 60000
A45: CEMENT | B45: N | C45: PLCW | D45: 1 | E45: PC01 | F45: Raw Mill | G45: dummy | H45: dummy | I45: Mode | J45: Status | K45: Raw Mill Main Drive | L45: state | M45: RM1_361SR1_SI | N45: Raw Mill | O45: RM1_361SR1_SI | P45: N-PLCW1-RM1-R-PV-RM1_361SR1_SI | U45: 60 | V45: opc.tcp://10.5.9.43:26080 | W45: ns=2;s=1:RM1_361MD1?Operating | X45: 6ffac698-d86c-4a62-8bfc-18fc29fb5744 | Y45: 994b5cbf-facc-477c-b8a6-dbb0783fb3cf | AB45: 60000
A46: CEMENT | B46: N | C46: PLCW | D46: 1 | E46: PC01 | F46: Raw Mill | G46: Mill | H46: Main Equipment | I46: PV | J46: Temperature | K46: Raw Mill Inlet Temp | L46: deg C | M46: RM1_361HT1_S01AI01 | N46: Raw Mill | O46: RM1_361HT1_S01AI01 | P46: N-PLCW1-RM1-S-PV-RM1_361HT1_S01AI01 | Q46: 0 | R46: 350 | S46: TBD | T46: TBD | U46: 60 | V46: opc.tcp://10.5.9.43:26080 | W46: ns=2;s=1:RM1_361RM1_TT1?Value | X46: cdd3907d-f2d4-4093-9a1c-1892f827e1ed | Y46: 994b5cbf-facc-477c-b8a6-dbb0783fb3cf | Z46: TRUE | AB46: 60000
...

Sheet PLCW-CBA
A1: Tag Name | B1: Section | C1: Tag UID
A2: SiO2 | B2: =VLOOKUP('PLCW-CBA'!A2,PLCW!M:N,2,FALSE) -> Raw Mill-1 | C2: =VLOOKUP(A2,PLCW!O:P,2,FALSE) -> N-PLCW1-RM1-Q-QC-SiO2
A3: SiO2_10 | B3: =VLOOKUP('PLCW-CBA'!A3,PLCW!M:N,2,FALSE) -> Raw Mill-1 | C3: =VLOOKUP(A3,PLCW!O:P,2,FALSE) -> N-PLCW1-RM1-Q-QC-SiO2_10
A4: SiO2_60 | B4: =VLOOKUP('PLCW-CBA'!A4,PLCW!M:N,2,FALSE) -> Raw Mill-1 | C4: =VLOOKUP(A4,PLCW!O:P,2,FALSE) -> N-PLCW1-RM1-Q-QC-SiO2_60
A5: SiO2_P | B5: =VLOOKUP('PLCW-CBA'!A5,PLCW!M:N,2,FALSE) -> Raw Mill-1 | C5: =VLOOKUP(A5,PLCW!O:P,2,FALSE) -> N-PLCW1-RM1-Q-QC-SiO2_P
A6: Al2O3 | B6: =VLOOKUP('PLCW-CBA'!A6,PLCW!M:N,2,FALSE) -> Raw Mill-1 | C6: =VLOOKUP(A6,PLCW!O:P,2,FALSE) -> N-PLCW1-RM1-Q-QC-Al2O3
A7: Al2O3_10 | B7: =VLOOKUP('PLCW-CBA'!A7,PLCW!M:N,2,FALSE) -> Raw Mill-1 | C7: =VLOOKUP(A7,PLCW!O:P,2,FALSE) -> N-PLCW1-RM1-Q-QC-Al2O3_10
A8: Al2O3_60 | B8: =VLOOKUP('PLCW-CBA'!A8,PLCW!M:N,2,FALSE) -> Raw Mill-1 | C8: =VLOOKUP(A8,PLCW!O:P,2,FALSE) -> N-PLCW1-RM1-Q-QC-Al2O3_60
A9: Al2O3_P | B9: =VLOOKUP('PLCW-CBA'!A9,PLCW!M:N,2,FALSE) -> Raw Mill-1 | C9: =VLOOKUP(A9,PLCW!O:P,2,FALSE) -> N-PLCW1-RM1-Q-QC-Al2O3_P
A10: Fe2O3 | B10: =VLOOKUP('PLCW-CBA'!A10,PLCW!M:N,2,FALSE) -> Raw Mill-1 | C10: =VLOOKUP(A10,PLCW!O:P,2,FALSE) -> N-PLCW1-RM1-Q-QC-Fe2O3
A11: Fe2O3_10 | B11: =VLOOKUP('PLCW-CBA'!A11,PLCW!M:N,2,FALSE) -> Raw Mill-1 | C11: =VLOOKUP(A11,PLCW!O:P,2,FALSE) -> N-PLCW1-RM1-Q-QC-Fe2O3_10
A12: Fe2O3_60 | B12: =VLOOKUP('PLCW-CBA'!A12,PLCW!M:N,2,FALSE) -> Raw Mill-1 | C12: =VLOOKUP(A12,PLCW!O:P,2,FALSE) -> N-PLCW1-RM1-Q-QC-Fe2O3_60
A13: Fe2O3_P | B13: =VLOOKUP('PLCW-CBA'!A13,PLCW!M:N,2,FALSE) -> Raw Mill-1 | C13: =VLOOKUP(A13,PLCW!O:P,2,FALSE) -> N-PLCW1-RM1-Q-QC-Fe2O3_P
... A65: TONS_P | B65: =VLOOKUP('PLCW-CBA'!A65,PLCW!M:N,2,FALSE) -> Raw Mill-1 | C65: =VLOOKUP(A65,PLCW!O:P,2,FALSE) -> N-PLCW1-RM1-WE-QC-TONS_P

Sheet PLCW-CementMill
A1: Tag Name | B1: Section | C1: Tag UID
A2: CM_531WI1AI01 | B2: =VLOOKUP(A2,PLCW!M:N,2,FALSE) -> Cement Mill | C2: =VLOOKUP(A2,PLCW!O:P,2,FALSE) -> N-PLCW1-CM1-F-FSP-CM_531WI1AI01
A3: CM_531WI1AI02 | B3: =VLOOKUP(A3,PLCW!M:N,2,FALSE) -> Cement Mill | C3: =VLOOKUP(A3,PLCW!O:P,2,FALSE) -> N-PLCW1-CM1-F-FSP-CM_531WI1AI02
A4: CM_531WI1AI03 | B4: =VLOOKUP(A4,PLCW!M:N,2,FALSE) -> Cement Mill | C4: =VLOOKUP(A4,PLCW!O:P,2,FALSE) -> N-PLCW1-CM1-F-FSP-CM_531WI1AI03
A5: CM_531WI1AI04 | B5: =VLOOKUP(A5,PLCW!M:N,2,FALSE) -> Cement Mill | C5: =VLOOKUP(A5,PLCW!O:P,2,FALSE) -> N-PLCW1-CM1-F-FSP-CM_531WI1AI04
A6: CM_531WI1AI05 | B6: =VLOOKUP(A6,PLCW!M:N,2,FALSE) -> Cement Mill | C6: =VLOOKUP(A6,PLCW!O:P,2,FALSE) -> N-PLCW1-CM1-F-FSP-CM_531WI1AI05
A7: CM_531WF1_FR | B7: =VLOOKUP(A7,PLCW!M:N,2,FALSE) -> Cement Mill | C7: =VLOOKUP(A7,PLCW!O:P,2,FALSE) -> N-PLCW1-CM1-F-PV-CM_531WF1_FR
A8: CM_531WF2_FR | B8: =VLOOKUP(A8,PLCW!M:N,2,FALSE) -> Cement Mill | C8: =VLOOKUP(A8,PLCW!O:P,2,FALSE) -> N-PLCW1-CM1-F-PV-CM_531WF2_FR
A9: CM_531WF3_FR | B9: =VLOOKUP(A9,PLCW!M:N,2,FALSE) -> Cement Mill | C9: =VLOOKUP(A9,PLCW!O:P,2,FALSE) -> N-PLCW1-CM1-F-PV-CM_531WF3_FR
A10: CM_531WF4_FR | B10: =VLOOKUP(A10,PLCW!M:N,2,FALSE) -> Cement Mill | C10: =VLOOKUP(A10,PLCW!O:P,2,FALSE) -> N-PLCW1-CM1-F-PV-CM_531WF4_FR
A11: CM_K31FM1_FI | B11: =VLOOKUP(A11,PLCW!M:N,2,FALSE) -> Cement Mill | C11: =VLOOKUP(A11,PLCW!O:P,2,FALSE) -> N-PLCW1-CM1-F-PV-CM_K31FM1_FI
A12: CM_561BE1_M01II_B | B12: =VLOOKUP(A12,PLCW!M:N,2,FALSE) -> Cement Mill | C12: =VLOOKUP(A12,PLCW!O:P,2,FALSE) -> N-PLCW1-CM1-I-PV-CM_561BE1_M01II_B
A13: Reject Bin | B13: =VLOOKUP(A13,PLCW!M:N,2,FALSE) -> #N/A | C13: =VLOOKUP(A13,PLCW!O:P,2,FALSE) -> #N/A
... A63: 561SK1 | B63: =VLOOKUP(A63,PLCW!M:N,2,FALSE) -> #N/A | C63: =VLOOKUP(A63,PLCW!O:P,2,FALSE) -> #N/A

Sheet PLCW-Cooler
A1: Tag Name | B1: Section | C1: Tag UID
A2: 471CV5 | B2: =VLOOKUP(A2,PLCW!M:N,2,FALSE) -> #N/A | C2: =VLOOKUP(A2,PLCW!O:P,2,FALSE) -> #N/A
A3: CL_472CV4_RUN | B3: =VLOOKUP(A3,PLCW!M:N,2,FALSE) -> #N/A | C3: =VLOOKUP(A3,PLCW!O:P,2,FALSE) -> #N/A
A4: 471CV6 | B4: =VLOOKUP(A4,PLCW!M:N,2,FALSE) -> #N/A | C4: =VLOOKUP(A4,PLCW!O:P,2,FALSE) -> #N/A
A5: CL_472CV5_RUN | B5: =VLOOKUP(A5,PLCW!M:N,2,FALSE) -> #N/A | C5: =VLOOKUP(A5,PLCW!O:P,2,FALSE) -> #N/A
A6: CL_472CV1_RUN | B6: =VLOOKUP(A6,PLCW!M:N,2,FALSE) -> #N/A | C6: =VLOOKUP(A6,PLCW!O:P,2,FALSE) -> #N/A
A7: CL_472CV2_RUN | B7: =VLOOKUP(A7,PLCW!M:N,2,FALSE) -> #N/A | C7: =VLOOKUP(A7,PLCW!O:P,2,FALSE) -> #N/A
A8: 471CV1 | B8: =VLOOKUP(A8,PLCW!M:N,2,FALSE) -> #N/A | C8: =VLOOKUP(A8,PLCW!O:P,2,FALSE) -> #N/A
A9: CL_472CV3_RUN | B9: =VLOOKUP(A9,PLCW!M:N,2,FALSE) -> #N/A | C9: =VLOOKUP(A9,PLCW!O:P,2,FALSE) -> #N/A
A10: CL_492DB1_RUN | B10: =VLOOKUP(A10,PLCW!M:N,2,FALSE) -> #N/A | C10: =VLOOKUP(A10,PLCW!O:P,2,FALSE) -> #N/A
A11: 491DB1 | B11: =VLOOKUP(A11,PLCW!M:N,2,FALSE) -> #N/A | C11: =VLOOKUP(A11,PLCW!O:P,2,FALSE) -> #N/A
A12: CL_492DB2_RUN | B12: =VLOOKUP(A12,PLCW!M:N,2,FALSE) -> #N/A | C12: =VLOOKUP(A12,PLCW!O:P,2,FALSE) -> #N/A
A13: 491DB2 | B13: =VLOOKUP(A13,PLCW!M:N,2,FALSE) -> #N/A | C13: =VLOOKUP(A13,PLCW!O:P,2,FALSE) -> #N/A
... A170: RA9 | B170: =VLOOKUP(A170,PLCW!M:N,2,FALSE) -> #N/A | C170: =VLOOKUP(A170,PLCW!O:P,2,FALSE) -> #N/A

Sheet PLCW-Kiln
A1: Tag Name | B1: Section | C1: Tag UID
A2: IA | B2: =VLOOKUP(A2,PLCW!M:N,2,FALSE) -> #N/A | C2: =VLOOKUP(A2,PLCW!O:P,2,FALSE) -> #N/A
A3: PH_441PH1_CN1A_PT1 | B3: =VLOOKUP(A3,PLCW!M:N,2,FALSE) -> Kiln | C3: =VLOOKUP(A3,PLCW!O:P,2,FALSE) -> N-PLCW1-KL1-P-PV-PH_441PH1_CN1A_PT1
A4: PH_441PH1_CN1A_TT1 | B4: =VLOOKUP(A4,PLCW!M:N,2,FALSE) -> Kiln | C4: =VLOOKUP(A4,PLCW!O:P,2,FALSE) -> N-PLCW1-KL1-T-PV-PH_441PH1_CN1A_TT1
A5: PH_441PH1_CN1A_PT2 | B5: =VLOOKUP(A5,PLCW!M:N,2,FALSE) -> Kiln | C5: =VLOOKUP(A5,PLCW!O:P,2,FALSE) -> N-PLCW1-KL1-P-PV-PH_441PH1_CN1A_PT2
A6: PH_441PH1_CN1A_TT2 | B6: =VLOOKUP(A6,PLCW!M:N,2,FALSE) -> Kiln | C6: =VLOOKUP(A6,PLCW!O:P,2,FALSE) -> N-PLCW1-KL1-T-PV-PH_441PH1_CN1A_TT2
A7: IB | B7: =VLOOKUP(A7,PLCW!M:N,2,FALSE) -> #N/A | C7: =VLOOKUP(A7,PLCW!O:P,2,FALSE) -> #N/A
A8: PH_441PH1_CN1B_PT1 | B8: =VLOOKUP(A8,PLCW!M:N,2,FALSE) -> Kiln | C8: =VLOOKUP(A8,PLCW!O:P,2,FALSE) -> N-PLCW1-KL1-P-PV-PH_441PH1_CN1B_PT1
A9: PH_441PH1_CN1B_TT1 | B9: =VLOOKUP(A9,PLCW!M:N,2,FALSE) -> Kiln | C9: =VLOOKUP(A9,PLCW!O:P,2,FALSE) -> N-PLCW1-KL1-T-PV-PH_441PH1_CN1B_TT1
A10: PH_441PH1_CN1B_PT2 | B10: =VLOOKUP(A10,PLCW!M:N,2,FALSE) -> Kiln | C10: =VLOOKUP(A10,PLCW!O:P,2,FALSE) -> N-PLCW1-KL1-P-PV-PH_441PH1_CN1B_PT2
A11: PH_441PH1_CN1B_TT2 | B11: =VLOOKUP(A11,PLCW!M:N,2,FALSE) -> Kiln | C11: =VLOOKUP(A11,PLCW!O:P,2,FALSE) -> N-PLCW1-KL1-T-PV-PH_441PH1_CN1B_TT2
A12: PH_441PH2_CN1A_PT1 | B12: =VLOOKUP(A12,PLCW!M:N,2,FALSE) -> Kiln | C12: =VLOOKUP(A12,PLCW!O:P,2,FALSE) -> N-PLCW1-KL1-P-PV-PH_441PH2_CN1A_PT1
A13: PH_441PH2_CN1A_TT1 | B13: =VLOOKUP(A13,PLCW!M:N,2,FALSE) -> Kiln | C13: =VLOOKUP(A13,PLCW!O:P,2,FALSE) -> N-PLCW1-KL1-T-PV-PH_441PH2_CN1A_TT1
... A148: 481BL3 | B148: =VLOOKUP(A148,PLCW!M:N,2,FALSE) -> #N/A | C148: =VLOOKUP(A148,PLCW!O:P,2,FALSE) -> #N/A

Sheet PLCW-RawMill
A1: Tag name | B1: Section | C1: Tag UID
A2: RM1_331WF1_FBAI01 | B2: =VLOOKUP(A2,PLCW!M:N,2,FALSE) -> Raw Mill | C2: =VLOOKUP(A2,PLCW!O:P,2,FALSE) -> N-PLCW1-RM1-F-FSP-RM1_331WF1_FBAI01
A3: RM1_331WF2_FBAI02 | B3: =VLOOKUP(A3,PLCW!M:N,2,FALSE) -> Raw Mill | C3: =VLOOKUP(A3,PLCW!O:P,2,FALSE) -> N-PLCW1-RM1-F-FSP-RM1_331WF2_FBAI02
A4: RM1_331WF3_FBAI03 | B4: =VLOOKUP(A4,PLCW!M:N,2,FALSE) -> Raw Mill | C4: =VLOOKUP(A4,PLCW!O:P,2,FALSE) -> N-PLCW1-RM1-F-FSP-RM1_331WF3_FBAI03
A5: RM1_331WF4_FBAI04 | B5: =VLOOKUP(A5,PLCW!M:N,2,FALSE) -> Raw Mill | C5: =VLOOKUP(A5,PLCW!O:P,2,FALSE) -> N-PLCW1-RM1-F-FSP-RM1_331WF4_FBAI04
A6: RM1_331WF5_FBAI05 | B6: =VLOOKUP(A6,PLCW!M:N,2,FALSE) -> Raw Mill | C6: =VLOOKUP(A6,PLCW!O:P,2,FALSE) -> N-PLCW1-RM1-F-FSP-RM1_331WF5_FBAI05
A7: RM1_331WF1_FR | B7: =VLOOKUP(A7,PLCW!M:N,2,FALSE) -> Raw Mill | C7: =VLOOKUP(A7,PLCW!O:P,2,FALSE) -> N-PLCW1-RM1-F-PV-RM1_331WF1_FR
A8: RM1_331WF2_FR | B8: =VLOOKUP(A8,PLCW!M:N,2,FALSE) -> Raw Mill | C8: =VLOOKUP(A8,PLCW!O:P,2,FALSE) -> N-PLCW1-RM1-F-PV-RM1_331WF2_FR
A9: RM1_331WF3_FR | B9: =VLOOKUP(A9,PLCW!M:N,2,FALSE) -> Raw Mill | C9: =VLOOKUP(A9,PLCW!O:P,2,FALSE) -> N-PLCW1-RM1-F-PV-RM1_331WF3_FR
A10: RM1_331WF4_FR | B10: =VLOOKUP(A10,PLCW!M:N,2,FALSE) -> Raw Mill | C10: =VLOOKUP(A10,PLCW!O:P,2,FALSE) -> N-PLCW1-RM1-F-PV-RM1_331WF4_FR
A11: RM1_331WF5_FR | B11: =VLOOKUP(A11,PLCW!M:N,2,FALSE) -> Raw Mill | C11: =VLOOKUP(A11,PLCW!O:P,2,FALSE) -> N-PLCW1-RM1-F-PV-RM1_331WF5_FR
A12: RM1_361BE1_M01II_B | B12: =VLOOKUP(A12,PLCW!M:N,2,FALSE) -> Raw Mill | C12: =VLOOKUP(A12,PLCW!O:P,2,FALSE) -> N-PLCW1-RM1-I-PV-RM1_361BE1_M01II_B
A13: RM1_331WF_TPH_TOT | B13: =VLOOKUP(A13,PLCW!M:N,2,FALSE) -> Raw Mill | C13: =VLOOKUP(A13,PLCW!O:P,2,FALSE) -> N-PLCW1-RM1-F-PV-RM1_331WF_TPH_TOT
... A37: RM1_361SR1_SPSPM | B37: =VLOOKUP(A37,PLCW!M:N,2,FALSE) -> Raw Mill | C37: =VLOOKUP(A37,PLCW!O:P,2,FALSE) -> N-PLCW1-RM1-R-FSP-RM1_361SR1_SPSPM
A38: 361 | B38: =VLOOKUP(A38,PLCW!M:N,2,FALSE) -> #N/A | C38: =VLOOKUP(A38,PLCW!O:P,2,FALSE) -> #N/A
A39: CN1 | B39: =VLOOKUP(A39,PLCW!M:N,2,FALSE) -> #N/A | C39: =VLOOKUP(A39,PLCW!O:P,2,FALSE) -> #N/A
A40: CN2 | B40: =VLOOKUP(A40,PLCW!M:N,2,FALSE) -> #N/A | C40: =VLOOKUP(A40,PLCW!O:P,2,FALSE) -> #N/A
A41: CN3 | B41: =VLOOKUP(A41,PLCW!M:N,2,FALSE) -> #N/A | C41: =VLOOKUP(A41,PLCW!O:P,2,FALSE) -> #N/A
A42: CN4 | B42: =VLOOKUP(A42,PLCW!M:N,2,FALSE) -> #N/A | C42: =VLOOKUP(A42,PLCW!O:P,2,FALSE) -> #N/A
A43: 391AS1 | B43: =VLOOKUP(A43,PLCW!M:N,2,FALSE) -> #N/A | C43: =VLOOKUP(A43,PLCW!O:P,2,FALSE) -> #N/A
A44: 391AS2 | B44: =VLOOKUP(A44,PLCW!M:N,2,FALSE) -> #N/A | C44: =VLOOKUP(A44,PLCW!O:P,2,FALSE) -> #N/A
A45: 391AS3 | B45: =VLOOKUP(A45,PLCW!M:N,2,FALSE) -> #N/A | C45: =VLOOKUP(A45,PLCW!O:P,2,FALSE) -> #N/A
A46: 391AS4 | B46: =VLOOKUP(A46,PLCW!M:N,2,FALSE) -> #N/A | C46: =VLOOKUP(A46,PLCW!O:P,2,FALSE) -> #N/A
A47: BagHouse | B47: =VLOOKUP(A47,PLCW!M:N,2,FALSE) -> #N/A | C47: =VLOOKUP(A47,PLCW!O:P,2,FALSE) -> #N/A
A48: PH_421BF1_DPT | B48: =VLOOKUP(A48,PLCW!M:N,2,FALSE) -> Raw Mill | C48: =VLOOKUP(A48,PLCW!O:P,2,FALSE) -> N-PLCW1-RM1-P-PV-PH_421BF1_DPT
A49: 391AS5 | B49: =VLOOKUP(A49,PLCW!M:N,2,FALSE) -> #N/A | C49: =VLOOKUP(A49,PLCW!O:P,2,FALSE) -> #N/A
A50: 391RA5 | B50: =VLOOKUP(A50,PLCW!M:N,2,FALSE) -> #N/A | C50: =VLOOKUP(A50,PLCW!O:P,2,FALSE) -> #N/A
... A78: 391RA1-4 | B78: =VLOOKUP(A78,PLCW!M:N,2,FALSE) -> #N/A | C78: =VLOOKUP(A78,PLCW!O:P,2,FALSE) -> #N/A
